Workbook

Sheet YoY
A1: 시장 현황 YoY 비교
A2: 조회 월 선택: | C2: 4 | D2: ← 1~4 입력
A4: 전체 평균 증감 | B4: 자사(SONO) 평균 | C4: 상승 (≥+0.5%p) | D4: 하락 (≤-0.5%p) | E4: 보합 | F4: 신규
A5: =AVERAGEIFS(H8:H69,B8:B69,"<>",H8:H69,"<>NEW") -> 2.906383 | B5: =AVERAGEIFS(H8:H69,C8:C69,"Y",H8:H69,"<>NEW") -> 3 | C5: =COUNTIFS(H8:H69,">="&0.5,B8:B69,"<>") -> 25 | D5: =COUNTIFS(H8:H69,"<="&-0.5,B8:B69,"<>") -> 20 | E5: =COUNTIFS(H8:H69,">"&-0.5,H8:H69,"<"&0.5,B8:B69,"<>",H8:H69,"<>NEW") -> 2 | F5: =COUNTIF(H8:H69,"NEW") -> 7
A7: 지역 | B7: 시설명 | C7: 자사 | D7: 객실수(25) | E7: 객실수(26) | F7: 25년 OCC | G7: 26년 OCC | H7: 증감(%p)
A8: 강원도 서부 지역
B9: 소노캄 비발디파크 | C9: Y | D9: ='2025'!D3 -> 1723 | E9: ='2026'!D3 -> 1762 | F9: =INDEX('2025'!E3:H3,1,$C$2) -> 0.342 | G9: =INDEX('2026'!E3:H3,1,$C$2) -> 0.254 | H9: =(G9-F9)*100 -> -8.8
B10: 소노벨리체 비발디 | C10: Y | D10: ='2025'!D4 -> 500 | E10: ='2026'!D4 -> 500 | F10: =INDEX('2025'!E4:H4,1,$C$2) -> 0.274 | G10: =INDEX('2026'!E4:H4,1,$C$2) -> 0.196 | H10: =(G10-F10)*100 -> -7.8
B11: 소노펠리체 빌리지 비발디 | C11: Y | D11: ='2025'!D5 -> 219 | E11: ='2026'!D5 -> 219 | F11: =INDEX('2025'!E5:H5,1,$C$2) -> 0.304 | G11: =INDEX('2026'!E5:H5,1,$C$2) -> 0.24 | H11: =(G11-F11)*100 -> -6.4
B12: 용평 | D12: ='2025'!D6 -> 1298 | E12: ='2026'!D6 -> 1298 | F12: =INDEX('2025'!E6:H6,1,$C$2) -> 0.183 | G12: =INDEX('2026'!E6:H6,1,$C$2) -> 0.206 | H12: =(G12-F12)*100 -> 2.3
B13: 휘닉스파크 | D13: ='2025'!D7 -> 962 | E13: ='2026'!D7 -> 962 | F13: =INDEX('2025'!E7:H7,1,$C$2) -> 0.225 | G13: =INDEX('2026'!E7:H7,1,$C$2) -> 0.272 | H13: =(G13-F13)*100 -> 4.7
B14: 오크밸리 | D14: ='2025'!D8 -> 1105 | E14: ='2026'!D8 -> 1105 | F14: =INDEX('2025'!E8:H8,1,$C$2) -> 0.477 | G14: =INDEX('2026'!E8:H8,1,$C$2) -> 0.398 | H14: =(G14-F14)*100 -> -7.9
B15: 웰리힐리 | D15: ='2025'!D9 -> 766 | E15: ='2026'!D9 -> 766 | F15: =INDEX('2025'!E9:H9,1,$C$2) -> 0.166 | G15: =INDEX('2026'!E9:H9,1,$C$2) -> 0.162 | H15: =(G15-F15)*100 -> -0.4
B16: 소노벨 양평 | C16: Y | D16: - | E16: ='2026'!D10 -> 193 | F16: - | G16: =INDEX('2026'!E10:H10,1,$C$2) -> 0.494 | H16: NEW
A17: 강원도 동부 지역
B18: 델피노 | C18: Y | D18: ='2025'!D12 -> 1196 | E18: ='2026'!D12 -> 1257 | F18: =INDEX('2025'!E12:H12,1,$C$2) -> 0.429 | G18: =INDEX('2026'!E12:H12,1,$C$2) -> 0.425 | H18: =(G18-F18)*100 -> -0.4
B19: 쏠비치 양양 | C19: Y | D19: ='2025'!D13 -> 501 | E19: ='2026'!D13 -> 497 | F19: =INDEX('2025'!E13:H13,1,$C$2) -> 0.533 | G19: =INDEX('2026'!E13:H13,1,$C$2) -> 0.507 | H19: =(G19-F19)*100 -> -2.6
B20: 쏠비치 삼척 | C20: Y | D20: ='2025'!D14 -> 707 | E20: ='2026'!D14 -> 707 | F20: =INDEX('2025'!E14:H14,1,$C$2) -> 0.607 | G20: =INDEX('2026'!E14:H14,1,$C$2) -> 0.636 | H20: =(G20-F20)*100 -> 2.9
B21: 롯데리조트 속초 | D21: ='2025'!D15 -> 392 | E21: ='2026'!D15 -> 392 | F21: =INDEX('2025'!E15:H15,1,$C$2) -> 0.737 | G21: =INDEX('2026'!E15:H15,1,$C$2) -> 0.652 | H21: =(G21-F21)*100 -> -8.5
B22: 카시아리조트 | D22: - | E22: ='2026'!D16 -> 674 | F22: - | G22: =INDEX('2026'!E16:H16,1,$C$2) -> 0.36 | H22: NEW
B23: 한화리조트 속초 | D23: ='2025'!D17 -> 1554 | E23: ='2026'!D17 -> 1554 | F23: =INDEX('2025'!E17:H17,1,$C$2) -> 0.468 | G23: =INDEX('2026'!E17:H17,1,$C$2) -> 0.439 | H23: =(G23-F23)*100 -> -2.9
B24: 한화브리드 양양 | D24: ='2025'!D18 -> 56 | E24: ='2026'!D18 -> 56 | F24: =INDEX('2025'!E18:H18,1,$C$2) -> 0.705 | G24: =INDEX('2026'!E18:H18,1,$C$2) -> 0.618 | H24: =(G24-F24)*100 -> -8.7
B25: 윈덤 호텔 고성 | D25: - | E25: ='2026'!D19 -> 529 | F25: - | G25: =INDEX('2026'!E19:H19,1,$C$2) -> 0.2 | H25: NEW
B26: 르네블루 by 쏠비치 고성 | C26: Y | D26: - | E26: ='2026'!D20 -> 87 | F26: - | G26: =INDEX('2026'!E20:H20,1,$C$2) -> 0.663 | H26: NEW
B27: 켄싱턴리조트 속초 | D27: ='2025'!D20 -> 176 | E27: ='2026'!D21 -> 176 | F27: =INDEX('2025'!E20:H20,1,$C$2) -> 0.74 | G27: =INDEX('2026'!E21:H21,1,$C$2) -> 0.646 | H27: =(G27-F27)*100 -> -9.4
A28: 경상도 지역
B29: 소노캄 경주 | C29: Y | D29: ='2025'!D22 -> 410 | E29: ='2026'!D23 -> 417 | F29: =INDEX('2025'!E22:H22,1,$C$2) -> 0 | G29: =INDEX('2026'!E23:H23,1,$C$2) -> 0.918 | H29: =(G29-F29)*100 -> 91.8
B30: 라한셀렉트 | D30: ='2025'!D23 -> 430 | E30: ='2026'!D24 -> 430 | F30: =INDEX('2025'!E23:H23,1,$C$2) -> 0.87 | G30: =INDEX('2026'!E24:H24,1,$C$2) -> 0.943 | H30: =(G30-F30)*100 -> 7.3
B31: 켄싱턴 | D31: ='2025'!D55 -> 214 | E31: ='2026'!D58 -> 214 | F31: =INDEX('2025'!E55:H55,1,$C$2) -> 0.665 | G31: =INDEX('2026'!E58:H58,1,$C$2) -> 0.722 | H31: =(G31-F31)*100 -> 5.7
B32: 한화리조트 경주 | D32: ='2025'!D25 -> 393 | E32: ='2026'!D26 -> 393 | F32: =INDEX('2025'!E25:H25,1,$C$2) -> 0.625 | G32: =INDEX('2026'!E26:H26,1,$C$2) -> 0.842 | H32: =(G32-F32)*100 -> 21.7
B33: 소노벨 단양 | C33: Y | D33: ='2025'!D26 -> 830 | E33: ='2026'!D27 -> 843 | F33: =INDEX('2025'!E26:H26,1,$C$2) -> 0.603 | G33: =INDEX('2026'!E27:H27,1,$C$2) -> 0.418 | H33: =(G33-F33)*100 -> -18.5
B34: 포레스트 리솜 | D34: ='2025'!D27 -> 450 | E34: ='2026'!D28 -> 450 | F34: =INDEX('2025'!E27:H27,1,$C$2) -> 0.719 | G34: =INDEX('2026'!E28:H28,1,$C$2) -> 0.739 | H34: =(G34-F34)*100 -> 2
B35: 소노벨 청송 | C35: Y | D35: ='2025'!D28 -> 306 | E35: ='2026'!D29 -> 320 | F35: =INDEX('2025'!E28:H28,1,$C$2) -> 0.362 | G35: =INDEX('2026'!E29:H29,1,$C$2) -> 0.433 | H35: =(G35-F35)*100 -> 7.1
A36: 충청/전북 지역
B37: 소노벨 천안 | C37: Y | D37: ='2025'!D30 -> 438 | E37: ='2026'!D31 -> 450 | F37: =INDEX('2025'!E30:H30,1,$C$2) -> 0.554 | G37: =INDEX('2026'!E31:H31,1,$C$2) -> 0.505 | H37: =(G37-F37)*100 -> -4.9
B38: 덕산스플라스 리솜 | D38: - | E38: ='2026'!D32 -> 405 | F38: - | G38: =INDEX('2026'!E32:H32,1,$C$2) -> 0.621 | H38: NEW
B39: 안면도 아일랜드 리솜 | D39: ='2025'!D32 -> 248 | E39: ='2026'!D33 -> 248 | F39: =INDEX('2025'!E32:H32,1,$C$2) -> 0.579 | G39: =INDEX('2026'!E33:H33,1,$C$2) -> 0.784 | H39: =(G39-F39)*100 -> 20.5
B40: 소노벨 변산 | C40: Y | D40: ='2025'!D33 -> 502 | E40: ='2026'!D34 -> 503 | F40: =INDEX('2025'!E33:H33,1,$C$2) -> 0.537 | G40: =INDEX('2026'!E34:H34,1,$C$2) -> 0.506 | H40: =(G40-F40)*100 -> -3.1
A41: 전라/경상도 지역
B42: 소노캄 여수 | C42: Y | D42: ='2025'!D35 -> 309 | E42: ='2026'!D36 -> 310 | F42: =INDEX('2025'!E35:H35,1,$C$2) -> 0.602 | G42: =INDEX('2026'!E36:H36,1,$C$2) -> 0.646 | H42: =(G42-F42)*100 -> 4.4
...

Sheet 2026
A1: 지역 | B1: 시설명 | C1: 자사 | D1: 가용객실수 | E1: 1월 | F1: 2월 | G1: 3월 | H1: 4월
A2: 강원도 서부 지역
B3: 소노캄 비발디파크 | C3: Y | D3: 1762 | E3: 0.77 | F3: 0.792 | G3: 0.208 | H3: 0.254
B4: 소노벨리체 비발디 | C4: Y | D4: 500 | E4: 0.529 | F4: 0.589 | G4: 0.12 | H4: 0.196
B5: 소노펠리체 빌리지 비발디 | C5: Y | D5: 219 | E5: 0.42 | F5: 0.433 | G5: 0.153 | H5: 0.24
B6: 용평 | D6: 1298 | E6: 0.853 | F6: 0.818 | G6: 0.268 | H6: 0.206
B7: 휘닉스파크 | D7: 962 | E7: 0.751 | F7: 0.653 | G7: 0.105 | H7: 0.272
B8: 오크밸리 | D8: 1105 | E8: 0.514 | F8: 0.562 | G8: 0.244 | H8: 0.398
B9: 웰리힐리 | D9: 766 | E9: 0.643 | F9: 0.6 | G9: 0.096 | H9: 0.162
B10: 소노벨 양평 | C10: Y | D10: 193 | E10: 0.529 | F10: 0.563 | G10: 0.386 | H10: 0.494
A11: 강원도 동부 지역
B12: 델피노 | C12: Y | D12: 1257 | E12: 0.59 | F12: 0.623 | G12: 0.259 | H12: 0.425
B13: 쏠비치 양양 | C13: Y | D13: 497 | E13: 0.556 | F13: 0.612 | G13: 0.339 | H13: 0.507
B14: 쏠비치 삼척 | C14: Y | D14: 707 | E14: 0.616 | F14: 0.696 | G14: 0.381 | H14: 0.636
B15: 롯데리조트 속초 | D15: 392 | E15: 0.646 | F15: 0.715 | G15: 0.479 | H15: 0.652
B16: 카시아리조트 | D16: 674 | E16: 0.38 | F16: 0.42 | G16: 0.3 | H16: 0.36
B17: 한화리조트 속초 | D17: 1554 | E17: 0.299 | F17: 0.293 | G17: 0.115 | H17: 0.439
B18: 한화브리드 양양 | D18: 56 | E18: 0.725 | F18: 0.713 | G18: 0.56 | H18: 0.618
B19: 윈덤 호텔 고성 | D19: 529 | E19: 0.15 | F19: 0.19 | G19: 0.09 | H19: 0.2
B20: 르네블루 by 쏠비치 고성 | C20: Y | D20: 87 | E20: 0.804 | F20: 0.826 | G20: 0.575 | H20: 0.663
B21: 켄싱턴리조트 속초 | D21: 176 | E21: 0.735 | F21: 0.708 | G21: 0.419 | H21: 0.646
A22: 경상도 지역
B23: 소노캄 경주 | C23: Y | D23: 417 | E23: 0.745 | F23: 0.805 | G23: 0.56 | H23: 0.918
B24: 라한셀렉트 | D24: 430 | E24: 0.786 | F24: 0.749 | G24: 0.638 | H24: 0.943
B25: 켄싱턴 | D25: 501 | E25: 0.471 | F25: 0.544 | G25: 0.343 | H25: 0.728
B26: 한화리조트 경주 | D26: 393 | E26: 0.611 | F26: 0.611 | G26: 0.568 | H26: 0.842
B27: 소노벨 단양 | C27: Y | D27: 843 | E27: 0.574 | F27: 0.609 | G27: 0.311 | H27: 0.418
B28: 포레스트 리솜 | D28: 450 | E28: 0.81 | F28: 0.835 | G28: 0.55 | H28: 0.739
B29: 소노벨 청송 | C29: Y | D29: 320 | E29: 0.688 | F29: 0.703 | G29: 0.356 | H29: 0.433
A30: 충청/전북 지역
B31: 소노벨 천안 | C31: Y | D31: 450 | E31: 0.755 | F31: 0.775 | G31: 0.369 | H31: 0.505
B32: 덕산스플라스 리솜 | D32: 405 | E32: 0.901 | F32: 0.882 | G32: 0.421 | H32: 0.621
B33: 안면도 아일랜드 리솜 | D33: 248 | E33: 0.605 | F33: 0.681 | G33: 0.494 | H33: 0.784
B34: 소노벨 변산 | C34: Y | D34: 503 | E34: 0.464 | F34: 0.62 | G34: 0.315 | H34: 0.506
A35: 전라/경상도 지역
B36: 소노캄 여수 | C36: Y | D36: 310 | E36: 0.409 | F36: 0.491 | G36: 0.42 | H36: 0.646
B37: 쏠비치 진도 | C37: Y | D37: 561 | E37: 0.52 | F37: 0.667 | G37: 0.294 | H37: 0.581
B38: 벨메르 한화 | D38: 100 | E38: 0.435 | F38: 0.493 | G38: 0.436 | H38: 0.625
B39: 신라스테이 여수 | D39: 315 | E39: 0.81 | F39: 0.842 | G39: 0.724 | H39: 0.825
B40: 유탑마리나 | D40: 298 | E40: 0.646 | F40: 0.687 | G40: 0.554 | H40: 0.692
...

Sheet 2025
A1: 지역 | B1: 시설명 | C1: 자사 | D1: 가용객실수 | E1: 1월 | F1: 2월 | G1: 3월 | H1: 4월
A2: 강원도 서부 지역
B3: 소노캄 비발디파크 | C3: Y | D3: 1723 | E3: 0.791 | F3: 0.756 | G3: 0.258 | H3: 0.342
B4: 소노벨리체 비발디 | C4: Y | D4: 500 | E4: 0.569 | F4: 0.472 | G4: 0.158 | H4: 0.274
B5: 소노펠리체 빌리지 비발디 | C5: Y | D5: 219 | E5: 0.477 | F5: 0.343 | G5: 0.205 | H5: 0.304
B6: 용평 | D6: 1298 | E6: 0.873 | F6: 0.761 | G6: 0.33 | H6: 0.183
B7: 휘닉스파크 | D7: 962 | E7: 0.735 | F7: 0.607 | G7: 0.213 | H7: 0.225
B8: 오크밸리 | D8: 1105 | E8: 0.544 | F8: 0.417 | G8: 0.225 | H8: 0.477
B9: 웰리힐리 | D9: 766 | E9: 0.73 | F9: 0.576 | G9: 0.122 | H9: 0.166
B10: 소노휴 양평 | C10: Y | D10: 189 | E10: 0.585 | F10: 0.465 | G10: 0.399 | H10: 0.506
A11: 강원도 동부 지역
B12: 델피노 | C12: Y | D12: 1196 | E12: 0.656 | F12: 0.547 | G12: 0.311 | H12: 0.429
B13: 쏠비치 양양 | C13: Y | D13: 501 | E13: 0.565 | F13: 0.535 | G13: 0.383 | H13: 0.533
B14: 쏠비치 삼척 | C14: Y | D14: 707 | E14: 0.612 | F14: 0.646 | G14: 0.429 | H14: 0.607
B15: 롯데리조트 속초 | D15: 392 | E15: 0.631 | F15: 0.633 | G15: 0.549 | H15: 0.737
B16: 카시아리조트(반얀트리) | D16: 674 | E16: 0.29 | F16: 0.26 | G16: 0.24 | H16: 0.25
B17: 한화리조트 속초 | D17: 1554 | E17: 0.468 | F17: 0.381 | G17: 0.15 | H17: 0.468
B18: 한화브리드 양양 | D18: 56 | E18: 0.819 | F18: 0.885 | G18: 0.696 | H18: 0.705
B19: 르네블루 by 워커힐 고성 | D19: 87 | E19: 0.758 | F19: 0.761 | G19: 0.629 | H19: 0.682
B20: 켄싱턴리조트 속초 | D20: 176 | E20: 0.78 | F20: 0.85 | G20: 0.583 | H20: 0.74
A21: 경상도 지역
B22: 소노캄 경주 | C22: Y | D22: 410 | E22: 0 | F22: 0 | G22: 0 | H22: 0
B23: 라한셀렉트 | D23: 430 | E23: 0.82 | F23: 0.85 | G23: 0.885 | H23: 0.87
B24: 켄싱턴 | D24: 501 | E24: 0.494 | F24: 0.553 | G24: 0.451 | H24: 0.65
B25: 한화리조트 경주 | D25: 393 | E25: 0.551 | F25: 0.417 | G25: 0.382 | H25: 0.625
B26: 소노벨 단양 | C26: Y | D26: 830 | E26: 0.563 | F26: 0.407 | G26: 0.496 | H26: 0.603
B27: 포레스트 리솜 | D27: 450 | E27: 0.858 | F27: 0.806 | G27: 0.631 | H27: 0.719
B28: 소노벨 청송 | C28: Y | D28: 306 | E28: 0.691 | F28: 0.626 | G28: 0.279 | H28: 0.362
A29: 충청/전북 지역
B30: 소노벨 천안 | C30: Y | D30: 438 | E30: 0.767 | F30: 0.743 | G30: 0.471 | H30: 0.554
B31: 덕산스폴라스 리솜 | D31: 405 | E31: 0.894 | F31: 0.832 | G31: 0.352 | H31: 0.369
B32: 안면도 아일랜드 리솜 | D32: 248 | E32: 0.62 | F32: 0.671 | G32: 0.424 | H32: 0.579
B33: 소노벨 변산 | C33: Y | D33: 502 | E33: 0.603 | F33: 0.595 | G33: 0.416 | H33: 0.537
A34: 전라/경상남도 지역
B35: 소노캄 여수 | C35: Y | D35: 309 | E35: 0.492 | F35: 0.498 | G35: 0.531 | H35: 0.602
B36: 벨메르 한화 | D36: 100 | E36: 0.442 | F36: 0.474 | G36: 0.474 | H36: 0.637
B37: 신라스테이 여수 | D37: 315 | E37: 0.724 | F37: 0.75 | G37: 0.656 | H37: 0.776
B38: 유탑마리나 | D38: 298 | E38: 0.75 | F38: 0.808 | G38: 0.659 | H38: 0.741
B39: 소노캄 거제 | C39: Y | D39: 479 | E39: 0.608 | F39: 0.618 | G39: 0.446 | H39: 0.647
B40: 한화리조트 벨버디어 | D40: 470 | E40: 0.548 | F40: 0.517 | G40: 0.339 | H40: 0.428
...
