Workbook

Sheet 팔라티움 해운대
C2: 사업장별 실적 현황 [팔라티움 해운대]
F6: =CA169 -> 7378 | L6: =CA170 -> 0 | R6: =CA171 -> 0 | X6: =CA172 -> 0 | AD6: =CA173 -> 0 | AJ6: =CA174 -> 0 | AP6: =CA175 -> 0 | BM6: [ 단위 : RN_실, ADR_천원, Revenue_천원 / VAT제외 ] | BS6: [ 단위 : RN_실, ADR_천원, Revenue_천원 / VAT제외 ]
C7: Segment | F7: 2026 Budget | L7: 2026 Actual | R7: 2025 Actual | X7: 2023 Actual | AD7: 2022 Actual | AJ7: 2021 Actual | AP7: 2020 Actual | AV7: 2026 Actual vs. 2026 Budget | BB7: 2026 Actual vs. 2025 Actual | BH7: 2026 Actual vs. 2024 Actual | BN7: 2025 Actual vs. 2020 Actual | BX7: ※ 실적 입력 | CA7: =SUM(CA10:CA165) -> 45056 | CC7: =SUM(CC10:CC165) -> 0 | CE7: =SUM(CE10:CE165) -> 0 | CG7: =SUM(CG10:CG165) -> 0 | CI7: =SUM(CI10:CI165) -> 0 | CK7: =SUM(CK10:CK165) -> 0 | CM7: =SUM(CM10:CM165) -> 0
F8: RN | H8: ADR | J8: Revenue | L8: RN | N8: ADR | P8: Revenue | R8: RN | T8: ADR | V8: Revenue | X8: RN | Z8: ADR | AB8: Revenue | AD8: RN | AF8: ADR | AH8: 매 출 | AJ8: RN | AL8: ADR | AN8: 매 출 | AP8: RN | AR8: ADR | AT8: 매 출 | AV8: RN | AX8: ADR | AZ8: Revenue | BB8: RN | BD8: ADR | BF8: Revenue | BH8: RN | BJ8: ADR | BL8: Revenue | BN8: RN | BP8: ADR | BR8: Revenue | BX8: 구 분 | CA8: 2026년 목표 | CC8: 2026년 실적 | CE8: 2025년 실적 | CG8: 2024년 실적 | CI8: 2023년 실적 | CK8: 2022년 실적 | CM8: 2021년 실적
G9: % | I9: 지 수 | K9: % | M9: % | O9: 지 수 | Q9: % | S9: % | U9: 지 수 | W9: % | Y9: % | AA9: 지 수 | AC9: % | AE9: % | AG9: 지 수 | AI9: % | AK9: % | AM9: 지 수 | AO9: % | AQ9: % | AS9: 지 수 | AU9: % | AW9: 증감율 | AY9: 증감율 | BA9: 증감율 | BC9: 증감율 | BE9: 증감율 | BG9: 증감율 | BI9: 증감율 | BK9: 증감율 | BM9: 증감율 | BO9: 증감율 | BQ9: 증감율 | BS9: 증감율 | CA9: 객실수 | CB9: 매 출 | CC9: 객실수 | CD9: 매 출 | CE9: 객실수 | CF9: 매 출 | CG9: 객실수 | CH9: 매 출 | CI9: 객실수 | CJ9: 매 출 | CK9: 객실수 | CL9: 매 출 | CM9: 객실수 | CN9: 매 출
C10: 1월 | D10: Membership | E10: 기 명 | F10: =CA10 -> 283 | G10: =IFERROR(F10/F26,0) -> 0.072806792 | H10: =IFERROR(J10/F10,"0") -> 0 | I10: =IFERROR(H10/H11,0) -> 0 | J10: =CB10 -> 0 | K10: =IFERROR(J10/J26,0) -> 0 | L10: =CC10 -> 0 | M10: =IFERROR(L10/L26,0) -> 0 | N10: =IFERROR(P10/L10,"0") -> 0 | O10: =IFERROR(N10/N11,0) -> 0 | P10: =CD10 -> 0 | Q10: =IFERROR(P10/P26,0) -> 0 | R10: =CE10 -> 0 | S10: =IFERROR(R10/R26,0) -> 0 | T10: =IFERROR(V10/R10,"0") -> 0 | U10: =IFERROR(T10/T11,0) -> 0 | V10: =CF10 -> 0 | W10: =IFERROR(V10/V26,0) -> 0 | X10: =CG10 -> 0 | Y10: =IFERROR(X10/X26,0) -> 0 | Z10: =IFERROR(AB10/X10,"0") -> 0 | AA10: =IFERROR(Z10/Z11,0) -> 0 | AB10: =CH10 -> 0 | AC10: =IFERROR(AB10/AB26,0) -> 0 | AD10: =CI10 -> 0 | AE10: =IFERROR(AD10/AD26,0) -> 0 | AF10: =IFERROR(AH10/AD10,"0") -> 0 | AG10: =IFERROR(AF10/AF11,0) -> 0 | AH10: =CJ10 -> 0 | AI10: =IFERROR(AH10/AH26,0) -> 0 | AJ10: =CK10 -> 0 | AK10: =IFERROR(AJ10/AJ26,0) -> 0 | AL10: =IFERROR(AN10/AJ10,"0") -> 0 | AM10: =IFERROR(AL10/AL11,0) -> 0 | AN10: =CL10 -> 0 | AO10: =IFERROR(AN10/AN26,0) -> 0 | AP10: =CM10 -> 0 | AQ10: =IFERROR(AP10/AP26,0) -> 0 | AR10: =IFERROR(AT10/AP10,"0") -> 0 | AS10: =IFERROR(AR10/AR11,0) -> 0 | AT10: =CN10 -> 0 | AU10: =IFERROR(AT10/AT26,0) -> 0 | AV10: =IFERROR(L10-F10,0) -> -283 | AW10: =IFERROR(AV10/F10,0) -> -1 | AX10: =IFERROR(N10-H10,0) -> 0 | AY10: =IFERROR(AX10/H10,0) -> 0 | AZ10: =IFERROR(P10-J10,0) -> 0 | BA10: =IFERROR(AZ10/J10,0) -> 0 | BB10: =IFERROR(L10-R10,0) -> 0 | BC10: =IFERROR(BB10/R10,0) -> 0 | BD10: =IFERROR(N10-T10,0) -> 0 | BE10: =IFERROR(BD10/T10,0) -> 0 | BF10: =IFERROR(P10-V10,0) -> 0 | BG10: =IFERROR(BF10/V10,0) -> 0 | BH10: =IFERROR(L10-X10,0) -> 0 | BI10: =IFERROR(BH10/X10,0) -> 0 | BJ10: =IFERROR(N10-Z10,0) -> 0 | BK10: =IFERROR(BJ10/Z10,0) -> 0 | BL10: =IFERROR(P10-AB10,0) -> 0 | BM10: =IFERROR(BL10/AB10,0) -> 0 | BN10: =IFERROR(L10-AP10,0) -> 0 | BO10: =IFERROR(BN10/AP10,0) -> 0 | BP10: =IFERROR(N10-AR10,0) -> 0 | BQ10: =IFERROR(BP10/AR10,0) -> 0 | BR10: =IFERROR(P10-AT10,0) -> 0 | BS10: =IFERROR(BR10/AT10,0) -> 0 | BX10: 1월 | BY10: 회 원 | BZ10: 기 명 | CA10: =기존구분!$E$46 -> 283
E11: 무기명 | F11: =CA11 -> 1047 | G11: =IFERROR(F11/F26,0) -> 0.2693594 | H11: =IFERROR(J11/F11,"0") -> 282.16527 | I11: =IFERROR(H11/H11,0) -> 1 | J11: =CB11 -> 295427.04 | K11: =IFERROR(J11/J26,0) -> 0.26235166 | L11: =CC11 -> 0 | M11: =IFERROR(L11/L26,0) -> 0 | N11: =IFERROR(P11/L11,"0") -> 0 | O11: =IFERROR(N11/N11,0) -> 0 | P11: =CD11 -> 0 | Q11: =IFERROR(P11/P26,0) -> 0 | R11: =CE11 -> 0 | S11: =IFERROR(R11/R26,0) -> 0 | T11: =IFERROR(V11/R11,"0") -> 0 | U11: =IFERROR(T11/T11,0) -> 0 | V11: =CF11 -> 0 | W11: =IFERROR(V11/V26,0) -> 0 | X11: =CG11 -> 0 | Y11: =IFERROR(X11/X26,0) -> 0 | Z11: =IFERROR(AB11/X11,"0") -> 0 | AA11: =IFERROR(Z11/Z11,0) -> 0 | AB11: =CH11 -> 0 | AC11: =IFERROR(AB11/AB26,0) -> 0 | AD11: =CI11 -> 0 | AE11: =IFERROR(AD11/AD26,0) -> 0 | AF11: =IFERROR(AH11/AD11,"0") -> 0 | AG11: =IFERROR(AF11/AF11,0) -> 0 | AH11: =CJ11 -> 0 | AI11: =IFERROR(AH11/AH26,0) -> 0 | AJ11: =CK11 -> 0 | AK11: =IFERROR(AJ11/AJ26,0) -> 0 | AL11: =IFERROR(AN11/AJ11,"0") -> 0 | AM11: =IFERROR(AL11/AL11,0) -> 0 | AN11: =CL11 -> 0 | AO11: =IFERROR(AN11/AN26,0) -> 0 | AP11: =CM11 -> 0 | AQ11: =IFERROR(AP11/AP26,0) -> 0 | AR11: =IFERROR(AT11/AP11,"0") -> 0 | AS11: =IFERROR(AR11/AR11,0) -> 0 | AT11: =CN11 -> 0 | AU11: =IFERROR(AT11/AT26,0) -> 0 | AV11: =IFERROR(L11-F11,0) -> -1047 | AW11: =IFERROR(AV11/F11,0) -> -1 | AX11: =IFERROR(N11-H11,0) -> -282.16527 | AY11: =IFERROR(AX11/H11,0) -> -1 | AZ11: =IFERROR(P11-J11,0) -> -295427.04 | BA11: =IFERROR(AZ11/J11,0) -> -1 | BB11: =IFERROR(L11-R11,0) -> 0 | BC11: =IFERROR(BB11/R11,0) -> 0 | BD11: =IFERROR(N11-T11,0) -> 0 | BE11: =IFERROR(BD11/T11,0) -> 0 | BF11: =IFERROR(P11-V11,0) -> 0 | BG11: =IFERROR(BF11/V11,0) -> 0 | BH11: =IFERROR(L11-X11,0) -> 0 | BI11: =IFERROR(BH11/X11,0) -> 0 | BJ11: =IFERROR(N11-Z11,0) -> 0 | BK11: =IFERROR(BJ11/Z11,0) -> 0 | BL11: =IFERROR(P11-AB11,0) -> 0 | BM11: =IFERROR(BL11/AB11,0) -> 0 | BN11: =IFERROR(L11-AP11,0) -> 0 | BO11: =IFERROR(BN11/AP11,0) -> 0 | BP11: =IFERROR(N11-AR11,0) -> 0 | BQ11: =IFERROR(BP11/AR11,0) -> 0 | BR11: =IFERROR(P11-AT11,0) -> 0 | BS11: =IFERROR(BR11/AT11,0) -> 0 | BZ11: 무기명 | CA11: =ROUND(기존구분!$E$45*(SUM('파나크 영덕'!L11,소노문해운대!L10:L11)/SUM('파나크 영덕'!L11:L13,소노문해운대!L10:L13)),0) -> 1047 | CB11: =CA11*기존구분!$E$53-1000 -> 295427.04
E12: Staff | F12: =CA12 -> 79 | G12: =IFERROR(F12/F26,0) -> 0.020324157 | H12: =IFERROR(J12/F12,"0") -> 295.77861 | I12: =IFERROR(H12/H11,0) -> 1.048246 | J12: =CB12 -> 23366.51 | K12: =IFERROR(J12/J26,0) -> 0.020750446 | L12: =CC12 -> 0 | M12: =IFERROR(L12/L26,0) -> 0 | N12: =IFERROR(P12/L12,"0") -> 0 | O12: =IFERROR(N12/N11,0) -> 0 | P12: =CD12 -> 0 | Q12: =IFERROR(P12/P26,0) -> 0 | R12: =CE12 -> 0 | S12: =IFERROR(R12/R26,0) -> 0 | T12: =IFERROR(V12/R12,"0") -> 0 | U12: =IFERROR(T12/T11,0) -> 0 | V12: =CF12 -> 0 | W12: =IFERROR(V12/V26,0) -> 0 | X12: =CG12 -> 0 | Y12: =IFERROR(X12/X26,0) -> 0 | Z12: =IFERROR(AB12/X12,"0") -> 0 | AA12: =IFERROR(Z12/Z11,0) -> 0 | AB12: =CH12 -> 0 | AC12: =IFERROR(AB12/AB26,0) -> 0 | AD12: =CI12 -> 0 | AE12: =IFERROR(AD12/AD26,0) -> 0 | AF12: =IFERROR(AH12/AD12,"0") -> 0 | AG12: =IFERROR(AF12/AF11,0) -> 0 | AH12: =CJ12 -> 0 | AI12: =IFERROR(AH12/AH26,0) -> 0 | AJ12: =CK12 -> 0 | AK12: =IFERROR(AJ12/AJ26,0) -> 0 | AL12: =IFERROR(AN12/AJ12,"0") -> 0 | AM12: =IFERROR(AL12/AL11,0) -> 0 | AN12: =CL12 -> 0 | AO12: =IFERROR(AN12/AN26,0) -> 0 | AP12: =CM12 -> 0 | AQ12: =IFERROR(AP12/AP26,0) -> 0 | AR12: =IFERROR(AT12/AP12,"0") -> 0 | AS12: =IFERROR(AR12/AR11,0) -> 0 | AT12: =CN12 -> 0 | AU12: =IFERROR(AT12/AT26,0) -> 0 | AV12: =IFERROR(L12-F12,0) -> -79 | AW12: =IFERROR(AV12/F12,0) -> -1 | AX12: =IFERROR(N12-H12,0) -> -295.77861 | AY12: =IFERROR(AX12/H12,0) -> -1 | AZ12: =IFERROR(P12-J12,0) -> -23366.51 | BA12: =IFERROR(AZ12/J12,0) -> -1 | BB12: =IFERROR(L12-R12,0) -> 0 | BC12: =IFERROR(BB12/R12,0) -> 0 | BD12: =IFERROR(N12-T12,0) -> 0 | BE12: =IFERROR(BD12/T12,0) -> 0 | BF12: =IFERROR(P12-V12,0) -> 0 | BG12: =IFERROR(BF12/V12,0) -> 0 | BH12: =IFERROR(L12-X12,0) -> 0 | BI12: =IFERROR(BH12/X12,0) -> 0 | BJ12: =IFERROR(N12-Z12,0) -> 0 | BK12: =IFERROR(BJ12/Z12,0) -> 0 | BL12: =IFERROR(P12-AB12,0) -> 0 | BM12: =IFERROR(BL12/AB12,0) -> 0 | BN12: =IFERROR(L12-AP12,0) -> 0 | BO12: =IFERROR(BN12/AP12,0) -> 0 | BP12: =IFERROR(N12-AR12,0) -> 0 | BQ12: =IFERROR(BP12/AR12,0) -> 0 | BR12: =IFERROR(P12-AT12,0) -> 0 | BS12: =IFERROR(BR12/AT12,0) -> 0 | BZ12: 직 원 | CA12: =ROUND(기존구분!$E$45*(SUM('파나크 영덕:소노문해운대'!L12)/SUM('파나크 영덕'!L11:L13,소노문해운대!L10:L13)),0) -> 79 | CB12: =CA12*기존구분!$E$53+1000 -> 23366.51
E13: Other | F13: =CA13 -> 19 | G13: =IFERROR(F13/F26,0) -> 0.0048880885 | H13: =IFERROR(J13/F13,"0") -> 283.12038 | I13: =IFERROR(H13/H11,0) -> 1.0033849 | J13: =CB13 -> 5379.2872 | K13: =IFERROR(J13/J26,0) -> 0.0047770338 | L13: =CC13 -> 0 | M13: =IFERROR(L13/L26,0) -> 0 | N13: =IFERROR(P13/L13,"0") -> 0 | O13: =IFERROR(N13/N11,0) -> 0 | P13: =CD13 -> 0 | Q13: =IFERROR(P13/P26,0) -> 0 | R13: =CE13 -> 0 | S13: =IFERROR(R13/R26,0) -> 0 | T13: =IFERROR(V13/R13,"0") -> 0 | U13: =IFERROR(T13/T11,0) -> 0 | V13: =CF13 -> 0 | W13: =IFERROR(V13/V26,0) -> 0 | X13: =CG13 -> 0 | Y13: =IFERROR(X13/X26,0) -> 0 | Z13: =IFERROR(AB13/X13,"0") -> 0 | AA13: =IFERROR(Z13/Z11,0) -> 0 | AB13: =CH13 -> 0 | AC13: =IFERROR(AB13/AB26,0) -> 0 | AD13: =CI13 -> 0 | AE13: =IFERROR(AD13/AD26,0) -> 0 | AF13: =IFERROR(AH13/AD13,"0") -> 0 | AG13: =IFERROR(AF13/AF11,0) -> 0 | AH13: =CJ13 -> 0 | AI13: =IFERROR(AH13/AH26,0) -> 0 | AJ13: =CK13 -> 0 | AK13: =IFERROR(AJ13/AJ26,0) -> 0 | AL13: =IFERROR(AN13/AJ13,"0") -> 0 | AM13: =IFERROR(AL13/AL11,0) -> 0 | AN13: =CL13 -> 0 | AO13: =IFERROR(AN13/AN26,0) -> 0 | AP13: =CM13 -> 0 | AQ13: =IFERROR(AP13/AP26,0) -> 0 | AR13: =IFERROR(AT13/AP13,"0") -> 0 | AS13: =IFERROR(AR13/AR11,0) -> 0 | AT13: =CN13 -> 0 | AU13: =IFERROR(AT13/AT26,0) -> 0 | AV13: =IFERROR(L13-F13,0) -> -19 | AW13: =IFERROR(AV13/F13,0) -> -1 | AX13: =IFERROR(N13-H13,0) -> -283.12038 | AY13: =IFERROR(AX13/H13,0) -> -1 | AZ13: =IFERROR(P13-J13,0) -> -5379.2872 | BA13: =IFERROR(AZ13/J13,0) -> -1 | BB13: =IFERROR(L13-R13,0) -> 0 | BC13: =IFERROR(BB13/R13,0) -> 0 | BD13: =IFERROR(N13-T13,0) -> 0 | BE13: =IFERROR(BD13/T13,0) -> 0 | BF13: =IFERROR(P13-V13,0) -> 0 | BG13: =IFERROR(BF13/V13,0) -> 0 | BH13: =IFERROR(L13-X13,0) -> 0 | BI13: =IFERROR(BH13/X13,0) -> 0 | BJ13: =IFERROR(N13-Z13,0) -> 0 | BK13: =IFERROR(BJ13/Z13,0) -> 0 | BL13: =IFERROR(P13-AB13,0) -> 0 | BM13: =IFERROR(BL13/AB13,0) -> 0 | BN13: =IFERROR(L13-AP13,0) -> 0 | BO13: =IFERROR(BN13/AP13,0) -> 0 | BP13: =IFERROR(N13-AR13,0) -> 0 | BQ13: =IFERROR(BP13/AR13,0) -> 0 | BR13: =IFERROR(P13-AT13,0) -> 0 | BS13: =IFERROR(BR13/AT13,0) -> 0 | BZ13: 기 타 | CA13: =ROUND(기존구분!$E$45*(SUM('파나크 영덕:소노문해운대'!L13)/SUM('파나크 영덕'!L11:L13,소노문해운대!L10:L13)),0) -> 19 | CB13: =CA13*기존구분!$E$53 -> 5379.2872
E14: Total | F14: =SUM(F10:F13) -> 1428 | G14: =IFERROR(F14/F26,0) -> 0.36737844 | H14: =IFERROR(J14/F14,"0") -> 227.01179 | I14: =IFERROR(H14/H11,0) -> 0.80453484 | J14: =SUM(J10:J13) -> 324172.83 | K14: =IFERROR(J14/J26,0) -> 0.28787914 | L14: =SUM(L10:L13) -> 0 | M14: =IFERROR(L14/L26,0) -> 0 | N14: =IFERROR(P14/L14,"0") -> 0 | O14: =IFERROR(N14/N11,0) -> 0 | P14: =SUM(P10:P13) -> 0 | Q14: =IFERROR(P14/P26,0) -> 0 | R14: =SUM(R10:R13) -> 0 | S14: =IFERROR(R14/R26,0) -> 0 | T14: =IFERROR(V14/R14,"0") -> 0 | U14: =IFERROR(T14/T11,0) -> 0 | V14: =SUM(V10:V13) -> 0 | W14: =IFERROR(V14/V26,0) -> 0 | X14: =SUM(X10:X13) -> 0 | Y14: =IFERROR(X14/X26,0) -> 0 | Z14: =IFERROR(AB14/X14,"0") -> 0 | AA14: =IFERROR(Z14/Z11,0) -> 0 | AB14: =SUM(AB10:AB13) -> 0 | AC14: =IFERROR(AB14/AB26,0) -> 0 | AD14: =SUM(AD10:AD13) -> 0 | AE14: =IFERROR(AD14/AD26,0) -> 0 | AF14: =IFERROR(AH14/AD14,"0") -> 0 | AG14: =IFERROR(AF14/AF11,0) -> 0 | AH14: =SUM(AH10:AH13) -> 0 | AI14: =IFERROR(AH14/AH26,0) -> 0 | AJ14: =SUM(AJ10:AJ13) -> 0 | AK14: =IFERROR(AJ14/AJ26,0) -> 0 | AL14: =IFERROR(AN14/AJ14,"0") -> 0 | AM14: =IFERROR(AL14/AL11,0) -> 0 | AN14: =SUM(AN10:AN13) -> 0 | AO14: =IFERROR(AN14/AN26,0) -> 0 | AP14: =SUM(AP10:AP13) -> 0 | AQ14: =IFERROR(AP14/AP26,0) -> 0 | AR14: =IFERROR(AT14/AP14,"0") -> 0 | AS14: =IFERROR(AR14/AR11,0) -> 0 | AT14: =SUM(AT10:AT13) -> 0 | AU14: =IFERROR(AT14/AT26,0) -> 0 | AV14: =IFERROR(L14-F14,0) -> -1428 | AW14: =IFERROR(AV14/F14,0) -> -1 | AX14: =IFERROR(N14-H14,0) -> -227.01179 | AY14: =IFERROR(AX14/H14,0) -> -1 | AZ14: =IFERROR(P14-J14,0) -> -324172.83 | BA14: =IFERROR(AZ14/J14,0) -> -1 | BB14: =IFERROR(L14-R14,0) -> 0 | BC14: =IFERROR(BB14/R14,0) -> 0 | BD14: =IFERROR(N14-T14,0) -> 0 | BE14: =IFERROR(BD14/T14,0) -> 0 | BF14: =IFERROR(P14-V14,0) -> 0 | BG14: =IFERROR(BF14/V14,0) -> 0 | BH14: =IFERROR(L14-X14,0) -> 0 | BI14: =IFERROR(BH14/X14,0) -> 0 | BJ14: =IFERROR(N14-Z14,0) -> 0 | BK14: =IFERROR(BJ14/Z14,0) -> 0 | BL14: =IFERROR(P14-AB14,0) -> 0 | BM14: =IFERROR(BL14/AB14,0) -> 0 | BN14: =IFERROR(L14-AP14,0) -> 0 | BO14: =IFERROR(BN14/AP14,0) -> 0 | BP14: =IFERROR(N14-AR14,0) -> 0 | BQ14: =IFERROR(BP14/AR14,0) -> 0 | BR14: =IFERROR(P14-AT14,0) -> 0 | BS14: =IFERROR(BR14/AT14,0) -> 0 | BY14: 단 체 | BZ14: 일 반 | CA14: =ROUND(기존구분!$E$44*(SUM('파나크 영덕:소노문해운대'!L15)/SUM('파나크 영덕:소노문해운대'!$L$18,'파나크 영덕:소노문해운대'!$L$24,'파나크 영덕:소노문해운대'!$L$25)),0) -> 486 | CB14: =CA14*기존구분!$E$52-30000 -> 128488.48
D15: Group | E15: G-Mice | F15: =CA14 -> 486 | G15: =IFERROR(F15/F26,0) -> 0.12503216 | H15: =IFERROR(J15/F15,"0") -> 264.37958 | I15: =IFERROR(H15/H11,0) -> 0.93696712 | J15: =CB14 -> 128488.48 | K15: =IFERROR(J15/J26,0) -> 0.11410318 | L15: =CC14 -> 0 | M15: =IFERROR(L15/L26,0) -> 0 | N15: =IFERROR(P15/L15,"0") -> 0 | O15: =IFERROR(N15/N11,0) -> 0 | P15: =CD14 -> 0 | Q15: =IFERROR(P15/P26,0) -> 0 | R15: =CE14 -> 0 | S15: =IFERROR(R15/R26,0) -> 0 | T15: =IFERROR(V15/R15,"0") -> 0 | U15: =IFERROR(T15/T11,0) -> 0 | V15: =CF14 -> 0 | W15: =IFERROR(V15/V26,0) -> 0 | X15: =CG14 -> 0 | Y15: =IFERROR(X15/X26,0) -> 0 | Z15: =IFERROR(AB15/X15,"0") -> 0 | AA15: =IFERROR(Z15/Z11,0) -> 0 | AB15: =CH14 -> 0 | AC15: =IFERROR(AB15/AB26,0) -> 0 | AD15: =CI14 -> 0 | AE15: =IFERROR(AD15/AD26,0) -> 0 | AF15: =IFERROR(AH15/AD15,"0") -> 0 | AG15: =IFERROR(AF15/AF11,0) -> 0 | AH15: =CJ14 -> 0 | AI15: =IFERROR(AH15/AH26,0) -> 0 | AJ15: =CK14 -> 0 | AK15: =IFERROR(AJ15/AJ26,0) -> 0 | AL15: =IFERROR(AN15/AJ15,"0") -> 0 | AM15: =IFERROR(AL15/AL11,0) -> 0 | AN15: =CL14 -> 0 | AO15: =IFERROR(AN15/AN26,0) -> 0 | AP15: =CM14 -> 0 | AQ15: =IFERROR(AP15/AP26,0) -> 0 | AR15: =IFERROR(AT15/AP15,"0") -> 0 | AS15: =IFERROR(AR15/AR11,0) -> 0 | AT15: =CN14 -> 0 | AU15: =IFERROR(AT15/AT26,0) -> 0 | AV15: =IFERROR(L15-F15,0) -> -486 | AW15: =IFERROR(AV15/F15,0) -> -1 | AX15: =IFERROR(N15-H15,0) -> -264.37958 | AY15: =IFERROR(AX15/H15,0) -> -1 | AZ15: =IFERROR(P15-J15,0) -> -128488.48 | BA15: =IFERROR(AZ15/J15,0) -> -1 | BB15: =IFERROR(L15-R15,0) -> 0 | BC15: =IFERROR(BB15/R15,0) -> 0 | BD15: =IFERROR(N15-T15,0) -> 0 | BE15: =IFERROR(BD15/T15,0) -> 0 | BF15: =IFERROR(P15-V15,0) -> 0 | BG15: =IFERROR(BF15/V15,0) -> 0 | BH15: =IFERROR(L15-X15,0) -> 0 | BI15: =IFERROR(BH15/X15,0) -> 0 | BJ15: =IFERROR(N15-Z15,0) -> 0 | BK15: =IFERROR(BJ15/Z15,0) -> 0 | BL15: =IFERROR(P15-AB15,0) -> 0 | BM15: =IFERROR(BL15/AB15,0) -> 0 | BN15: =IFERROR(L15-AP15,0) -> 0 | BO15: =IFERROR(BN15/AP15,0) -> 0 | BP15: =IFERROR(N15-AR15,0) -> 0 | BQ15: =IFERROR(BP15/AR15,0) -> 0 | BR15: =IFERROR(P15-AT15,0) -> 0 | BS15: =IFERROR(BR15/AT15,0) -> 0 | BZ15: 학 생 | CA15: =ROUND(기존구분!$E$44*(SUM('파나크 영덕:소노문해운대'!L16)/SUM('파나크 영덕:소노문해운대'!$L$18,'파나크 영덕:소노문해운대'!$L$24,'파나크 영덕:소노문해운대'!$L$25)),0) -> 0 | CB15: =CA15*기존구분!$E$52 -> 0
E16: E-Mice | F16: =CA15 -> 0 | G16: =IFERROR(F16/F26,0) -> 0 | H16: =IFERROR(J16/F16,"0") -> 0 | I16: =IFERROR(H16/H11,0) -> 0 | J16: =CB15 -> 0 | K16: =IFERROR(J16/J26,0) -> 0 | L16: =CC15 -> 0 | M16: =IFERROR(L16/L26,0) -> 0 | N16: =IFERROR(P16/L16,"0") -> 0 | O16: =IFERROR(N16/N11,0) -> 0 | P16: =CD15 -> 0 | Q16: =IFERROR(P16/P26,0) -> 0 | R16: =CE15 -> 0 | S16: =IFERROR(R16/R26,0) -> 0 | T16: =IFERROR(V16/R16,"0") -> 0 | U16: =IFERROR(T16/T11,0) -> 0 | V16: =CF15 -> 0 | W16: =IFERROR(V16/V26,0) -> 0 | X16: =CG15 -> 0 | Y16: =IFERROR(X16/X26,0) -> 0 | Z16: =IFERROR(AB16/X16,"0") -> 0 | AA16: =IFERROR(Z16/Z11,0) -> 0 | AB16: =CH15 -> 0 | AC16: =IFERROR(AB16/AB26,0) -> 0 | AD16: =CI15 -> 0 | AE16: =IFERROR(AD16/AD26,0) -> 0 | AF16: =IFERROR(AH16/AD16,"0") -> 0 | AG16: =IFERROR(AF16/AF11,0) -> 0 | AH16: =CJ15 -> 0 | AI16: =IFERROR(AH16/AH26,0) -> 0 | AJ16: =CK15 -> 0 | AK16: =IFERROR(AJ16/AJ26,0) -> 0 | AL16: =IFERROR(AN16/AJ16,"0") -> 0 | AM16: =IFERROR(AL16/AL11,0) -> 0 | AN16: =CL15 -> 0 | AO16: =IFERROR(AN16/AN26,0) -> 0 | AP16: =CM15 -> 0 | AQ16: =IFERROR(AP16/AP26,0) -> 0 | AR16: =IFERROR(AT16/AP16,"0") -> 0 | AS16: =IFERROR(AR16/AR11,0) -> 0 | AT16: =CN15 -> 0 | AU16: =IFERROR(AT16/AT26,0) -> 0 | AV16: =IFERROR(L16-F16,0) -> 0 | AW16: =IFERROR(AV16/F16,0) -> 0 | AX16: =IFERROR(N16-H16,0) -> 0 | AY16: =IFERROR(AX16/H16,0) -> 0 | AZ16: =IFERROR(P16-J16,0) -> 0 | BA16: =IFERROR(AZ16/J16,0) -> 0 | BB16: =IFERROR(L16-R16,0) -> 0 | BC16: =IFERROR(BB16/R16,0) -> 0 | BD16: =IFERROR(N16-T16,0) -> 0 | BE16: =IFERROR(BD16/T16,0) -> 0 | BF16: =IFERROR(P16-V16,0) -> 0 | BG16: =IFERROR(BF16/V16,0) -> 0 | BH16: =IFERROR(L16-X16,0) -> 0 | BI16: =IFERROR(BH16/X16,0) -> 0 | BJ16: =IFERROR(N16-Z16,0) -> 0 | BK16: =IFERROR(BJ16/Z16,0) -> 0 | BL16: =IFERROR(P16-AB16,0) -> 0 | BM16: =IFERROR(BL16/AB16,0) -> 0 | BN16: =IFERROR(L16-AP16,0) -> 0 | BO16: =IFERROR(BN16/AP16,0) -> 0 | BP16: =IFERROR(N16-AR16,0) -> 0 | BQ16: =IFERROR(BP16/AR16,0) -> 0 | BR16: =IFERROR(P16-AT16,0) -> 0 | BS16: =IFERROR(BR16/AT16,0) -> 0 | BZ16: 인바운드 | CA16: =ROUND(기존구분!$E$44*(SUM('파나크 영덕:소노문해운대'!L17)/SUM('파나크 영덕:소노문해운대'!$L$18,'파나크 영덕:소노문해운대'!$L$24,'파나크 영덕:소노문해운대'!$L$25)),0) -> 283 | CB16: =CA16*기존구분!$E$52-20000 -> 72288.557
E17: Inbound | F17: =CA16 -> 283 | G17: =IFERROR(F17/F26,0) -> 0.072806792 | H17: =IFERROR(J17/F17,"0") -> 255.4366 | I17: =IFERROR(H17/H11,0) -> 0.90527299 | J17: =CB16 -> 72288.557 | K17: =IFERROR(J17/J26,0) -> 0.064195286 | L17: =CC16 -> 0 | M17: =IFERROR(L17/L26,0) -> 0 | N17: =IFERROR(P17/L17,"0") -> 0 | O17: =IFERROR(N17/N11,0) -> 0 | P17: =CD16 -> 0 | Q17: =IFERROR(P17/P26,0) -> 0 | R17: =CE16 -> 0 | S17: =IFERROR(R17/R26,0) -> 0 | T17: =IFERROR(V17/R17,"0") -> 0 | U17: =IFERROR(T17/T11,0) -> 0 | V17: =CF16 -> 0 | W17: =IFERROR(V17/V26,0) -> 0 | X17: =CG16 -> 0 | Y17: =IFERROR(X17/X26,0) -> 0 | Z17: =IFERROR(AB17/X17,"0") -> 0 | AA17: =IFERROR(Z17/Z11,0) -> 0 | AB17: =CH16 -> 0 | AC17: =IFERROR(AB17/AB26,0) -> 0 | AD17: =CI16 -> 0 | AE17: =IFERROR(AD17/AD26,0) -> 0 | AF17: =IFERROR(AH17/AD17,"0") -> 0 | AG17: =IFERROR(AF17/AF11,0) -> 0 | AH17: =CJ16 -> 0 | AI17: =IFERROR(AH17/AH26,0) -> 0 | AJ17: =CK16 -> 0 | AK17: =IFERROR(AJ17/AJ26,0) -> 0 | AL17: =IFERROR(AN17/AJ17,"0") -> 0 | AM17: =IFERROR(AL17/AL11,0) -> 0 | AN17: =CL16 -> 0 | AO17: =IFERROR(AN17/AN26,0) -> 0 | AP17: =CM16 -> 0 | AQ17: =IFERROR(AP17/AP26,0) -> 0 | AR17: =IFERROR(AT17/AP17,"0") -> 0 | AS17: =IFERROR(AR17/AR11,0) -> 0 | AT17: =CN16 -> 0 | AU17: =IFERROR(AT17/AT26,0) -> 0 | AV17: =IFERROR(L17-F17,0) -> -283 | AW17: =IFERROR(AV17/F17,0) -> -1 | AX17: =IFERROR(N17-H17,0) -> -255.4366 | AY17: =IFERROR(AX17/H17,0) -> -1 | AZ17: =IFERROR(P17-J17,0) -> -72288.557 | BA17: =IFERROR(AZ17/J17,0) -> -1 | BB17: =IFERROR(L17-R17,0) -> 0 | BC17: =IFERROR(BB17/R17,0) -> 0 | BD17: =IFERROR(N17-T17,0) -> 0 | BE17: =IFERROR(BD17/T17,0) -> 0 | BF17: =IFERROR(P17-V17,0) -> 0 | BG17: =IFERROR(BF17/V17,0) -> 0 | BH17: =IFERROR(L17-X17,0) -> 0 | BI17: =IFERROR(BH17/X17,0) -> 0 | BJ17: =IFERROR(N17-Z17,0) -> 0 | BK17: =IFERROR(BJ17/Z17,0) -> 0 | BL17: =IFERROR(P17-AB17,0) -> 0 | BM17: =IFERROR(BL17/AB17,0) -> 0 | BN17: =IFERROR(L17-AP17,0) -> 0 | BO17: =IFERROR(BN17/AP17,0) -> 0 | BP17: =IFERROR(N17-AR17,0) -> 0 | BQ17: =IFERROR(BP17/AR17,0) -> 0 | BR17: =IFERROR(P17-AT17,0) -> 0 | BS17: =IFERROR(BR17/AT17,0) -> 0 | BY17: 일 반 | BZ17: 홈페이지 | CA17: =ROUND(기존구분!$E$44*(SUM('파나크 영덕:소노문해운대'!L19)/SUM('파나크 영덕:소노문해운대'!$L$18,'파나크 영덕:소노문해운대'!$L$24,'파나크 영덕:소노문해운대'!$L$25)),0) -> 309 | CB17: =CA17*기존구분!$E$52+5000+10088 -> 115855.36
E18: Total | F18: =SUM(F15:F17) -> 769 | G18: =IFERROR(F18/F26,0) -> 0.19783895 | H18: =IFERROR(J18/F18,"0") -> 261.08847 | I18: =IFERROR(H18/H11,0) -> 0.92530335 | J18: =SUM(J15:J17) -> 200777.03 | K18: =IFERROR(J18/J26,0) -> 0.17829847 | L18: =SUM(L15:L17) -> 0 | M18: =IFERROR(L18/L26,0) -> 0 | N18: =IFERROR(P18/L18,"0") -> 0 | O18: =IFERROR(N18/N11,0) -> 0 | P18: =SUM(P15:P17) -> 0 | Q18: =IFERROR(P18/P26,0) -> 0 | R18: =SUM(R15:R17) -> 0 | S18: =IFERROR(R18/R26,0) -> 0 | T18: =IFERROR(V18/R18,"0") -> 0 | U18: =IFERROR(T18/T11,0) -> 0 | V18: =SUM(V15:V17) -> 0 | W18: =IFERROR(V18/V26,0) -> 0 | X18: =SUM(X15:X17) -> 0 | Y18: =IFERROR(X18/X26,0) -> 0 | Z18: =IFERROR(AB18/X18,"0") -> 0 | AA18: =IFERROR(Z18/Z11,0) -> 0 | AB18: =SUM(AB15:AB17) -> 0 | AC18: =IFERROR(AB18/AB26,0) -> 0 | AD18: =SUM(AD15:AD17) -> 0 | AE18: =IFERROR(AD18/AD26,0) -> 0 | AF18: =IFERROR(AH18/AD18,"0") -> 0 | AG18: =IFERROR(AF18/AF11,0) -> 0 | AH18: =SUM(AH15:AH17) -> 0 | AI18: =IFERROR(AH18/AH26,0) -> 0 | AJ18: =SUM(AJ15:AJ17) -> 0 | AK18: =IFERROR(AJ18/AJ26,0) -> 0 | AL18: =IFERROR(AN18/AJ18,"0") -> 0 | AM18: =IFERROR(AL18/AL11,0) -> 0 | AN18: =SUM(AN15:AN17) -> 0 | AO18: =IFERROR(AN18/AN26,0) -> 0 | AP18: =SUM(AP15:AP17) -> 0 | AQ18: =IFERROR(AP18/AP26,0) -> 0 | AR18: =IFERROR(AT18/AP18,"0") -> 0 | AS18: =IFERROR(AR18/AR11,0) -> 0 | AT18: =SUM(AT15:AT17) -> 0 | AU18: =IFERROR(AT18/AT26,0) -> 0 | AV18: =IFERROR(L18-F18,0) -> -769 | AW18: =IFERROR(AV18/F18,0) -> -1 | AX18: =IFERROR(N18-H18,0) -> -261.08847 | AY18: =IFERROR(AX18/H18,0) -> -1 | AZ18: =IFERROR(P18-J18,0) -> -200777.03 | BA18: =IFERROR(AZ18/J18,0) -> -1 | BB18: =IFERROR(L18-R18,0) -> 0 | BC18: =IFERROR(BB18/R18,0) -> 0 | BD18: =IFERROR(N18-T18,0) -> 0 | BE18: =IFERROR(BD18/T18,0) -> 0 | BF18: =IFERROR(P18-V18,0) -> 0 | BG18: =IFERROR(BF18/V18,0) -> 0 | BH18: =IFERROR(L18-X18,0) -> 0 | BI18: =IFERROR(BH18/X18,0) -> 0 | BJ18: =IFERROR(N18-Z18,0) -> 0 | BK18: =IFERROR(BJ18/Z18,0) -> 0 | BL18: =IFERROR(P18-AB18,0) -> 0 | BM18: =IFERROR(BL18/AB18,0) -> 0 | BN18: =IFERROR(L18-AP18,0) -> 0 | BO18: =IFERROR(BN18/AP18,0) -> 0 | BP18: =IFERROR(N18-AR18,0) -> 0 | BQ18: =IFERROR(BP18/AR18,0) -> 0 | BR18: =IFERROR(P18-AT18,0) -> 0 | BS18: =IFERROR(BR18/AT18,0) -> 0 | BZ18: OTA | CA18: =ROUND(기존구분!$E$44*(SUM('파나크 영덕:소노문해운대'!L20)/SUM('파나크 영덕:소노문해운대'!$L$18,'파나크 영덕:소노문해운대'!$L$24,'파나크 영덕:소노문해운대'!$L$25)),0) -> 682 | CB18: =CA18*기존구분!$E$52+25000 -> 247405.64
D19: FIT | E19: Homepage | F19: =CA17 -> 309 | G19: =IFERROR(F19/F26,0) -> 0.079495755 | H19: =IFERROR(J19/F19,"0") -> 374.93645 | I19: =IFERROR(H19/H11,0) -> 1.3287832 | J19: =CB17 -> 115855.36 | K19: =IFERROR(J19/J26,0) -> 0.10288445 | L19: =CC17 -> 0 | M19: =IFERROR(L19/L26,0) -> 0 | N19: =IFERROR(P19/L19,"0") -> 0 | O19: =IFERROR(N19/N11,0) -> 0 | P19: =CD17 -> 0 | Q19: =IFERROR(P19/P26,0) -> 0 | R19: =CE17 -> 0 | S19: =IFERROR(R19/R26,0) -> 0 | T19: =IFERROR(V19/R19,"0") -> 0 | U19: =IFERROR(T19/T11,0) -> 0 | V19: =CF17 -> 0 | W19: =IFERROR(V19/V26,0) -> 0 | X19: =CG17 -> 0 | Y19: =IFERROR(X19/X26,0) -> 0 | Z19: =IFERROR(AB19/X19,"0") -> 0 | AA19: =IFERROR(Z19/Z11,0) -> 0 | AB19: =CH17 -> 0 | AC19: =IFERROR(AB19/AB26,0) -> 0 | AD19: =CI17 -> 0 | AE19: =IFERROR(AD19/AD26,0) -> 0 | AF19: =IFERROR(AH19/AD19,"0") -> 0 | AG19: =IFERROR(AF19/AF11,0) -> 0 | AH19: =CJ17 -> 0 | AI19: =IFERROR(AH19/AH26,0) -> 0 | AJ19: =CK17 -> 0 | AK19: =IFERROR(AJ19/AJ26,0) -> 0 | AL19: =IFERROR(AN19/AJ19,"0") -> 0 | AM19: =IFERROR(AL19/AL11,0) -> 0 | AN19: =CL17 -> 0 | AO19: =IFERROR(AN19/AN26,0) -> 0 | AP19: =CM17 -> 0 | AQ19: =IFERROR(AP19/AP26,0) -> 0 | AR19: =IFERROR(AT19/AP19,"0") -> 0 | AS19: =IFERROR(AR19/AR11,0) -> 0 | AT19: =CN17 -> 0 | AU19: =IFERROR(AT19/AT26,0) -> 0 | AV19: =IFERROR(L19-F19,0) -> -309 | AW19: =IFERROR(AV19/F19,0) -> -1 | AX19: =IFERROR(N19-H19,0) -> -374.93645 | AY19: =IFERROR(AX19/H19,0) -> -1 | AZ19: =IFERROR(P19-J19,0) -> -115855.36 | BA19: =IFERROR(AZ19/J19,0) -> -1 | BB19: =IFERROR(L19-R19,0) -> 0 | BC19: =IFERROR(BB19/R19,0) -> 0 | BD19: =IFERROR(N19-T19,0) -> 0 | BE19: =IFERROR(BD19/T19,0) -> 0 | BF19: =IFERROR(P19-V19,0) -> 0 | BG19: =IFERROR(BF19/V19,0) -> 0 | BH19: =IFERROR(L19-X19,0) -> 0 | BI19: =IFERROR(BH19/X19,0) -> 0 | BJ19: =IFERROR(N19-Z19,0) -> 0 | BK19: =IFERROR(BJ19/Z19,0) -> 0 | BL19: =IFERROR(P19-AB19,0) -> 0 | BM19: =IFERROR(BL19/AB19,0) -> 0 | BN19: =IFERROR(L19-AP19,0) -> 0 | BO19: =IFERROR(BN19/AP19,0) -> 0 | BP19: =IFERROR(N19-AR19,0) -> 0 | BQ19: =IFERROR(BP19/AR19,0) -> 0 | BR19: =IFERROR(P19-AT19,0) -> 0 | BS19: =IFERROR(BR19/AT19,0) -> 0 | BZ19: G-OTA | CA19: =ROUND(기존구분!$E$44*(SUM('파나크 영덕:소노문해운대'!L21)/SUM('파나크 영덕:소노문해운대'!$L$18,'파나크 영덕:소노문해운대'!$L$24,'파나크 영덕:소노문해운대'!$L$25)),0) -> 584 | CB19: =CA19*기존구분!$E$52+20000 -> 210447.06
E20: OTA | F20: =CA18 -> 682 | G20: =IFERROR(F20/F26,0) -> 0.17545665 | H20: =IFERROR(J20/F20,"0") -> 362.76487 | I20: =IFERROR(H20/H11,0) -> 1.2856468 | J20: =CB18 -> 247405.64 | K20: =IFERROR(J20/J26,0) -> 0.21970664 | L20: =CC18 -> 0 | M20: =IFERROR(L20/L26,0) -> 0 | N20: =IFERROR(P20/L20,"0") -> 0 | O20: =IFERROR(N20/N11,0) -> 0 | P20: =CD18 -> 0 | Q20: =IFERROR(P20/P26,0) -> 0 | R20: =CE18 -> 0 | S20: =IFERROR(R20/R26,0) -> 0 | T20: =IFERROR(V20/R20,"0") -> 0 | U20: =IFERROR(T20/T11,0) -> 0 | V20: =CF18 -> 0 | W20: =IFERROR(V20/V26,0) -> 0 | X20: =CG18 -> 0 | Y20: =IFERROR(X20/X26,0) -> 0 | Z20: =IFERROR(AB20/X20,"0") -> 0 | AA20: =IFERROR(Z20/Z11,0) -> 0 | AB20: =CH18 -> 0 | AC20: =IFERROR(AB20/AB26,0) -> 0 | AD20: =CI18 -> 0 | AE20: =IFERROR(AD20/AD26,0) -> 0 | AF20: =IFERROR(AH20/AD20,"0") -> 0 | AG20: =IFERROR(AF20/AF11,0) -> 0 | AH20: =CJ18 -> 0 | AI20: =IFERROR(AH20/AH26,0) -> 0 | AJ20: =CK18 -> 0 | AK20: =IFERROR(AJ20/AJ26,0) -> 0 | AL20: =IFERROR(AN20/AJ20,"0") -> 0 | AM20: =IFERROR(AL20/AL11,0) -> 0 | AN20: =CL18 -> 0 | AO20: =IFERROR(AN20/AN26,0) -> 0 | AP20: =CM18 -> 0 | AQ20: =IFERROR(AP20/AP26,0) -> 0 | AR20: =IFERROR(AT20/AP20,"0") -> 0 | AS20: =IFERROR(AR20/AR11,0) -> 0 | AT20: =CN18 -> 0 | AU20: =IFERROR(AT20/AT26,0) -> 0 | AV20: =IFERROR(L20-F20,0) -> -682 | AW20: =IFERROR(AV20/F20,0) -> -1 | AX20: =IFERROR(N20-H20,0) -> -362.76487 | AY20: =IFERROR(AX20/H20,0) -> -1 | AZ20: =IFERROR(P20-J20,0) -> -247405.64 | BA20: =IFERROR(AZ20/J20,0) -> -1 | BB20: =IFERROR(L20-R20,0) -> 0 | BC20: =IFERROR(BB20/R20,0) -> 0 | BD20: =IFERROR(N20-T20,0) -> 0 | BE20: =IFERROR(BD20/T20,0) -> 0 | BF20: =IFERROR(P20-V20,0) -> 0 | BG20: =IFERROR(BF20/V20,0) -> 0 | BH20: =IFERROR(L20-X20,0) -> 0 | BI20: =IFERROR(BH20/X20,0) -> 0 | BJ20: =IFERROR(N20-Z20,0) -> 0 | BK20: =IFERROR(BJ20/Z20,0) -> 0 | BL20: =IFERROR(P20-AB20,0) -> 0 | BM20: =IFERROR(BL20/AB20,0) -> 0 | BN20: =IFERROR(L20-AP20,0) -> 0 | BO20: =IFERROR(BN20/AP20,0) -> 0 | BP20: =IFERROR(N20-AR20,0) -> 0 | BQ20: =IFERROR(BP20/AR20,0) -> 0 | BR20: =IFERROR(P20-AT20,0) -> 0 | BS20: =IFERROR(BR20/AT20,0) -> 0 | BZ20: 제휴사 | CA20: =ROUND(기존구분!$E$44*(SUM('파나크 영덕:소노문해운대'!L22)/SUM('파나크 영덕:소노문해운대'!$L$18,'파나크 영덕:소노문해운대'!$L$24,'파나크 영덕:소노문해운대'!$L$25)),0) -> 0 | CB20: =CA20*기존구분!$E$52 -> 0
E21: G-OTA | F21: =CA19 -> 584 | G21: =IFERROR(F21/F26,0) -> 0.1502444 | H21: =IFERROR(J21/F21,"0") -> 360.35455 | I21: =IFERROR(H21/H11,0) -> 1.2771046 | J21: =CB19 -> 210447.06 | K21: =IFERROR(J21/J26,0) -> 0.18688586 | L21: =CC19 -> 0 | M21: =IFERROR(L21/L26,0) -> 0 | N21: =IFERROR(P21/L21,"0") -> 0 | O21: =IFERROR(N21/N11,0) -> 0 | P21: =CD19 -> 0 | Q21: =IFERROR(P21/P26,0) -> 0 | R21: =CE19 -> 0 | S21: =IFERROR(R21/R26,0) -> 0 | T21: =IFERROR(V21/R21,"0") -> 0 | U21: =IFERROR(T21/T11,0) -> 0 | V21: =CF19 -> 0 | W21: =IFERROR(V21/V26,0) -> 0 | X21: =CG19 -> 0 | Y21: =IFERROR(X21/X26,0) -> 0 | Z21: =IFERROR(AB21/X21,"0") -> 0 | AA21: =IFERROR(Z21/Z11,0) -> 0 | AB21: =CH19 -> 0 | AC21: =IFERROR(AB21/AB26,0) -> 0 | AD21: =CI19 -> 0 | AE21: =IFERROR(AD21/AD26,0) -> 0 | AF21: =IFERROR(AH21/AD21,"0") -> 0 | AG21: =IFERROR(AF21/AF11,0) -> 0 | AH21: =CJ19 -> 0 | AI21: =IFERROR(AH21/AH26,0) -> 0 | AJ21: =CK19 -> 0 | AK21: =IFERROR(AJ21/AJ26,0) -> 0 | AL21: =IFERROR(AN21/AJ21,"0") -> 0 | AM21: =IFERROR(AL21/AL11,0) -> 0 | AN21: =CL19 -> 0 | AO21: =IFERROR(AN21/AN26,0) -> 0 | AP21: =CM19 -> 0 | AQ21: =IFERROR(AP21/AP26,0) -> 0 | AR21: =IFERROR(AT21/AP21,"0") -> 0 | AS21: =IFERROR(AR21/AR11,0) -> 0 | AT21: =CN19 -> 0 | AU21: =IFERROR(AT21/AT26,0) -> 0 | AV21: =IFERROR(L21-F21,0) -> -584 | AW21: =IFERROR(AV21/F21,0) -> -1 | AX21: =IFERROR(N21-H21,0) -> -360.35455 | AY21: =IFERROR(AX21/H21,0) -> -1 | AZ21: =IFERROR(P21-J21,0) -> -210447.06 | BA21: =IFERROR(AZ21/J21,0) -> -1 | BB21: =IFERROR(L21-R21,0) -> 0 | BC21: =IFERROR(BB21/R21,0) -> 0 | BD21: =IFERROR(N21-T21,0) -> 0 | BE21: =IFERROR(BD21/T21,0) -> 0 | BF21: =IFERROR(P21-V21,0) -> 0 | BG21: =IFERROR(BF21/V21,0) -> 0 | BH21: =IFERROR(L21-X21,0) -> 0 | BI21: =IFERROR(BH21/X21,0) -> 0 | BJ21: =IFERROR(N21-Z21,0) -> 0 | BK21: =IFERROR(BJ21/Z21,0) -> 0 | BL21: =IFERROR(P21-AB21,0) -> 0 | BM21: =IFERROR(BL21/AB21,0) -> 0 | BN21: =IFERROR(L21-AP21,0) -> 0 | BO21: =IFERROR(BN21/AP21,0) -> 0 | BP21: =IFERROR(N21-AR21,0) -> 0 | BQ21: =IFERROR(BP21/AR21,0) -> 0 | BR21: =IFERROR(P21-AT21,0) -> 0 | BS21: =IFERROR(BR21/AT21,0) -> 0 | BZ21: 기 타 | CA21: =ROUND(기존구분!$E$44*(SUM('파나크 영덕:소노문해운대'!L23)/SUM('파나크 영덕:소노문해운대'!$L$18,'파나크 영덕:소노문해운대'!$L$24,'파나크 영덕:소노문해운대'!$L$25)),0) -> 81 | CB21: =CA21*기존구분!$E$52+1000 -> 27414.746
E22: Affiliate | F22: =CA20 -> 0 | G22: =IFERROR(F22/F26,0) -> 0 | H22: =IFERROR(J22/F22,"0") -> 0 | I22: =IFERROR(H22/H11,0) -> 0 | J22: =CB20 -> 0 | K22: =IFERROR(J22/J26,0) -> 0 | L22: =CC20 -> 0 | M22: =IFERROR(L22/L26,0) -> 0 | N22: =IFERROR(P22/L22,"0") -> 0 | O22: =IFERROR(N22/N11,0) -> 0 | P22: =CD20 -> 0 | Q22: =IFERROR(P22/P26,0) -> 0 | R22: =CE20 -> 0 | S22: =IFERROR(R22/R26,0) -> 0 | T22: =IFERROR(V22/R22,"0") -> 0 | U22: =IFERROR(T22/T11,0) -> 0 | V22: =CF20 -> 0 | W22: =IFERROR(V22/V26,0) -> 0 | X22: =CG20 -> 0 | Y22: =IFERROR(X22/X26,0) -> 0 | Z22: =IFERROR(AB22/X22,"0") -> 0 | AA22: =IFERROR(Z22/Z11,0) -> 0 | AB22: =CH20 -> 0 | AC22: =IFERROR(AB22/AB26,0) -> 0 | AD22: =CI20 -> 0 | AE22: =IFERROR(AD22/AD26,0) -> 0 | AF22: =IFERROR(AH22/AD22,"0") -> 0 | AG22: =IFERROR(AF22/AF11,0) -> 0 | AH22: =CJ20 -> 0 | AI22: =IFERROR(AH22/AH26,0) -> 0 | AJ22: =CK20 -> 0 | AK22: =IFERROR(AJ22/AJ26,0) -> 0 | AL22: =IFERROR(AN22/AJ22,"0") -> 0 | AM22: =IFERROR(AL22/AL11,0) -> 0 | AN22: =CL20 -> 0 | AO22: =IFERROR(AN22/AN26,0) -> 0 | AP22: =CM20 -> 0 | AQ22: =IFERROR(AP22/AP26,0) -> 0 | AR22: =IFERROR(AT22/AP22,"0") -> 0 | AS22: =IFERROR(AR22/AR11,0) -> 0 | AT22: =CN20 -> 0 | AU22: =IFERROR(AT22/AT26,0) -> 0 | AV22: =IFERROR(L22-F22,0) -> 0 | AW22: =IFERROR(AV22/F22,0) -> 0 | AX22: =IFERROR(N22-H22,0) -> 0 | AY22: =IFERROR(AX22/H22,0) -> 0 | AZ22: =IFERROR(P22-J22,0) -> 0 | BA22: =IFERROR(AZ22/J22,0) -> 0 | BB22: =IFERROR(L22-R22,0) -> 0 | BC22: =IFERROR(BB22/R22,0) -> 0 | BD22: =IFERROR(N22-T22,0) -> 0 | BE22: =IFERROR(BD22/T22,0) -> 0 | BF22: =IFERROR(P22-V22,0) -> 0 | BG22: =IFERROR(BF22/V22,0) -> 0 | BH22: =IFERROR(L22-X22,0) -> 0 | BI22: =IFERROR(BH22/X22,0) -> 0 | BJ22: =IFERROR(N22-Z22,0) -> 0 | BK22: =IFERROR(BJ22/Z22,0) -> 0 | BL22: =IFERROR(P22-AB22,0) -> 0 | BM22: =IFERROR(BL22/AB22,0) -> 0 | BN22: =IFERROR(L22-AP22,0) -> 0 | BO22: =IFERROR(BN22/AP22,0) -> 0 | BP22: =IFERROR(N22-AR22,0) -> 0 | BQ22: =IFERROR(BP22/AR22,0) -> 0 | BR22: =IFERROR(P22-AT22,0) -> 0 | BS22: =IFERROR(BR22/AT22,0) -> 0 | BY22: COMP | CA22: =ROUND(기존구분!$E$44*(SUM('파나크 영덕:소노문해운대'!L25)/SUM('파나크 영덕:소노문해운대'!$L$18,'파나크 영덕:소노문해운대'!$L$24,'파나크 영덕:소노문해운대'!$L$25)),0) -> 34
E23: Other | F23: =CA21 -> 81 | G23: =IFERROR(F23/F26,0) -> 0.020838693 | H23: =IFERROR(J23/F23,"0") -> 338.45365 | I23: =IFERROR(H23/H11,0) -> 1.1994873 | J23: =CB21 -> 27414.746 | K23: =IFERROR(J23/J26,0) -> 0.02434545 | L23: =CC21 -> 0 | M23: =IFERROR(L23/L26,0) -> 0 | N23: =IFERROR(P23/L23,"0") -> 0 | O23: =IFERROR(N23/N11,0) -> 0 | P23: =CD21 -> 0 | Q23: =IFERROR(P23/P26,0) -> 0 | R23: =CE21 -> 0 | S23: =IFERROR(R23/R26,0) -> 0 | T23: =IFERROR(V23/R23,"0") -> 0 | U23: =IFERROR(T23/T11,0) -> 0 | V23: =CF21 -> 0 | W23: =IFERROR(V23/V26,0) -> 0 | X23: =CG21 -> 0 | Y23: =IFERROR(X23/X26,0) -> 0 | Z23: =IFERROR(AB23/X23,"0") -> 0 | AA23: =IFERROR(Z23/Z11,0) -> 0 | AB23: =CH21 -> 0 | AC23: =IFERROR(AB23/AB26,0) -> 0 | AD23: =CI21 -> 0 | AE23: =IFERROR(AD23/AD26,0) -> 0 | AF23: =IFERROR(AH23/AD23,"0") -> 0 | AG23: =IFERROR(AF23/AF11,0) -> 0 | AH23: =CJ21 -> 0 | AI23: =IFERROR(AH23/AH26,0) -> 0 | AJ23: =CK21 -> 0 | AK23: =IFERROR(AJ23/AJ26,0) -> 0 | AL23: =IFERROR(AN23/AJ23,"0") -> 0 | AM23: =IFERROR(AL23/AL11,0) -> 0 | AN23: =CL21 -> 0 | AO23: =IFERROR(AN23/AN26,0) -> 0 | AP23: =CM21 -> 0 | AQ23: =IFERROR(AP23/AP26,0) -> 0 | AR23: =IFERROR(AT23/AP23,"0") -> 0 | AS23: =IFERROR(AR23/AR11,0) -> 0 | AT23: =CN21 -> 0 | AU23: =IFERROR(AT23/AT26,0) -> 0 | AV23: =IFERROR(L23-F23,0) -> -81 | AW23: =IFERROR(AV23/F23,0) -> -1 | AX23: =IFERROR(N23-H23,0) -> -338.45365 | AY23: =IFERROR(AX23/H23,0) -> -1 | AZ23: =IFERROR(P23-J23,0) -> -27414.746 | BA23: =IFERROR(AZ23/J23,0) -> -1 | BB23: =IFERROR(L23-R23,0) -> 0 | BC23: =IFERROR(BB23/R23,0) -> 0 | BD23: =IFERROR(N23-T23,0) -> 0 | BE23: =IFERROR(BD23/T23,0) -> 0 | BF23: =IFERROR(P23-V23,0) -> 0 | BG23: =IFERROR(BF23/V23,0) -> 0 | BH23: =IFERROR(L23-X23,0) -> 0 | BI23: =IFERROR(BH23/X23,0) -> 0 | BJ23: =IFERROR(N23-Z23,0) -> 0 | BK23: =IFERROR(BJ23/Z23,0) -> 0 | BL23: =IFERROR(P23-AB23,0) -> 0 | BM23: =IFERROR(BL23/AB23,0) -> 0 | BN23: =IFERROR(L23-AP23,0) -> 0 | BO23: =IFERROR(BN23/AP23,0) -> 0 | BP23: =IFERROR(N23-AR23,0) -> 0 | BQ23: =IFERROR(BP23/AR23,0) -> 0 | BR23: =IFERROR(P23-AT23,0) -> 0 | BS23: =IFERROR(BR23/AT23,0) -> 0 | BX23: 2월 | BY23: 회 원 | BZ23: 기 명 | CA23: =기존구분!$F$46 -> 232
E24: Total | F24: =SUM(F19:F23) -> 1656 | G24: =IFERROR(F24/F26,0) -> 0.4260355 | H24: =IFERROR(J24/F24,"0") -> 362.99686 | I24: =IFERROR(H24/H11,0) -> 1.286469 | J24: =SUM(J19:J23) -> 601122.81 | K24: =IFERROR(J24/J26,0) -> 0.53382239 | L24: =SUM(L19:L23) -> 0 | M24: =IFERROR(L24/L26,0) -> 0 | N24: =IFERROR(P24/L24,"0") -> 0 | O24: =IFERROR(N24/N11,0) -> 0 | P24: =SUM(P19:P23) -> 0 | Q24: =IFERROR(P24/P26,0) -> 0 | R24: =SUM(R19:R23) -> 0 | S24: =IFERROR(R24/R26,0) -> 0 | T24: =IFERROR(V24/R24,"0") -> 0 | U24: =IFERROR(T24/T11,0) -> 0 | V24: =SUM(V19:V23) -> 0 | W24: =IFERROR(V24/V26,0) -> 0 | X24: =SUM(X19:X23) -> 0 | Y24: =IFERROR(X24/X26,0) -> 0 | Z24: =IFERROR(AB24/X24,"0") -> 0 | AA24: =IFERROR(Z24/Z11,0) -> 0 | AB24: =SUM(AB19:AB23) -> 0 | AC24: =IFERROR(AB24/AB26,0) -> 0 | AD24: =SUM(AD19:AD23) -> 0 | AE24: =IFERROR(AD24/AD26,0) -> 0 | AF24: =IFERROR(AH24/AD24,"0") -> 0 | AG24: =IFERROR(AF24/AF11,0) -> 0 | AH24: =SUM(AH19:AH23) -> 0 | AI24: =IFERROR(AH24/AH26,0) -> 0 | AJ24: =SUM(AJ19:AJ23) -> 0 | AK24: =IFERROR(AJ24/AJ26,0) -> 0 | AL24: =IFERROR(AN24/AJ24,"0") -> 0 | AM24: =IFERROR(AL24/AL11,0) -> 0 | AN24: =SUM(AN19:AN23) -> 0 | AO24: =IFERROR(AN24/AN26,0) -> 0 | AP24: =SUM(AP19:AP23) -> 0 | AQ24: =IFERROR(AP24/AP26,0) -> 0 | AR24: =IFERROR(AT24/AP24,"0") -> 0 | AS24: =IFERROR(AR24/AR11,0) -> 0 | AT24: =SUM(AT19:AT23) -> 0 | AU24: =IFERROR(AT24/AT26,0) -> 0 | AV24: =IFERROR(L24-F24,0) -> -1656 | AW24: =IFERROR(AV24/F24,0) -> -1 | AX24: =IFERROR(N24-H24,0) -> -362.99686 | AY24: =IFERROR(AX24/H24,0) -> -1 | AZ24: =IFERROR(P24-J24,0) -> -601122.81 | BA24: =IFERROR(AZ24/J24,0) -> -1 | BB24: =IFERROR(L24-R24,0) -> 0 | BC24: =IFERROR(BB24/R24,0) -> 0 | BD24: =IFERROR(N24-T24,0) -> 0 | BE24: =IFERROR(BD24/T24,0) -> 0 | BF24: =IFERROR(P24-V24,0) -> 0 | BG24: =IFERROR(BF24/V24,0) -> 0 | BH24: =IFERROR(L24-X24,0) -> 0 | BI24: =IFERROR(BH24/X24,0) -> 0 | BJ24: =IFERROR(N24-Z24,0) -> 0 | BK24: =IFERROR(BJ24/Z24,0) -> 0 | BL24: =IFERROR(P24-AB24,0) -> 0 | BM24: =IFERROR(BL24/AB24,0) -> 0 | BN24: =IFERROR(L24-AP24,0) -> 0 | BO24: =IFERROR(BN24/AP24,0) -> 0 | BP24: =IFERROR(N24-AR24,0) -> 0 | BQ24: =IFERROR(BP24/AR24,0) -> 0 | BR24: =IFERROR(P24-AT24,0) -> 0 | BS24: =IFERROR(BR24/AT24,0) -> 0 | BZ24: 무기명 | CA24: =ROUND(기존구분!$F$45*(SUM('파나크 영덕'!L35,소노문해운대!L34:L35)/SUM('파나크 영덕'!L35:L37,소노문해운대!L34:L37)),0) -> 477 | CB24: =CA24*기존구분!$F$53-1000 -> 134048.42
D25: COMP | F25: =CA22 -> 34 | G25: =IFERROR(F25/F26,0) -> 0.0087471057 | H25: =IFERROR(J25/F25,"0") -> 0 | I25: =IFERROR(H25/H11,0) -> 0 | J25: =CB22 -> 0 | K25: =IFERROR(J25/J26,0) -> 0 | L25: =CC22 -> 0 | M25: =IFERROR(L25/L26,0) -> 0 | N25: =IFERROR(P25/L25,"0") -> 0 | O25: =IFERROR(N25/N11,0) -> 0 | P25: =CD22 -> 0 | Q25: =IFERROR(P25/P26,0) -> 0 | R25: =CE22 -> 0 | S25: =IFERROR(R25/R26,0) -> 0 | T25: =IFERROR(V25/R25,"0") -> 0 | U25: =IFERROR(T25/T11,0) -> 0 | V25: =CF22 -> 0 | W25: =IFERROR(V25/V26,0) -> 0 | X25: =CG22 -> 0 | Y25: =IFERROR(X25/X26,0) -> 0 | Z25: =IFERROR(AB25/X25,"0") -> 0 | AA25: =IFERROR(Z25/Z11,0) -> 0 | AB25: =CH22 -> 0 | AC25: =IFERROR(AB25/AB26,0) -> 0 | AD25: =CI22 -> 0 | AE25: =IFERROR(AD25/AD26,0) -> 0 | AF25: =IFERROR(AH25/AD25,"0") -> 0 | AG25: =IFERROR(AF25/AF11,0) -> 0 | AH25: =CJ22 -> 0 | AI25: =IFERROR(AH25/AH26,0) -> 0 | AJ25: =CK22 -> 0 | AK25: =IFERROR(AJ25/AJ26,0) -> 0 | AL25: =IFERROR(AN25/AJ25,"0") -> 0 | AM25: =IFERROR(AL25/AL11,0) -> 0 | AN25: =CL22 -> 0 | AO25: =IFERROR(AN25/AN26,0) -> 0 | AP25: =CM22 -> 0 | AQ25: =IFERROR(AP25/AP26,0) -> 0 | AR25: =IFERROR(AT25/AP25,"0") -> 0 | AS25: =IFERROR(AR25/AR11,0) -> 0 | AT25: =CN22 -> 0 | AU25: =IFERROR(AT25/AT26,0) -> 0 | AV25: =IFERROR(L25-F25,0) -> -34 | AW25: =IFERROR(AV25/F25,0) -> -1 | AX25: =IFERROR(N25-H25,0) -> 0 | AY25: =IFERROR(AX25/H25,0) -> 0 | AZ25: =IFERROR(P25-J25,0) -> 0 | BA25: =IFERROR(AZ25/J25,0) -> 0 | BB25: =IFERROR(L25-R25,0) -> 0 | BC25: =IFERROR(BB25/R25,0) -> 0 | BD25: =IFERROR(N25-T25,0) -> 0 | BE25: =IFERROR(BD25/T25,0) -> 0 | BF25: =IFERROR(P25-V25,0) -> 0 | BG25: =IFERROR(BF25/V25,0) -> 0 | BH25: =IFERROR(L25-X25,0) -> 0 | BI25: =IFERROR(BH25/X25,0) -> 0 | BJ25: =IFERROR(N25-Z25,0) -> 0 | BK25: =IFERROR(BJ25/Z25,0) -> 0 | BL25: =IFERROR(P25-AB25,0) -> 0 | BM25: =IFERROR(BL25/AB25,0) -> 0 | BN25: =IFERROR(L25-AP25,0) -> 0 | BO25: =IFERROR(BN25/AP25,0) -> 0 | BP25: =IFERROR(N25-AR25,0) -> 0 | BQ25: =IFERROR(BP25/AR25,0) -> 0 | BR25: =IFERROR(P25-AT25,0) -> 0 | BS25: =IFERROR(BR25/AT25,0) -> 0 | BZ25: 직 원 | CA25: =ROUND(기존구분!$F$45*(SUM('파나크 영덕:소노문해운대'!L36)/SUM('파나크 영덕'!L35:L37,소노문해운대!L34:L37)),0) -> 45 | CB25: =CA25*기존구분!$F$53+1000 -> 13740.417
D26: Grand Total | F26: =SUM(F14,F18,F24,F25) -> 3887 | G26: =IFERROR(F26/F26,0) -> 1 | H26: =IFERROR(J26/F26,"0") -> 289.70226 | I26: =IFERROR(H26/H11,0) -> 1.0267113 | J26: =SUM(J14,J18,J24,J25) -> 1126072.7 | K26: =IFERROR(J26/J26,0) -> 1 | L26: =SUM(L14,L18,L24,L25) -> 0 | M26: =IFERROR(L26/L26,0) -> 0 | N26: =IFERROR(P26/L26,"0") -> 0 | O26: =IFERROR(N26/N11,0) -> 0 | P26: =SUM(P14,P18,P24,P25) -> 0 | Q26: =IFERROR(P26/P26,0) -> 0 | R26: =SUM(R14,R18,R24,R25) -> 0 | S26: =IFERROR(R26/R26,0) -> 0 | T26: =IFERROR(V26/R26,"0") -> 0 | U26: =IFERROR(T26/T11,0) -> 0 | V26: =SUM(V14,V18,V24,V25) -> 0 | W26: =IFERROR(V26/V26,0) -> 0 | X26: =SUM(X14,X18,X24,X25) -> 0 | Y26: =IFERROR(X26/X26,0) -> 0 | Z26: =IFERROR(AB26/X26,"0") -> 0 | AA26: =IFERROR(Z26/Z11,0) -> 0 | AB26: =SUM(AB14,AB18,AB24,AB25) -> 0 | AC26: =IFERROR(AB26/AB26,0) -> 0 | AD26: =SUM(AD14,AD18,AD24,AD25) -> 0 | AE26: =IFERROR(AD26/AD26,0) -> 0 | AF26: =IFERROR(AH26/AD26,"0") -> 0 | AG26: =IFERROR(AF26/AF11,0) -> 0 | AH26: =SUM(AH14,AH18,AH24,AH25) -> 0 | AI26: =IFERROR(AH26/AH26,0) -> 0 | AJ26: =SUM(AJ14,AJ18,AJ24,AJ25) -> 0 | AK26: =IFERROR(AJ26/AJ26,0) -> 0 | AL26: =IFERROR(AN26/AJ26,"0") -> 0 | AM26: =IFERROR(AL26/AL11,0) -> 0 | AN26: =SUM(AN14,AN18,AN24,AN25) -> 0 | AO26: =IFERROR(AN26/AN26,0) -> 0 | AP26: =SUM(AP14,AP18,AP24,AP25) -> 0 | AQ26: =IFERROR(AP26/AP26,0) -> 0 | AR26: =IFERROR(AT26/AP26,"0") -> 0 | AS26: =IFERROR(AR26/AR11,0) -> 0 | AT26: =SUM(AT14,AT18,AT24,AT25) -> 0 | AU26: =IFERROR(AT26/AT26,0) -> 0 | AV26: =IFERROR(L26-F26,0) -> -3887 | AW26: =IFERROR(AV26/F26,0) -> -1 | AX26: =IFERROR(N26-H26,0) -> -289.70226 | AY26: =IFERROR(AX26/H26,0) -> -1 | AZ26: =IFERROR(P26-J26,0) -> -1126072.7 | BA26: =IFERROR(AZ26/J26,0) -> -1 | BB26: =IFERROR(L26-R26,0) -> 0 | BC26: =IFERROR(BB26/R26,0) -> 0 | BD26: =IFERROR(N26-T26,0) -> 0 | BE26: =IFERROR(BD26/T26,0) -> 0 | BF26: =IFERROR(P26-V26,0) -> 0 | BG26: =IFERROR(BF26/V26,0) -> 0 | BH26: =IFERROR(L26-X26,0) -> 0 | BI26: =IFERROR(BH26/X26,0) -> 0 | BJ26: =IFERROR(N26-Z26,0) -> 0 | BK26: =IFERROR(BJ26/Z26,0) -> 0 | BL26: =IFERROR(P26-AB26,0) -> 0 | BM26: =IFERROR(BL26/AB26,0) -> 0 | BN26: =IFERROR(L26-AP26,0) -> 0 | BO26: =IFERROR(BN26/AP26,0) -> 0 | BP26: =IFERROR(N26-AR26,0) -> 0 | BQ26: =IFERROR(BP26/AR26,0) -> 0 | BR26: =IFERROR(P26-AT26,0) -> 0 | BS26: =IFERROR(BR26/AT26,0) -> 0 | BZ26: 기 타 | CA26: =ROUND(기존구분!$F$45*(SUM('파나크 영덕:소노문해운대'!L37)/SUM('파나크 영덕'!L35:L37,소노문해운대!L34:L37)),0) -> 28 | CB26: =CA26*기존구분!$F$53 -> 7927.3706
D27: OCC | F27: =F26/F6 -> 0.52683654 | L27: =L26/L6 -> #DIV/0! | R27: =R26/R6 -> #DIV/0! | X27: =X26/X6 -> #DIV/0! | AD27: =AD26/AD6 -> #DIV/0! | AJ27: =AJ26/AJ6 -> #DIV/0! | AP27: =AP26/AP6 -> #DIV/0! | AV27: =IFERROR(L27-F27,0) -> 0 | BB27: =IFERROR(L27-R27,0) -> 0 | BH27: =IFERROR(L27-X27,0) -> 0 | BN27: =IFERROR(L27-AP27,0) -> 0 | BY27: 단 체 | BZ27: 일 반
BZ28: 학 생
BZ29: 인바운드
F30: =CB169 -> 2996 | L30: =CB170 -> 0 | R30: =CB171 -> 0 | X30: =CB172 -> 0 | AD30: =CB173 -> 0 | AJ30: =CB174 -> 0 | AP30: =CB175 -> 0 | BM30: [ 단위 : RN_실, ADR_천원, Revenue_천원 / VAT제외 ] | BS30: [ 단위 : RN_실, ADR_천원, Revenue_천원 / VAT제외 ] | BY30: 일 반 | BZ30: 홈페이지 | CA30: =ROUND(기존구분!$F$44*(SUM('파나크 영덕:소노문해운대'!L43)/SUM('파나크 영덕:소노문해운대'!$L$48,'파나크 영덕:소노문해운대'!$L$49)),0) -> 144 | CB30: =CA30*기존구분!$F$52+2000 -> 48959.548
C31: Segment | F31: =$F$7 -> 2026 Budget | L31: =$L$7 -> 2026 Actual | R31: =$R$7 -> 2025 Actual | X31: =$X$7 -> 2023 Actual | AD31: =$AD$7 -> 2022 Actual | AJ31: =$AJ$7 -> 2021 Actual | AP31: =$AP$7 -> 2020 Actual | AV31: =$AV$7 -> 2026 Actual vs. 2026 Budget | BB31: =$BB$7 -> 2026 Actual vs. 2025 Actual | BH31: =$BH$7 -> 2026 Actual vs. 2024 Actual | BN31: =$BN$7 -> 2025 Actual vs. 2020 Actual | BZ31: OTA | CA31: =ROUND(기존구분!$F$44*(SUM('파나크 영덕:소노문해운대'!L44)/SUM('파나크 영덕:소노문해운대'!$L$48,'파나크 영덕:소노문해운대'!$L$49)),0) -> 541 | CB31: =CA31*기존구분!$F$52+1500 -> 177924.41
F32: RN | H32: ADR | J32: Revenue | L32: RN | N32: ADR | P32: Revenue | R32: RN | T32: ADR | V32: Revenue | X32: RN | Z32: ADR | AB32: Revenue | AD32: RN | AF32: ADR | AH32: 매 출 | AJ32: RN | AL32: ADR | AN32: 매 출 | AP32: RN | AR32: ADR | AT32: 매 출 | AV32: RN | AX32: ADR | AZ32: Revenue | BB32: RN | BD32: ADR | BF32: Revenue | BH32: RN | BJ32: ADR | BL32: Revenue | BN32: RN | BP32: ADR | BR32: Revenue | BZ32: G-OTA | CA32: =ROUND(기존구분!$F$44*(SUM('파나크 영덕:소노문해운대'!L45)/SUM('파나크 영덕:소노문해운대'!$L$48,'파나크 영덕:소노문해운대'!$L$49)),0) -> 458 | CB32: =CA32*기존구분!$F$52 -> 149357.45
G33: % | I33: 지 수 | K33: % | M33: % | O33: 지 수 | Q33: % | S33: % | U33: 지 수 | W33: % | Y33: % | AA33: 지 수 | AC33: % | AE33: % | AG33: 지 수 | AI33: % | AK33: % | AM33: 지 수 | AO33: % | AQ33: % | AS33: 지 수 | AU33: % | AW33: 증감율 | AY33: 증감율 | BA33: 증감율 | BC33: 증감율 | BE33: 증감율 | BG33: 증감율 | BI33: 증감율 | BK33: 증감율 | BM33: 증감율 | BO33: 증감율 | BQ33: 증감율 | BS33: 증감율 | BZ33: 제휴사 | CA33: =ROUND(기존구분!$F$44*(SUM('파나크 영덕:소노문해운대'!L46)/SUM('파나크 영덕:소노문해운대'!$L$48,'파나크 영덕:소노문해운대'!$L$49)),0) -> 2 | CB33: =CA33*기존구분!$F$52+87 -> 739.21595
C34: 2월 | D34: Membership | E34: 기 명 | F34: =CA23 -> 232 | G34: =IFERROR(F34/F50,0) -> 0.11788618 | H34: =IFERROR(J34/F34,"0") -> 0 | I34: =IFERROR(H34/H35,0) -> 0 | J34: =CB23 -> 0 | K34: =IFERROR(J34/J50,0) -> 0 | L34: =CC23 -> 0 | M34: =IFERROR(L34/L50,0) -> 0 | N34: =IFERROR(P34/L34,"0") -> 0 | O34: =IFERROR(N34/N35,0) -> 0 | P34: =CD23 -> 0 | Q34: =IFERROR(P34/P50,0) -> 0 | R34: =CE23 -> 0 | S34: =IFERROR(R34/R50,0) -> 0 | T34: =IFERROR(V34/R34,"0") -> 0 | U34: =IFERROR(T34/T35,0) -> 0 | V34: =CF23 -> 0 | W34: =IFERROR(V34/V50,0) -> 0 | X34: =CG23 -> 0 | Y34: =IFERROR(X34/X50,0) -> 0 | Z34: =IFERROR(AB34/X34,"0") -> 0 | AA34: =IFERROR(Z34/Z35,0) -> 0 | AB34: =CH23 -> 0 | AC34: =IFERROR(AB34/AB50,0) -> 0 | AD34: =CI23 -> 0 | AE34: =IFERROR(AD34/AD50,0) -> 0 | AF34: =IFERROR(AH34/AD34,"0") -> 0 | AG34: =IFERROR(AF34/AF35,0) -> 0 | AH34: =CJ23 -> 0 | AI34: =IFERROR(AH34/AH50,0) -> 0 | AJ34: =CK23 -> 0 | AK34: =IFERROR(AJ34/AJ50,0) -> 0 | AL34: =IFERROR(AN34/AJ34,"0") -> 0 | AM34: =IFERROR(AL34/AL35,0) -> 0 | AN34: =CL23 -> 0 | AO34: =IFERROR(AN34/AN50,0) -> 0 | AP34: =CM23 -> 0 | AQ34: =IFERROR(AP34/AP50,0) -> 0 | AR34: =IFERROR(AT34/AP34,"0") -> 0 | AS34: =IFERROR(AR34/AR35,0) -> 0 | AT34: =CN23 -> 0 | AU34: =IFERROR(AT34/AT50,0) -> 0 | AV34: =IFERROR(L34-F34,0) -> -232 | AW34: =IFERROR(AV34/F34,0) -> -1 | AX34: =IFERROR(N34-H34,0) -> 0 | AY34: =IFERROR(AX34/H34,0) -> 0 | AZ34: =IFERROR(P34-J34,0) -> 0 | BA34: =IFERROR(AZ34/J34,0) -> 0 | BB34: =IFERROR(L34-R34,0) -> 0 | BC34: =IFERROR(BB34/R34,0) -> 0 | BD34: =IFERROR(N34-T34,0) -> 0 | BE34: =IFERROR(BD34/T34,0) -> 0 | BF34: =IFERROR(P34-V34,0) -> 0 | BG34: =IFERROR(BF34/V34,0) -> 0 | BH34: =IFERROR(L34-X34,0) -> 0 | BI34: =IFERROR(BH34/X34,0) -> 0 | BJ34: =IFERROR(N34-Z34,0) -> 0 | BK34: =IFERROR(BJ34/Z34,0) -> 0 | BL34: =IFERROR(P34-AB34,0) -> 0 | BM34: =IFERROR(BL34/AB34,0) -> 0 | BN34: =IFERROR(L34-AP34,0) -> 0 | BO34: =IFERROR(BN34/AP34,0) -> 0 | BP34: =IFERROR(N34-AR34,0) -> 0 | BQ34: =IFERROR(BP34/AR34,0) -> 0 | BR34: =IFERROR(P34-AT34,0) -> 0 | BS34: =IFERROR(BR34/AT34,0) -> 0 | BZ34: 기 타 | CA34: =ROUND(기존구분!$F$44*(SUM('파나크 영덕:소노문해운대'!L47)/SUM('파나크 영덕:소노문해운대'!$L$48,'파나크 영덕:소노문해운대'!$L$49)),0) -> 30 | CB34: =CA34*기존구분!$F$52 -> 9783.2392
E35: 무기명 | F35: =CA24 -> 477 | G35: =IFERROR(F35/F50,0) -> 0.24237805 | H35: =IFERROR(J35/F35,"0") -> 281.02394 | I35: =IFERROR(H35/H35,0) -> 1 | J35: =CB24 -> 134048.42 | K35: =IFERROR(J35/J50,0) -> 0.24710294 | L35: =CC24 -> 0 | M35: =IFERROR(L35/L50,0) -> 0 | N35: =IFERROR(P35/L35,"0") -> 0 | O35: =IFERROR(N35/N35,0) -> 0 | P35: =CD24 -> 0 | Q35: =IFERROR(P35/P50,0) -> 0 | R35: =CE24 -> 0 | S35: =IFERROR(R35/R50,0) -> 0 | T35: =IFERROR(V35/R35,"0") -> 0 | U35: =IFERROR(T35/T35,0) -> 0 | V35: =CF24 -> 0 | W35: =IFERROR(V35/V50,0) -> 0 | X35: =CG24 -> 0 | Y35: =IFERROR(X35/X50,0) -> 0 | Z35: =IFERROR(AB35/X35,"0") -> 0 | AA35: =IFERROR(Z35/Z35,0) -> 0 | AB35: =CH24 -> 0 | AC35: =IFERROR(AB35/AB50,0) -> 0 | AD35: =CI24 -> 0 | AE35: =IFERROR(AD35/AD50,0) -> 0 | AF35: =IFERROR(AH35/AD35,"0") -> 0 | AG35: =IFERROR(AF35/AF35,0) -> 0 | AH35: =CJ24 -> 0 | AI35: =IFERROR(AH35/AH50,0) -> 0 | AJ35: =CK24 -> 0 | AK35: =IFERROR(AJ35/AJ50,0) -> 0 | AL35: =IFERROR(AN35/AJ35,"0") -> 0 | AM35: =IFERROR(AL35/AL35,0) -> 0 | AN35: =CL24 -> 0 | AO35: =IFERROR(AN35/AN50,0) -> 0 | AP35: =CM24 -> 0 | AQ35: =IFERROR(AP35/AP50,0) -> 0 | AR35: =IFERROR(AT35/AP35,"0") -> 0 | AS35: =IFERROR(AR35/AR35,0) -> 0 | AT35: =CN24 -> 0 | AU35: =IFERROR(AT35/AT50,0) -> 0 | AV35: =IFERROR(L35-F35,0) -> -477 | AW35: =IFERROR(AV35/F35,0) -> -1 | AX35: =IFERROR(N35-H35,0) -> -281.02394 | AY35: =IFERROR(AX35/H35,0) -> -1 | AZ35: =IFERROR(P35-J35,0) -> -134048.42 | BA35: =IFERROR(AZ35/J35,0) -> -1 | BB35: =IFERROR(L35-R35,0) -> 0 | BC35: =IFERROR(BB35/R35,0) -> 0 | BD35: =IFERROR(N35-T35,0) -> 0 | BE35: =IFERROR(BD35/T35,0) -> 0 | BF35: =IFERROR(P35-V35,0) -> 0 | BG35: =IFERROR(BF35/V35,0) -> 0 | BH35: =IFERROR(L35-X35,0) -> 0 | BI35: =IFERROR(BH35/X35,0) -> 0 | BJ35: =IFERROR(N35-Z35,0) -> 0 | BK35: =IFERROR(BJ35/Z35,0) -> 0 | BL35: =IFERROR(P35-AB35,0) -> 0 | BM35: =IFERROR(BL35/AB35,0) -> 0 | BN35: =IFERROR(L35-AP35,0) -> 0 | BO35: =IFERROR(BN35/AP35,0) -> 0 | BP35: =IFERROR(N35-AR35,0) -> 0 | BQ35: =IFERROR(BP35/AR35,0) -> 0 | BR35: =IFERROR(P35-AT35,0) -> 0 | BS35: =IFERROR(BR35/AT35,0) -> 0 | BY35: COMP | CA35: =ROUND(기존구분!$F$44*(SUM('파나크 영덕:소노문해운대'!L49)/SUM('파나크 영덕:소노문해운대'!$L$48,'파나크 영덕:소노문해운대'!$L$49)),0)+1 -> 11
E36: Staff | F36: =CA25 -> 45 | G36: =IFERROR(F36/F50,0) -> 0.022865854 | H36: =IFERROR(J36/F36,"0") -> 305.3426 | I36: =IFERROR(H36/H35,0) -> 1.0865359 | J36: =CB25 -> 13740.417 | K36: =IFERROR(J36/J50,0) -> 0.025328888 | L36: =CC25 -> 0 | M36: =IFERROR(L36/L50,0) -> 0 | N36: =IFERROR(P36/L36,"0") -> 0 | O36: =IFERROR(N36/N35,0) -> 0 | P36: =CD25 -> 0 | Q36: =IFERROR(P36/P50,0) -> 0 | R36: =CE25 -> 0 | S36: =IFERROR(R36/R50,0) -> 0 | T36: =IFERROR(V36/R36,"0") -> 0 | U36: =IFERROR(T36/T35,0) -> 0 | V36: =CF25 -> 0 | W36: =IFERROR(V36/V50,0) -> 0 | X36: =CG25 -> 0 | Y36: =IFERROR(X36/X50,0) -> 0 | Z36: =IFERROR(AB36/X36,"0") -> 0 | AA36: =IFERROR(Z36/Z35,0) -> 0 | AB36: =CH25 -> 0 | AC36: =IFERROR(AB36/AB50,0) -> 0 | AD36: =CI25 -> 0 | AE36: =IFERROR(AD36/AD50,0) -> 0 | AF36: =IFERROR(AH36/AD36,"0") -> 0 | AG36: =IFERROR(AF36/AF35,0) -> 0 | AH36: =CJ25 -> 0 | AI36: =IFERROR(AH36/AH50,0) -> 0 | AJ36: =CK25 -> 0 | AK36: =IFERROR(AJ36/AJ50,0) -> 0 | AL36: =IFERROR(AN36/AJ36,"0") -> 0 | AM36: =IFERROR(AL36/AL35,0) -> 0 | AN36: =CL25 -> 0 | AO36: =IFERROR(AN36/AN50,0) -> 0 | AP36: =CM25 -> 0 | AQ36: =IFERROR(AP36/AP50,0) -> 0 | AR36: =IFERROR(AT36/AP36,"0") -> 0 | AS36: =IFERROR(AR36/AR35,0) -> 0 | AT36: =CN25 -> 0 | AU36: =IFERROR(AT36/AT50,0) -> 0 | AV36: =IFERROR(L36-F36,0) -> -45 | AW36: =IFERROR(AV36/F36,0) -> -1 | AX36: =IFERROR(N36-H36,0) -> -305.3426 | AY36: =IFERROR(AX36/H36,0) -> -1 | AZ36: =IFERROR(P36-J36,0) -> -13740.417 | BA36: =IFERROR(AZ36/J36,0) -> -1 | BB36: =IFERROR(L36-R36,0) -> 0 | BC36: =IFERROR(BB36/R36,0) -> 0 | BD36: =IFERROR(N36-T36,0) -> 0 | BE36: =IFERROR(BD36/T36,0) -> 0 | BF36: =IFERROR(P36-V36,0) -> 0 | BG36: =IFERROR(BF36/V36,0) -> 0 | BH36: =IFERROR(L36-X36,0) -> 0 | BI36: =IFERROR(BH36/X36,0) -> 0 | BJ36: =IFERROR(N36-Z36,0) -> 0 | BK36: =IFERROR(BJ36/Z36,0) -> 0 | BL36: =IFERROR(P36-AB36,0) -> 0 | BM36: =IFERROR(BL36/AB36,0) -> 0 | BN36: =IFERROR(L36-AP36,0) -> 0 | BO36: =IFERROR(BN36/AP36,0) -> 0 | BP36: =IFERROR(N36-AR36,0) -> 0 | BQ36: =IFERROR(BP36/AR36,0) -> 0 | BR36: =IFERROR(P36-AT36,0) -> 0 | BS36: =IFERROR(BR36/AT36,0) -> 0 | BX36: 3월 | BY36: 회 원 | BZ36: 기 명 | CA36: =기존구분!$G$46 -> 259
E37: Other | F37: =CA26 -> 28 | G37: =IFERROR(F37/F50,0) -> 0.014227642 | H37: =IFERROR(J37/F37,"0") -> 283.12038 | I37: =IFERROR(H37/H35,0) -> 1.00746 | J37: =CB26 -> 7927.3706 | K37: =IFERROR(J37/J50,0) -> 0.014613201 | L37: =CC26 -> 0 | M37: =IFERROR(L37/L50,0) -> 0 | N37: =IFERROR(P37/L37,"0") -> 0 | O37: =IFERROR(N37/N35,0) -> 0 | P37: =CD26 -> 0 | Q37: =IFERROR(P37/P50,0) -> 0 | R37: =CE26 -> 0 | S37: =IFERROR(R37/R50,0) -> 0 | T37: =IFERROR(V37/R37,"0") -> 0 | U37: =IFERROR(T37/T35,0) -> 0 | V37: =CF26 -> 0 | W37: =IFERROR(V37/V50,0) -> 0 | X37: =CG26 -> 0 | Y37: =IFERROR(X37/X50,0) -> 0 | Z37: =IFERROR(AB37/X37,"0") -> 0 | AA37: =IFERROR(Z37/Z35,0) -> 0 | AB37: =CH26 -> 0 | AC37: =IFERROR(AB37/AB50,0) -> 0 | AD37: =CI26 -> 0 | AE37: =IFERROR(AD37/AD50,0) -> 0 | AF37: =IFERROR(AH37/AD37,"0") -> 0 | AG37: =IFERROR(AF37/AF35,0) -> 0 | AH37: =CJ26 -> 0 | AI37: =IFERROR(AH37/AH50,0) -> 0 | AJ37: =CK26 -> 0 | AK37: =IFERROR(AJ37/AJ50,0) -> 0 | AL37: =IFERROR(AN37/AJ37,"0") -> 0 | AM37: =IFERROR(AL37/AL35,0) -> 0 | AN37: =CL26 -> 0 | AO37: =IFERROR(AN37/AN50,0) -> 0 | AP37: =CM26 -> 0 | AQ37: =IFERROR(AP37/AP50,0) -> 0 | AR37: =IFERROR(AT37/AP37,"0") -> 0 | AS37: =IFERROR(AR37/AR35,0) -> 0 | AT37: =CN26 -> 0 | AU37: =IFERROR(AT37/AT50,0) -> 0 | AV37: =IFERROR(L37-F37,0) -> -28 | AW37: =IFERROR(AV37/F37,0) -> -1 | AX37: =IFERROR(N37-H37,0) -> -283.12038 | AY37: =IFERROR(AX37/H37,0) -> -1 | AZ37: =IFERROR(P37-J37,0) -> -7927.3706 | BA37: =IFERROR(AZ37/J37,0) -> -1 | BB37: =IFERROR(L37-R37,0) -> 0 | BC37: =IFERROR(BB37/R37,0) -> 0 | BD37: =IFERROR(N37-T37,0) -> 0 | BE37: =IFERROR(BD37/T37,0) -> 0 | BF37: =IFERROR(P37-V37,0) -> 0 | BG37: =IFERROR(BF37/V37,0) -> 0 | BH37: =IFERROR(L37-X37,0) -> 0 | BI37: =IFERROR(BH37/X37,0) -> 0 | BJ37: =IFERROR(N37-Z37,0) -> 0 | BK37: =IFERROR(BJ37/Z37,0) -> 0 | BL37: =IFERROR(P37-AB37,0) -> 0 | BM37: =IFERROR(BL37/AB37,0) -> 0 | BN37: =IFERROR(L37-AP37,0) -> 0 | BO37: =IFERROR(BN37/AP37,0) -> 0 | BP37: =IFERROR(N37-AR37,0) -> 0 | BQ37: =IFERROR(BP37/AR37,0) -> 0 | BR37: =IFERROR(P37-AT37,0) -> 0 | BS37: =IFERROR(BR37/AT37,0) -> 0 | BZ37: 무기명 | CA37: =ROUND(기존구분!$G$45*(SUM('파나크 영덕'!L59,소노문해운대!L58:L59)/SUM('파나크 영덕'!L59:L61,소노문해운대!L58:L61)),0) -> 522 | CB37: =CA37*기존구분!$G$53-1000 -> 146788.84
E38: Total | F38: =SUM(F34:F37) -> 782 | G38: =IFERROR(F38/F50,0) -> 0.39735772 | H38: =IFERROR(J38/F38,"0") -> 199.12559 | I38: =IFERROR(H38/H35,0) -> 0.7085716 | J38: =SUM(J34:J37) -> 155716.21 | K38: =IFERROR(J38/J50,0) -> 0.28704503 | L38: =SUM(L34:L37) -> 0 | M38: =IFERROR(L38/L50,0) -> 0 | N38: =IFERROR(P38/L38,"0") -> 0 | O38: =IFERROR(N38/N35,0) -> 0 | P38: =SUM(P34:P37) -> 0 | Q38: =IFERROR(P38/P50,0) -> 0 | R38: =SUM(R34:R37) -> 0 | S38: =IFERROR(R38/R50,0) -> 0 | T38: =IFERROR(V38/R38,"0") -> 0 | U38: =IFERROR(T38/T35,0) -> 0 | V38: =SUM(V34:V37) -> 0 | W38: =IFERROR(V38/V50,0) -> 0 | X38: =SUM(X34:X37) -> 0 | Y38: =IFERROR(X38/X50,0) -> 0 | Z38: =IFERROR(AB38/X38,"0") -> 0 | AA38: =IFERROR(Z38/Z35,0) -> 0 | AB38: =SUM(AB34:AB37) -> 0 | AC38: =IFERROR(AB38/AB50,0) -> 0 | AD38: =SUM(AD34:AD37) -> 0 | AE38: =IFERROR(AD38/AD50,0) -> 0 | AF38: =IFERROR(AH38/AD38,"0") -> 0 | AG38: =IFERROR(AF38/AF35,0) -> 0 | AH38: =SUM(AH34:AH37) -> 0 | AI38: =IFERROR(AH38/AH50,0) -> 0 | AJ38: =SUM(AJ34:AJ37) -> 0 | AK38: =IFERROR(AJ38/AJ50,0) -> 0 | AL38: =IFERROR(AN38/AJ38,"0") -> 0 | AM38: =IFERROR(AL38/AL35,0) -> 0 | AN38: =SUM(AN34:AN37) -> 0 | AO38: =IFERROR(AN38/AN50,0) -> 0 | AP38: =SUM(AP34:AP37) -> 0 | AQ38: =IFERROR(AP38/AP50,0) -> 0 | AR38: =IFERROR(AT38/AP38,"0") -> 0 | AS38: =IFERROR(AR38/AR35,0) -> 0 | AT38: =SUM(AT34:AT37) -> 0 | AU38: =IFERROR(AT38/AT50,0) -> 0 | AV38: =IFERROR(L38-F38,0) -> -782 | AW38: =IFERROR(AV38/F38,0) -> -1 | AX38: =IFERROR(N38-H38,0) -> -199.12559 | AY38: =IFERROR(AX38/H38,0) -> -1 | AZ38: =IFERROR(P38-J38,0) -> -155716.21 | BA38: =IFERROR(AZ38/J38,0) -> -1 | BB38: =IFERROR(L38-R38,0) -> 0 | BC38: =IFERROR(BB38/R38,0) -> 0 | BD38: =IFERROR(N38-T38,0) -> 0 | BE38: =IFERROR(BD38/T38,0) -> 0 | BF38: =IFERROR(P38-V38,0) -> 0 | BG38: =IFERROR(BF38/V38,0) -> 0 | BH38: =IFERROR(L38-X38,0) -> 0 | BI38: =IFERROR(BH38/X38,0) -> 0 | BJ38: =IFERROR(N38-Z38,0) -> 0 | BK38: =IFERROR(BJ38/Z38,0) -> 0 | BL38: =IFERROR(P38-AB38,0) -> 0 | BM38: =IFERROR(BL38/AB38,0) -> 0 | BN38: =IFERROR(L38-AP38,0) -> 0 | BO38: =IFERROR(BN38/AP38,0) -> 0 | BP38: =IFERROR(N38-AR38,0) -> 0 | BQ38: =IFERROR(BP38/AR38,0) -> 0 | BR38: =IFERROR(P38-AT38,0) -> 0 | BS38: =IFERROR(BR38/AT38,0) -> 0 | BZ38: 직 원 | CA38: =ROUND(기존구분!$G$45*(SUM('파나크 영덕:소노문해운대'!L60)/SUM('파나크 영덕'!L59:L61,소노문해운대!L58:L61)),0) -> 54 | CB38: =CA38*기존구분!$G$53+1000 -> 16288.5
D39: Group | E39: G-Mice | F39: =CA27 -> 0 | G39: =IFERROR(F39/F50,0) -> 0 | H39: =IFERROR(J39/F39,"0") -> 0 | I39: =IFERROR(H39/H35,0) -> 0 | J39: =CB27 -> 0 | K39: =IFERROR(J39/J50,0) -> 0 | L39: =CC27 -> 0 | M39: =IFERROR(L39/L50,0) -> 0 | N39: =IFERROR(P39/L39,"0") -> 0 | O39: =IFERROR(N39/N35,0) -> 0 | P39: =CD27 -> 0 | Q39: =IFERROR(P39/P50,0) -> 0 | R39: =CE27 -> 0 | S39: =IFERROR(R39/R50,0) -> 0 | T39: =IFERROR(V39/R39,"0") -> 0 | U39: =IFERROR(T39/T35,0) -> 0 | V39: =CF27 -> 0 | W39: =IFERROR(V39/V50,0) -> 0 | X39: =CG27 -> 0 | Y39: =IFERROR(X39/X50,0) -> 0 | Z39: =IFERROR(AB39/X39,"0") -> 0 | AA39: =IFERROR(Z39/Z35,0) -> 0 | AB39: =CH27 -> 0 | AC39: =IFERROR(AB39/AB50,0) -> 0 | AD39: =CI27 -> 0 | AE39: =IFERROR(AD39/AD50,0) -> 0 | AF39: =IFERROR(AH39/AD39,"0") -> 0 | AG39: =IFERROR(AF39/AF35,0) -> 0 | AH39: =CJ27 -> 0 | AI39: =IFERROR(AH39/AH50,0) -> 0 | AJ39: =CK27 -> 0 | AK39: =IFERROR(AJ39/AJ50,0) -> 0 | AL39: =IFERROR(AN39/AJ39,"0") -> 0 | AM39: =IFERROR(AL39/AL35,0) -> 0 | AN39: =CL27 -> 0 | AO39: =IFERROR(AN39/AN50,0) -> 0 | AP39: =CM27 -> 0 | AQ39: =IFERROR(AP39/AP50,0) -> 0 | AR39: =IFERROR(AT39/AP39,"0") -> 0 | AS39: =IFERROR(AR39/AR35,0) -> 0 | AT39: =CN27 -> 0 | AU39: =IFERROR(AT39/AT50,0) -> 0 | AV39: =IFERROR(L39-F39,0) -> 0 | AW39: =IFERROR(AV39/F39,0) -> 0 | AX39: =IFERROR(N39-H39,0) -> 0 | AY39: =IFERROR(AX39/H39,0) -> 0 | AZ39: =IFERROR(P39-J39,0) -> 0 | BA39: =IFERROR(AZ39/J39,0) -> 0 | BB39: =IFERROR(L39-R39,0) -> 0 | BC39: =IFERROR(BB39/R39,0) -> 0 | BD39: =IFERROR(N39-T39,0) -> 0 | BE39: =IFERROR(BD39/T39,0) -> 0 | BF39: =IFERROR(P39-V39,0) -> 0 | BG39: =IFERROR(BF39/V39,0) -> 0 | BH39: =IFERROR(L39-X39,0) -> 0 | BI39: =IFERROR(BH39/X39,0) -> 0 | BJ39: =IFERROR(N39-Z39,0) -> 0 | BK39: =IFERROR(BJ39/Z39,0) -> 0 | BL39: =IFERROR(P39-AB39,0) -> 0 | BM39: =IFERROR(BL39/AB39,0) -> 0 | BN39: =IFERROR(L39-AP39,0) -> 0 | BO39: =IFERROR(BN39/AP39,0) -> 0 | BP39: =IFERROR(N39-AR39,0) -> 0 | BQ39: =IFERROR(BP39/AR39,0) -> 0 | BR39: =IFERROR(P39-AT39,0) -> 0 | BS39: =IFERROR(BR39/AT39,0) -> 0 | BZ39: 기 타 | CA39: =ROUND(기존구분!$G$45*(SUM('파나크 영덕:소노문해운대'!L61)/SUM('파나크 영덕'!L59:L61,소노문해운대!L58:L61)),0) -> 38 | CB39: =CA39*기존구분!$G$53 -> 10758.574
E40: E-Mice | F40: =CA28 -> 0 | G40: =IFERROR(F40/F50,0) -> 0 | H40: =IFERROR(J40/F40,"0") -> 0 | I40: =IFERROR(H40/H35,0) -> 0 | J40: =CB28 -> 0 | K40: =IFERROR(J40/J50,0) -> 0 | L40: =CC28 -> 0 | M40: =IFERROR(L40/L50,0) -> 0 | N40: =IFERROR(P40/L40,"0") -> 0 | O40: =IFERROR(N40/N35,0) -> 0 | P40: =CD28 -> 0 | Q40: =IFERROR(P40/P50,0) -> 0 | R40: =CE28 -> 0 | S40: =IFERROR(R40/R50,0) -> 0 | T40: =IFERROR(V40/R40,"0") -> 0 | U40: =IFERROR(T40/T35,0) -> 0 | V40: =CF28 -> 0 | W40: =IFERROR(V40/V50,0) -> 0 | X40: =CG28 -> 0 | Y40: =IFERROR(X40/X50,0) -> 0 | Z40: =IFERROR(AB40/X40,"0") -> 0 | AA40: =IFERROR(Z40/Z35,0) -> 0 | AB40: =CH28 -> 0 | AC40: =IFERROR(AB40/AB50,0) -> 0 | AD40: =CI28 -> 0 | AE40: =IFERROR(AD40/AD50,0) -> 0 | AF40: =IFERROR(AH40/AD40,"0") -> 0 | AG40: =IFERROR(AF40/AF35,0) -> 0 | AH40: =CJ28 -> 0 | AI40: =IFERROR(AH40/AH50,0) -> 0 | AJ40: =CK28 -> 0 | AK40: =IFERROR(AJ40/AJ50,0) -> 0 | AL40: =IFERROR(AN40/AJ40,"0") -> 0 | AM40: =IFERROR(AL40/AL35,0) -> 0 | AN40: =CL28 -> 0 | AO40: =IFERROR(AN40/AN50,0) -> 0 | AP40: =CM28 -> 0 | AQ40: =IFERROR(AP40/AP50,0) -> 0 | AR40: =IFERROR(AT40/AP40,"0") -> 0 | AS40: =IFERROR(AR40/AR35,0) -> 0 | AT40: =CN28 -> 0 | AU40: =IFERROR(AT40/AT50,0) -> 0 | AV40: =IFERROR(L40-F40,0) -> 0 | AW40: =IFERROR(AV40/F40,0) -> 0 | AX40: =IFERROR(N40-H40,0) -> 0 | AY40: =IFERROR(AX40/H40,0) -> 0 | AZ40: =IFERROR(P40-J40,0) -> 0 | BA40: =IFERROR(AZ40/J40,0) -> 0 | BB40: =IFERROR(L40-R40,0) -> 0 | BC40: =IFERROR(BB40/R40,0) -> 0 | BD40: =IFERROR(N40-T40,0) -> 0 | BE40: =IFERROR(BD40/T40,0) -> 0 | BF40: =IFERROR(P40-V40,0) -> 0 | BG40: =IFERROR(BF40/V40,0) -> 0 | BH40: =IFERROR(L40-X40,0) -> 0 | BI40: =IFERROR(BH40/X40,0) -> 0 | BJ40: =IFERROR(N40-Z40,0) -> 0 | BK40: =IFERROR(BJ40/Z40,0) -> 0 | BL40: =IFERROR(P40-AB40,0) -> 0 | BM40: =IFERROR(BL40/AB40,0) -> 0 | BN40: =IFERROR(L40-AP40,0) -> 0 | BO40: =IFERROR(BN40/AP40,0) -> 0 | BP40: =IFERROR(N40-AR40,0) -> 0 | BQ40: =IFERROR(BP40/AR40,0) -> 0 | BR40: =IFERROR(P40-AT40,0) -> 0 | BS40: =IFERROR(BR40/AT40,0) -> 0 | BY40: 단 체 | BZ40: 일 반
