Workbook
Name _______A1: #REF!
Name _______A1: #REF!
Name _______A1: #REF!
Name _______A1: #REF!
Name _______A1: #REF!
Name _______A1: #REF!
Name ______A1: #REF!
Name ______A1: #REF!
Name ______A1: #REF!
Name ______A1: #REF!
Name ______A1: #REF!
Name ______A1: #REF!
Name _____A1: #REF!
Name _____A1: #REF!
Name _____A1: #REF!
Name _____A1: #REF!
Name _____A1: #REF!
Name _____A1: #REF!
Name ____A1: #REF!
Name ____A1: #REF!
Name ____A1: #REF!
Name ____A1: #REF!
Name ____A1: #REF!
Name ____A1: #REF!
Name ___ST1: #N/A
Name ___YO1: #N/A
Name __IntlFixup: TRUE
Name __mac03: [1]장비!$M$125
Name __mac10: [1]장비!$M$133
Name __mbh07: [1]장비!$M$21
Name __mdt02: [1]장비!$M$241
Name __mdt15: [1]장비!$M$17
Name __mgn05: [1]장비!$M$177
Name __mgp45: [1]장비!$M$237
Name __mlm10: [1]장비!$M$165
Name __mlt17: [1]장비!$M$33
Name __mmd36: [1]장비!$M$37
Name __mmr08: [1]장비!$M$45
Name __mmr10: [1]장비!$M$41
Name __mmx02: [1]장비!$M$221
Name __mtc30: [1]장비!$M$85
Name __mtd10: [1]장비!$M$49
Name __mtr08: [1]장비!$M$57
Name __mvr10: [1]장비!$M$53
Name __mwt55: [1]장비!$M$161
Name __R69496: '[2]입출재고현황 (2)'!$R$62503
Name __R70000: '[2]입출재고현황 (2)'!$R$60007
Name __R80000: '[2]입출재고현황 (2)'!$R$20007
Name __R90000: '[2]입출재고현황 (2)'!$R$20007
Name __R99000: '[2]입출재고현황 (2)'!$R$11947
Name __ST1: #N/A
Name __YO1: #N/A
Name _\Z: [3]결과조달!$GU$5658:$IV$7860
Name _10A_61: #N/A
Name _10A_62: #N/A
Name _10A_63: #N/A
Name _10A_64: #N/A
Name _10A_65: #N/A
Name _10A_66: #N/A
Name _10A_67: #N/A

Sheet 요약
A1: 2026년 팔라티움 해운대 사업계획
A3: ■ 총괄
Q4: [단위 : 백만원]
B5: 구분 | D5: 합계 | E5: 2026년 사업계획 | Q5: 비고
E6: 1 | F6: 2 | G6: 3 | H6: 4 | I6: 5 | J6: 6 | K6: 7 | L6: 8 | M6: 9 | N6: 10 | O6: 11 | P6: 12
B7: 판매객실수(실) | D7: =SUM(E7:P7) -> 55510 | E7: =SUM(Sheet1!Y23:Y25) -> 4111 | F7: =SUM(Sheet1!Z23:Z25) -> 3333 | G7: =SUM(Sheet1!AA23:AA25) -> 3732 | H7: =SUM(Sheet1!AB23:AB25) -> 4122 | I7: =SUM(Sheet1!AC23:AC25) -> 4774 | J7: =SUM(Sheet1!AD23:AD25) -> 4788 | K7: =SUM(Sheet1!AE23:AE25) -> 5516 | L7: =SUM(Sheet1!AF23:AF25) -> 5903 | ... P7: =SUM(Sheet1!AJ23:AJ25) -> 4365 | U7: 2896 | V7: =238*0.7 -> 166.6
B8: 투숙률 | D8: =D7/Sheet1!X31 -> 0.63900081 | E8: =E7/Sheet1!Y31 -> 0.55719707 | F8: =F7/Sheet1!Z31 -> 0.50015006 | G8: =G7/Sheet1!AA31 -> 0.50582814 | H8: =H7/Sheet1!AB31 -> 0.57731092 | I8: =I7/Sheet1!AC31 -> 0.64705882 | J8: =J7/Sheet1!AD31 -> 0.67058824 | K8: =K7/Sheet1!AE31 -> 0.74762808 | ... P8: =P7/Sheet1!AJ31 -> 0.59162375 | Q8: - 연간 투숙률 64% | U8: =+U7*0.65 -> 1882.4 | V8: 166
B9: ADR(천원) | D9: =매출목표!G7/요약!D7 -> 293.99782 | E9: =매출목표!H7/요약!E7 -> 291.66172 | F9: =매출목표!I7/요약!F7 -> 291.29582 | G9: =매출목표!J7/요약!G7 -> 291.39847 | H9: =매출목표!K7/요약!H7 -> 291.62481 | I9: =매출목표!L7/요약!I7 -> 293.55779 | J9: =매출목표!M7/요약!J7 -> 295.90756 | K9: =매출목표!N7/요약!K7 -> 291.74667 | ... P9: =매출목표!S7/요약!P7 -> 296.57639 | Q9: - 연간 ADR 294,000원 | U9: =+U8*5% -> 94.12 | V9: =+V8*365 -> 60590
B10: Ⅰ. 매 출 액 | D10: =SUM(E10:P10) -> 16483017 | E10: =E11 -> 1211011.6 | F10: =F11 -> 980597.85 | G10: =G11 -> 1098374.1 | H10: =H11 -> 1214098.2 | I10: =I11 -> 1415459.3 | J10: =J11 -> 1430973.5 | K10: =K11 -> 1625367.4 | L10: =L11 -> 1740604.4 | ... P10: =P11 -> 1307501.5 | U10: =72-94 -> -22 | V10: =+V9*294 -> 17813460
C11: 객 실 | D11: =SUM(E11:P11) -> 16483017 | E11: =매출목표!H9 -> 1211011.6 | F11: =매출목표!I9 -> 980597.85 | G11: =매출목표!J9 -> 1098374.1 | H11: =매출목표!K9 -> 1214098.2 | I11: =매출목표!L9 -> 1415459.3 | J11: =매출목표!M9 -> 1430973.5 | K11: =매출목표!N9 -> 1625367.4 | L11: =매출목표!O9 -> 1740604.4 | ... P11: =매출목표!S9 -> 1307501.5 | V11: =16483-17813 -> -1330
B12: Ⅱ. 운 영 원 가 | D12: =SUM(E12:P12) -> 8772294.2 | E12: =SUM(E13:E24) -> 676278.79 | F12: =SUM(F13:F24) -> 607309.9 | G12: =SUM(G13:G24) -> 645438.95 | H12: =SUM(H13:H24) -> 676950.8 | I12: =SUM(I13:I24) -> 736935.26 | J12: =SUM(J13:J24) -> 745016.25 | K12: =SUM(K13:K24) -> 799821.6 | L12: =SUM(L13:L24) -> 834184.8 | ... P12: =SUM(P13:P24) -> 773565.8
C13: 인 건 비 | D13: =SUM(E13:P13) -> 928527.07 | E13: =E39 -> 71928.153 | F13: =F39 -> 71928.153 | G13: =G39 -> 71928.153 | H13: =H39 -> 71928.153 | I13: =I39 -> 71928.153 | J13: =J39 -> 71928.153 | K13: =K39 -> 71928.153 | L13: =L39 -> 71928.153 | ... P13: =P39 -> 137317.38 | Q13: - 인력 운영계획 기준 (직영 16명)
C14: 재 료 비 | D14: =SUM(E14:P14) -> 0 | E14: =E40 -> 0 | F14: =F40 -> 0 | G14: =G40 -> 0 | H14: =H40 -> 0 | I14: =I40 -> 0 | J14: =J40 -> 0 | K14: =K40 -> 0 | L14: =L40 -> 0 | ... P14: =P40 -> 0 | Q14: - 미반영
C15: 용 역 비 | D15: =SUM(E15:P15) -> 2010992.9 | E15: =E45 -> 166769.87 | F15: =F45 -> 165617.8 | G15: =G45 -> 166206.68 | H15: =H45 -> 166785.31 | I15: =I45 -> 167792.11 | J15: =J45 -> 167869.68 | K15: =K45 -> 168841.65 | L15: =L45 -> 169417.84 | ... P15: =P45 -> 167252.32 | Q15: - 도급운영 인력계획 기준 (객실 17명), 객실정비료 실당 23천원
C16: 복리후생비 | D16: =SUM(E16:P16) -> 203423.88 | E16: =E56 -> 16918.656 | F16: =F56 -> 16918.656 | G16: =G56 -> 16918.656 | H16: =H56 -> 16918.656 | I16: =I56 -> 16918.656 | J16: =J56 -> 16918.656 | K16: =K56 -> 17118.656 | L16: =L56 -> 17118.656 | ... P16: =P56 -> 16918.656 | Q16: - 직영 16명 기준(급식대, 경조사비, 의료비 등) 적용
C17: 수도광열비 | D17: =SUM(E17:P17) -> 1307103.2 | E17: =E62 -> 96033.217 | F17: =F62 -> 77761.41 | G17: =G62 -> 87101.066 | H17: =H62 -> 96277.989 | I17: =I62 -> 112245.93 | J17: =J62 -> 113476.2 | K17: =K62 -> 128891.63 | L17: =L62 -> 138029.93 | ... P17: =P62 -> 103684.87 | Q17: - 총매출 x 소노문 해운대 1~8월 집행률. 계정별 별도 가중치 적용
C18: 소 모 품 비 | D18: =SUM(E18:P18) -> 560422.58 | E18: =E63 -> 41174.393 | F18: =F63 -> 33340.327 | G18: =G63 -> 37344.719 | H18: =H63 -> 41279.34 | I18: =I63 -> 48125.618 | J18: =J63 -> 48653.098 | K18: =K63 -> 55262.49 | L18: =L63 -> 59180.55 | ... P18: =P63 -> 44455.05 | Q18: - 총매출 x 소노인터내셔널 전사업장 1~8월 누계 3.4% 적용
C19: 지급수수료 | D19: =SUM(E19:P19) -> 3502196.5 | E19: =E68 -> 264550.92 | F19: =F68 -> 225739.73 | G19: =G68 -> 245581.43 | H19: =H68 -> 265072.28 | I19: =I68 -> 298920.06 | J19: =J68 -> 301437.32 | K19: =K68 -> 334360.35 | L19: =L68 -> 353765.77 | ... P19: =P68 -> 280624.31 | Q19: - 카드수수료, 위탁수수료, 영업용역료(외부 수수료 10% 등) 반영
C20: 수 선 비 | D20: =SUM(E20:P20) -> 8241.5085 | E20: =E69 -> 605.50578 | F20: =F69 -> 490.29893 | G20: =G69 -> 549.18705 | H20: =H69 -> 607.04911 | I20: =I69 -> 707.72967 | J20: =J69 -> 715.48673 | K20: =K69 -> 812.68368 | L20: =L69 -> 870.3022 | ... P20: =P69 -> 653.75074 | Q20: - 총매출 x 2019년 쏠비치 진도 오픈 초 수선비율 0.05% 적용
C21: 광고선전비 | D21: =SUM(E21:P21) -> 18000 | E21: =E74 -> 500 | F21: =F74 -> 500 | G21: =G74 -> 3500 | H21: =H74 -> 500 | I21: =I74 -> 500 | J21: =J74 -> 3500 | K21: =K74 -> 500 | L21: =L74 -> 500 | ... P21: =P74 -> 3500 | Q21: - 영업활성화 최소 광고비 집행 반영(분기별 예비성 예산)
C22: 세금과공과 | D22: =SUM(E22:P22) -> 4973.3538 | E22: =E83 -> 576.94615 | F22: =F83 -> 326.94615 | G22: =G83 -> 326.94615 | H22: =H83 -> 326.94615 | I22: =I83 -> 326.94615 | J22: =J83 -> 726.94615 | K22: =K83 -> 326.94615 | L22: =L83 -> 326.94615 | ... P22: =P83 -> 726.94615 | Q22: - 주민세 인건비 X 0.5% 반영
C23: 감가상각비 | D23: =SUM(E23:P23) -> 36000 | E23: =E86 -> 3000 | F23: =F86 -> 3000 | G23: =G86 -> 3000 | H23: =H86 -> 3000 | I23: =I86 -> 3000 | J23: =J86 -> 3000 | K23: =K86 -> 3000 | L23: =L86 -> 3000 | ... P23: =P86 -> 3000 | Q23: - 유형자산 감가상각비 월 3,000천원 반영
C24: 기 타 경 비 | D24: =SUM(E24:P24) -> 192413.19 | E24: =E96 -> 14221.127 | F24: =F96 -> 11686.576 | G24: =G96 -> 12982.115 | H24: =H96 -> 14255.08 | I24: =I96 -> 16470.053 | J24: =J96 -> 16790.708 | K24: =K96 -> 18779.041 | L24: =L96 -> 20046.649 | ... P24: =P96 -> 15432.516 | Q24: - 지급임차료, 보험료, 교통비, 통신비 등 반영
B25: Ⅲ. 영 업 이 익 | D25: =SUM(E25:P25) -> 7710722.7 | E25: =E10-E12 -> 534732.77 | F25: =F10-F12 -> 373287.96 | G25: =G10-G12 -> 452935.15 | H25: =H10-H12 -> 537147.42 | I25: =I10-I12 -> 678524.09 | J25: =J10-J12 -> 685957.21 | K25: =K10-K12 -> 825545.76 | L25: =L10-L12 -> 906419.61 | ... P25: =P10-P12 -> 533935.68
C26: % | D26: =D25/D$10 -> 0.46779802 | E26: =E25/E$10 -> 0.44155877 | F26: =F25/F$10 -> 0.38067385 | G26: =G25/G$10 -> 0.41236874 | H26: =H25/H$10 -> 0.44242501 | I26: =I25/I$10 -> 0.47936671 | J26: =J25/J$10 -> 0.47936404 | K26: =K25/K$10 -> 0.50791334 | ... P26: =P25/P$10 -> 0.40836335
B27: Ⅳ. 영 업 이 익[+@] | D27: =SUM(E27:P27) -> 7170972.1 | E27: =E25 -> 534732.77 | F27: =F25 -> 373287.96 | G27: =G25 -> 452935.15 | H27: =H25 -> 537147.42 | I27: =I25 -> 678524.09 | J27: =J25 -> 685957.21 | K27: =K25 -> 825545.76 | L27: =L25 -> 906419.61 | ... O27: =O25 -> 643338.85 | P27: =P25-(D25*7%) -> -5814.9076 | Q27: 이익률 47% 기준 Incentive Fee 7% 적용. 12월 +540백
C28: % | D28: =D27/D$10 -> 0.43505216 | E28: =E27/E$10 -> 0.44155877 | F28: =F27/F$10 -> 0.38067385 | G28: =G27/G$10 -> 0.41236874 | H28: =H27/H$10 -> 0.44242501 | I28: =I27/I$10 -> 0.47936671 | J28: =J27/J$10 -> 0.47936404 | K28: =K27/K$10 -> 0.50791334 | ... P28: =P27/P$10 -> -0.0044473431
A30: ■ 운영원가 세부
Q31: [단위 : 백만원]
B32: 구분 | D32: 합계 | E32: 2026년 사업계획 | Q32: 비고
E33: 1 | F33: 2 | G33: 3 | H33: 4 | I33: 5 | J33: 6 | K33: 7 | L33: 8 | M33: 9 | N33: 10 | O33: 11 | P33: 12
B34: 급료 | D34: =SUM(E34:P34) -> 784670.76 | E34: =손익계산서!E33 -> 65389.23 | F34: =손익계산서!F33 -> 65389.23 | G34: =손익계산서!G33 -> 65389.23 | H34: =손익계산서!H33 -> 65389.23 | I34: =손익계산서!I33 -> 65389.23 | J34: =손익계산서!J33 -> 65389.23 | K34: =손익계산서!K33 -> 65389.23 | L34: =손익계산서!L33 -> 65389.23 | ... P34: =손익계산서!P33 -> 65389.23 | Q34: #)참고자료 1. 인력계획 참고 (직영 28명 기준)
B35: 임금 | D35: =SUM(E35:P35) -> 0 | E35: =손익계산서!E34 -> 0 | F35: =손익계산서!F34 -> 0 | G35: =손익계산서!G34 -> 0 | H35: =손익계산서!H34 -> 0 | I35: =손익계산서!I34 -> 0 | J35: =손익계산서!J34 -> 0 | K35: =손익계산서!K34 -> 0 | L35: =손익계산서!L34 -> 0 | ... P35: =손익계산서!P34 -> 0 | Q35: 미반영
B36: 상여금 | D36: =SUM(E36:P36) -> 65389.23 | E36: =손익계산서!E35 -> 0 | F36: =손익계산서!F35 -> 0 | G36: =손익계산서!G35 -> 0 | H36: =손익계산서!H35 -> 0 | I36: =손익계산서!I35 -> 0 | J36: =손익계산서!J35 -> 0 | K36: =손익계산서!K35 -> 0 | L36: =손익계산서!L35 -> 0 | ... P36: =손익계산서!P35 -> 65389.23 | Q36: 12월 성과급 월급여 100% 지급 가정
B37: 제수당 | D37: =SUM(E37:P37) -> 0 | E37: =손익계산서!E36 -> 0 | F37: =손익계산서!F36 -> 0 | G37: =손익계산서!G36 -> 0 | H37: =손익계산서!H36 -> 0 | I37: =손익계산서!I36 -> 0 | J37: =손익계산서!J36 -> 0 | K37: =손익계산서!K36 -> 0 | L37: =손익계산서!L36 -> 0 | ... P37: =손익계산서!P36 -> 0 | Q37: 미반영(급료 단가포함)
B38: 퇴직급여 | D38: =SUM(E38:P38) -> 78467.076 | E38: =손익계산서!E37 -> 6538.923 | F38: =손익계산서!F37 -> 6538.923 | G38: =손익계산서!G37 -> 6538.923 | H38: =손익계산서!H37 -> 6538.923 | I38: =손익계산서!I37 -> 6538.923 | J38: =손익계산서!J37 -> 6538.923 | K38: =손익계산서!K37 -> 6538.923 | L38: =손익계산서!L37 -> 6538.923 | ... P38: =손익계산서!P37 -> 6538.923 | Q38: 급여 10% 충당금 설정
B39: 인건비소계 | D39: =SUM(E39:P39) -> 928527.07 | E39: =SUM(E34:E38) -> 71928.153 | F39: =SUM(F34:F38) -> 71928.153 | G39: =SUM(G34:G38) -> 71928.153 | H39: =SUM(H34:H38) -> 71928.153 | I39: =SUM(I34:I38) -> 71928.153 | J39: =SUM(J34:J38) -> 71928.153 | K39: =SUM(K34:K38) -> 71928.153 | L39: =SUM(L34:L38) -> 71928.153 | ... P39: =SUM(P34:P38) -> 137317.38
B40: 재료비소계 | D40: =SUM(E40:P40) -> 0 | E40: =손익계산서!E39 -> 0 | F40: =손익계산서!F39 -> 0 | G40: =손익계산서!G39 -> 0 | H40: =손익계산서!H39 -> 0 | I40: =손익계산서!I39 -> 0 | J40: =손익계산서!J39 -> 0 | K40: =손익계산서!K39 -> 0 | L40: =손익계산서!L39 -> 0 | ... P40: =손익계산서!P39 -> 0 | Q40: 소노문 해운대 Lounge, Moon 재료비율 적용(1~8월 누계 43%)
B41: 고정도급비 | D41: =SUM(E41:P41) -> 651849.38 | E41: =손익계산서!E40 -> 54320.781 | F41: =손익계산서!F40 -> 54320.781 | G41: =손익계산서!G40 -> 54320.781 | H41: =손익계산서!H40 -> 54320.781 | I41: =손익계산서!I40 -> 54320.781 | J41: =손익계산서!J40 -> 54320.781 | K41: =손익계산서!K40 -> 54320.781 | L41: =손익계산서!L40 -> 54320.781 | ... P41: =손익계산서!P40 -> 54320.781 | Q41: #)참고자료 1. 인력계획 참고
B42: 추가도급비 | D42: =SUM(E42:P42) -> 0 | E42: =손익계산서!E41 -> 0 | F42: =손익계산서!F41 -> 0 | G42: =손익계산서!G41 -> 0 | H42: =손익계산서!H41 -> 0 | I42: =손익계산서!I41 -> 0 | J42: =손익계산서!J41 -> 0 | K42: =손익계산서!K41 -> 0 | L42: =손익계산서!L41 -> 0 | ... P42: =손익계산서!P41 -> 0 | Q42: 미반영
...

Sheet 손익계산서
A1: 2026년 팔라티움 해운대 사업계획
A3: ■ 총괄
Q4: [단위 : 백만원]
B5: 구분 | D5: 합계 | E5: 2026년 사업계획 | Q5: 비고
E6: 1 | F6: 2 | G6: 3 | H6: 4 | I6: 5 | J6: 6 | K6: 7 | L6: 8 | M6: 9 | N6: 10 | O6: 11 | P6: 12
B7: Ⅰ. 매 출 액 | D7: =SUM(E7:P7) -> 16483017 | E7: =E8 -> 1211011.6 | F7: =F8 -> 980597.85 | G7: =G8 -> 1098374.1 | H7: =H8 -> 1214098.2 | I7: =I8 -> 1415459.3 | J7: =J8 -> 1430973.5 | K7: =K8 -> 1625367.4 | L7: =L8 -> 1740604.4 | ... P7: =P8 -> 1307501.5
C8: 객실 | D8: =SUM(E8:P8) -> 16483017 | E8: =매출목표!H9 -> 1211011.6 | F8: =매출목표!I9 -> 980597.85 | G8: =매출목표!J9 -> 1098374.1 | H8: =매출목표!K9 -> 1214098.2 | I8: =매출목표!L9 -> 1415459.3 | J8: =매출목표!M9 -> 1430973.5 | K8: =매출목표!N9 -> 1625367.4 | L8: =매출목표!O9 -> 1740604.4 | ... P8: =매출목표!S9 -> 1307501.5 | Q8: - 투숙률 64%, ADR 324천원
B9: Ⅱ. 운 영 원 가 | D9: =SUM(E9:P9) -> 8772294.2 | E9: =SUM(E10:E21) -> 676278.79 | F9: =SUM(F10:F21) -> 607309.9 | G9: =SUM(G10:G21) -> 645438.95 | H9: =SUM(H10:H21) -> 676950.8 | I9: =SUM(I10:I21) -> 736935.26 | J9: =SUM(J10:J21) -> 745016.25 | K9: =SUM(K10:K21) -> 799821.6 | L9: =SUM(L10:L21) -> 834184.8 | ... P9: =SUM(P10:P21) -> 773565.8
C10: 인 건 비 | D10: =SUM(E10:P10) -> 928527.07 | E10: =E38 -> 71928.153 | F10: =F38 -> 71928.153 | G10: =G38 -> 71928.153 | H10: =H38 -> 71928.153 | I10: =I38 -> 71928.153 | J10: =J38 -> 71928.153 | K10: =K38 -> 71928.153 | L10: =L38 -> 71928.153 | ... P10: =P38 -> 137317.38 | Q10: - 24.12.30 프랜차이즈 검토 인력계획 참고 (직영 16명 기준)
C11: 재 료 비 | D11: =SUM(E11:P11) -> 0 | E11: =E39 -> 0 | F11: =F39 -> 0 | G11: =G39 -> 0 | H11: =H39 -> 0 | I11: =I39 -> 0 | J11: =J39 -> 0 | K11: =K39 -> 0 | L11: =L39 -> 0 | ... P11: =P39 -> 0 | Q11: - 소노문 해운대 Lounge, Moon 재료비율 적용(1~8월 누계 43%)
C12: 용 역 비 | D12: =SUM(E12:P12) -> 2010992.9 | E12: =E44 -> 166769.87 | F12: =F44 -> 165617.8 | G12: =G44 -> 166206.68 | H12: =H44 -> 166785.31 | I12: =I44 -> 167792.11 | J12: =J44 -> 167869.68 | K12: =K44 -> 168841.65 | L12: =L44 -> 169417.84 | ... P12: =P44 -> 167252.32 | Q12: - 24.12.30 프랜차이즈 검토 인력계획 참고 (도급 62명 기준)
C13: 복리후생비 | D13: =SUM(E13:P13) -> 203423.88 | E13: =E55 -> 16918.656 | F13: =F55 -> 16918.656 | G13: =G55 -> 16918.656 | H13: =H55 -> 16918.656 | I13: =I55 -> 16918.656 | J13: =J55 -> 16918.656 | K13: =K55 -> 17118.656 | L13: =L55 -> 17118.656 | ... P13: =P55 -> 16918.656 | Q13: - 직영 16명 기준(급식대, 경조사비, 의료비 등) 적용
C14: 수도광열비 | D14: =SUM(E14:P14) -> 1307103.2 | E14: =E61 -> 96033.217 | F14: =F61 -> 77761.41 | G14: =G61 -> 87101.066 | H14: =H61 -> 96277.989 | I14: =I61 -> 112245.93 | J14: =J61 -> 113476.2 | K14: =K61 -> 128891.63 | L14: =L61 -> 138029.93 | ... P14: =P61 -> 103684.87 | Q14: - 총매출 x 소노문 해운대 1~8월 평균 집행률 x 130% 적용
C15: 소 모 품 비 | D15: =SUM(E15:P15) -> 560422.58 | E15: =E62 -> 41174.393 | F15: =F62 -> 33340.327 | G15: =G62 -> 37344.719 | H15: =H62 -> 41279.34 | I15: =I62 -> 48125.618 | J15: =J62 -> 48653.098 | K15: =K62 -> 55262.49 | L15: =L62 -> 59180.55 | ... P15: =P62 -> 44455.05 | Q15: - 총매출 x 소노인터내셔널 전사업장 1~8월 누계 3.4% 적용
C16: 지급수수료 | D16: =SUM(E16:P16) -> 3502196.5 | E16: =E67 -> 264550.92 | F16: =F67 -> 225739.73 | G16: =G67 -> 245581.43 | H16: =H67 -> 265072.28 | I16: =I67 -> 298920.06 | J16: =J67 -> 301437.32 | K16: =K67 -> 334360.35 | L16: =L67 -> 353765.77 | ... P16: =P67 -> 280624.31 | Q16: - 카드수수료, 위탁수수료, 영업용역료 반영
C17: 수 선 비 | D17: =SUM(E17:P17) -> 8241.5085 | E17: =E68 -> 605.50578 | F17: =F68 -> 490.29893 | G17: =G68 -> 549.18705 | H17: =H68 -> 607.04911 | I17: =I68 -> 707.72967 | J17: =J68 -> 715.48673 | K17: =K68 -> 812.68368 | L17: =L68 -> 870.3022 | ... P17: =P68 -> 653.75074 | Q17: - 총매출 x 2019년 쏠비치 진도 오픈 초 수선비율 0.05% 적용
C18: 광고선전비 | D18: =SUM(E18:P18) -> 18000 | E18: =E73 -> 500 | F18: =F73 -> 500 | G18: =G73 -> 3500 | H18: =H73 -> 500 | I18: =I73 -> 500 | J18: =J73 -> 3500 | K18: =K73 -> 500 | L18: =L73 -> 500 | ... P18: =P73 -> 3500 | Q18: - 영업활성화 최소 광고비 집행 반영(분기별 예비성 예산)
C19: 세금과공과 | D19: =SUM(E19:P19) -> 4973.3538 | E19: =E82 -> 576.94615 | F19: =F82 -> 326.94615 | G19: =G82 -> 326.94615 | H19: =H82 -> 326.94615 | I19: =I82 -> 326.94615 | J19: =J82 -> 726.94615 | K19: =K82 -> 326.94615 | L19: =L82 -> 326.94615 | ... P19: =P82 -> 726.94615 | Q19: - 재산세&종부세 소노문 해운대 24년 집행액 x 130% 적용
C20: 감가상각비 | D20: =SUM(E20:P20) -> 36000 | E20: =E85 -> 3000 | F20: =F85 -> 3000 | G20: =G85 -> 3000 | H20: =H85 -> 3000 | I20: =I85 -> 3000 | J20: =J85 -> 3000 | K20: =K85 -> 3000 | L20: =L85 -> 3000 | ... P20: =P85 -> 3000 | Q20: - 소노문 해운대 24년 집행액 x 130% 적용(변동가능성 高)
C21: 기 타 경 비 | D21: =SUM(E21:P21) -> 192413.19 | E21: =E95 -> 14221.127 | F21: =F95 -> 11686.576 | G21: =G95 -> 12982.115 | H21: =H95 -> 14255.08 | I21: =I95 -> 16470.053 | J21: =J95 -> 16790.708 | K21: =K95 -> 18779.041 | L21: =L95 -> 20046.649 | ... P21: =P95 -> 15432.516 | Q21: - 지급임차료, 보험료, 교통비, 통신비 등 반영
B22: Ⅲ. 영 업 이 익 | D22: =SUM(E22:P22) -> 7710722.7 | E22: =E7-E9 -> 534732.77 | F22: =F7-F9 -> 373287.96 | G22: =G7-G9 -> 452935.15 | H22: =H7-H9 -> 537147.42 | I22: =I7-I9 -> 678524.09 | J22: =J7-J9 -> 685957.21 | K22: =K7-K9 -> 825545.76 | L22: =L7-L9 -> 906419.61 | ... P22: =P7-P9 -> 533935.68
C23: % | D23: =D22/D$7 -> 0.46779802 | E23: =E22/E$7 -> 0.44155877 | F23: =F22/F$7 -> 0.38067385 | G23: =G22/G$7 -> 0.41236874 | H23: =H22/H$7 -> 0.44242501 | I23: =I22/I$7 -> 0.47936671 | J23: =J22/J$7 -> 0.47936404 | K23: =K22/K$7 -> 0.50791334 | ... P23: =P22/P$7 -> 0.40836335
B24: Ⅳ. 영 업 이 익[+@] | D24: =SUM(E24:P24) -> 7170972.1 | E24: =E22 -> 534732.77 | F24: =F22 -> 373287.96 | G24: =G22 -> 452935.15 | H24: =H22 -> 537147.42 | I24: =I22 -> 678524.09 | J24: =J22 -> 685957.21 | K24: =K22 -> 825545.76 | L24: =L22 -> 906419.61 | ... O24: =O22 -> 643338.85 | P24: =P22-(D22*7%) -> -5814.9076 | Q24: 이익률 49% 기준 Incentive Fee 7% 적용. 12월 +676백
C25: % | D25: =D24/D$7 -> 0.43505216 | E25: =E24/E$7 -> 0.44155877 | F25: =F24/F$7 -> 0.38067385 | G25: =G24/G$7 -> 0.41236874 | H25: =H24/H$7 -> 0.44242501 | I25: =I24/I$7 -> 0.47936671 | J25: =J24/J$7 -> 0.47936404 | K25: =K24/K$7 -> 0.50791334 | ... P25: =P24/P$7 -> -0.0044473431
A27: 2026년 팔라티움 해운대 사업계획
A29: ■ 운영원가 세부
Q30: [단위 : 백만원]
B31: 구분 | D31: 합계 | E31: 2026년 사업계획 | Q31: 비고
E32: 1 | F32: 2 | G32: 3 | H32: 4 | I32: 5 | J32: 6 | K32: 7 | L32: 8 | M32: 9 | N32: 10 | O32: 11 | P32: 12
B33: 급료 | D33: =SUM(E33:P33) -> 784670.76 | E33: ='#)비용'!$E$6/12 -> 65389.23 | F33: ='#)비용'!$E$6/12 -> 65389.23 | G33: ='#)비용'!$E$6/12 -> 65389.23 | H33: ='#)비용'!$E$6/12 -> 65389.23 | I33: ='#)비용'!$E$6/12 -> 65389.23 | J33: ='#)비용'!$E$6/12 -> 65389.23 | K33: ='#)비용'!$E$6/12 -> 65389.23 | L33: ='#)비용'!$E$6/12 -> 65389.23 | ... P33: ='#)비용'!$E$6/12 -> 65389.23 | Q33: #)참고자료 1. 인력계획 참고 (직영 16명 기준)
B34: 임금 | D34: =SUM(E34:P34) -> 0 | E34: ='#)비용'!$E$7/12 -> 0 | F34: ='#)비용'!$E$7/12 -> 0 | G34: ='#)비용'!$E$7/12 -> 0 | H34: ='#)비용'!$E$7/12 -> 0 | I34: ='#)비용'!$E$7/12 -> 0 | J34: ='#)비용'!$E$7/12 -> 0 | K34: ='#)비용'!$E$7/12 -> 0 | L34: ='#)비용'!$E$7/12 -> 0 | ... P34: ='#)비용'!$E$7/12 -> 0 | Q34: 미반영
B35: 상여금 | D35: =SUM(E35:P35) -> 65389.23 | P35: ='#)비용'!$E$8 -> 65389.23 | Q35: 12월 성과급 월급여 100% 지급 가정
B36: 제수당 | D36: =SUM(E36:P36) -> 0 | E36: ='#)비용'!$E$9/12 -> 0 | F36: ='#)비용'!$E$9/12 -> 0 | G36: ='#)비용'!$E$9/12 -> 0 | H36: ='#)비용'!$E$9/12 -> 0 | I36: ='#)비용'!$E$9/12 -> 0 | J36: ='#)비용'!$E$9/12 -> 0 | K36: ='#)비용'!$E$9/12 -> 0 | L36: ='#)비용'!$E$9/12 -> 0 | ... P36: ='#)비용'!$E$9/12 -> 0 | Q36: 미반영(급료 단가포함)
B37: 퇴직급여 | D37: =SUM(E37:P37) -> 78467.076 | E37: ='#)비용'!$E$10/12 -> 6538.923 | F37: ='#)비용'!$E$10/12 -> 6538.923 | G37: ='#)비용'!$E$10/12 -> 6538.923 | H37: ='#)비용'!$E$10/12 -> 6538.923 | I37: ='#)비용'!$E$10/12 -> 6538.923 | J37: ='#)비용'!$E$10/12 -> 6538.923 | K37: ='#)비용'!$E$10/12 -> 6538.923 | L37: ='#)비용'!$E$10/12 -> 6538.923 | ... P37: ='#)비용'!$E$10/12 -> 6538.923 | Q37: 급여 10% 충당금 설정
B38: 인건비소계 | D38: =SUM(E38:P38) -> 928527.07 | E38: =SUM(E33:E37) -> 71928.153 | F38: =SUM(F33:F37) -> 71928.153 | G38: =SUM(G33:G37) -> 71928.153 | H38: =SUM(H33:H37) -> 71928.153 | I38: =SUM(I33:I37) -> 71928.153 | J38: =SUM(J33:J37) -> 71928.153 | K38: =SUM(K33:K37) -> 71928.153 | L38: =SUM(L33:L37) -> 71928.153 | ... P38: =SUM(P33:P37) -> 137317.38
B39: 재료비소계 | D39: =SUM(E39:P39) -> 0 | Q39: 미반영
B40: 고정도급비 | D40: =SUM(E40:P40) -> 651849.38 | E40: ='#)비용'!$E$13/12 -> 54320.781 | F40: ='#)비용'!$E$13/12 -> 54320.781 | G40: ='#)비용'!$E$13/12 -> 54320.781 | H40: ='#)비용'!$E$13/12 -> 54320.781 | I40: ='#)비용'!$E$13/12 -> 54320.781 | J40: ='#)비용'!$E$13/12 -> 54320.781 | K40: ='#)비용'!$E$13/12 -> 54320.781 | L40: ='#)비용'!$E$13/12 -> 54320.781 | ... P40: ='#)비용'!$E$13/12 -> 54320.781 | Q40: 객실부문 17명 기준 반영
B41: 추가도급비 | D41: =SUM(E41:P41) -> 0 | Q41: 미반영
B42: 시설관리비 | D42: =SUM(E42:P42) -> 82415.085 | E42: =E7*0.5% -> 6055.0578 | F42: =F7*0.5% -> 4902.9893 | G42: =G7*0.5% -> 5491.8705 | H42: =H7*0.5% -> 6070.4911 | I42: =I7*0.5% -> 7077.2967 | J42: =J7*0.5% -> 7154.8673 | K42: =K7*0.5% -> 8126.8368 | L42: =L7*0.5% -> 8703.022 | ... P42: =P7*0.5% -> 6537.5074 | Q42: 총매출 x 0.5% (소노인터내셔널 전사업장 1~8월 누계 0.5%)
B43: 객실정비료 | D43: =SUM(E43:P43) -> 1276728.4 | E43: ='#)비용'!$E$16/12 -> 106394.03 | F43: ='#)비용'!$E$16/12 -> 106394.03 | G43: ='#)비용'!$E$16/12 -> 106394.03 | H43: ='#)비용'!$E$16/12 -> 106394.03 | I43: ='#)비용'!$E$16/12 -> 106394.03 | J43: ='#)비용'!$E$16/12 -> 106394.03 | K43: ='#)비용'!$E$16/12 -> 106394.03 | L43: ='#)비용'!$E$16/12 -> 106394.03 | ... P43: ='#)비용'!$E$16/12 -> 106394.03 | Q43: 판매객실수(55,510실) x 실당 정비단가(23천원) 반영
...

Sheet 1)총비용
A3: ■ 총괄
P4: [단위 : 백만원]
B5: 구분 | D5: 합계 | E5: 객실 | H5: 식음 | K5: 부대 | N5: 임대 | P5: 비고
E6: 팔라티움 | F6: 도급-객실 | G6: 계 | H6: 루프탑바 | I6: 예비 | J6: 계 | K6: 인피니티풀 | L6: 예비 | M6: 계 | N6: 입주업체 | O6: 계
B7: Ⅰ. 매 출 액 | D7: =SUM(G7,J7,M7,O7) -> 16858639 | E7: ='2)팀공통비'!E7 -> 16483017 | F7: ='2)팀공통비'!F7 -> 0 | G7: =SUM(E7:F7) -> 16483017 | H7: ='2)팀공통비'!H7 -> 73941.84 | I7: ='2)팀공통비'!I7 -> 0 | J7: =SUM(H7:I7) -> 73941.84 | K7: ='2)팀공통비'!K7 -> 0 | L7: ='2)팀공통비'!L7 -> 0 | M7: =SUM(K7:L7) -> 0 | N7: ='2)팀공통비'!N7 -> 301680 | O7: =SUM(N7) -> 301680
B8: Ⅱ. 운 영 원 가 | D8: =SUM(G8,J8,M8,O8) -> 0 | E8: =SUM(E9:E20) -> 0 | F8: =SUM(F9:F20) -> 0 | G8: =SUM(E8:F8) -> 0 | H8: =SUM(H9:H20) -> 0 | I8: =SUM(I9:I20) -> 0 | J8: =SUM(H8:I8) -> 0 | K8: =SUM(K9:K20) -> 0 | L8: =SUM(L9:L20) -> 0 | M8: =SUM(K8:L8) -> 0 | N8: =SUM(N9:N20) -> 0 | O8: =SUM(N8) -> 0
C9: 인 건 비 | D9: =SUM(G9,J9,M9,O9) -> 0 | E9: =E35 -> 0 | F9: =F35 -> 0 | G9: =SUM(E9:F9) -> 0 | H9: =H35 -> 0 | I9: =I35 -> 0 | J9: =SUM(H9:I9) -> 0 | K9: =K35 -> 0 | L9: =L35 -> 0 | M9: =SUM(K9:L9) -> 0 | N9: =N35 -> 0 | O9: =SUM(N9) -> 0
C10: 재 료 비 | D10: =SUM(G10,J10,M10,O10) -> 0 | E10: =E36 -> 0 | F10: =F36 -> 0 | G10: =SUM(E10:F10) -> 0 | H10: =H36 -> 0 | I10: =I36 -> 0 | J10: =SUM(H10:I10) -> 0 | K10: =K36 -> 0 | L10: =L36 -> 0 | M10: =SUM(K10:L10) -> 0 | N10: =N36 -> 0 | O10: =SUM(N10) -> 0
C11: 용 역 비 | D11: =SUM(G11,J11,M11,O11) -> 0 | E11: =E41 -> 0 | F11: =F41 -> 0 | G11: =SUM(E11:F11) -> 0 | H11: =H41 -> 0 | I11: =I41 -> 0 | J11: =SUM(H11:I11) -> 0 | K11: =K41 -> 0 | L11: =L41 -> 0 | M11: =SUM(K11:L11) -> 0 | N11: =N41 -> 0 | O11: =SUM(N11) -> 0
C12: 복리후생비 | D12: =SUM(G12,J12,M12,O12) -> 0 | E12: =E52 -> 0 | F12: =F52 -> 0 | G12: =SUM(E12:F12) -> 0 | H12: =H52 -> 0 | I12: =I52 -> 0 | J12: =SUM(H12:I12) -> 0 | K12: =K52 -> 0 | L12: =L52 -> 0 | M12: =SUM(K12:L12) -> 0 | N12: =N52 -> 0 | O12: =SUM(N12) -> 0
C13: 수도광열비 | D13: =SUM(G13,J13,M13,O13) -> 0 | E13: =E58 -> 0 | F13: =F58 -> 0 | G13: =SUM(E13:F13) -> 0 | H13: =H58 -> 0 | I13: =I58 -> 0 | J13: =SUM(H13:I13) -> 0 | K13: =K58 -> 0 | L13: =L58 -> 0 | M13: =SUM(K13:L13) -> 0 | N13: =N58 -> 0 | O13: =SUM(N13) -> 0
C14: 소 모 품 비 | D14: =SUM(G14,J14,M14,O14) -> 0 | E14: =E59 -> 0 | F14: =F59 -> 0 | G14: =SUM(E14:F14) -> 0 | H14: =H59 -> 0 | I14: =I59 -> 0 | J14: =SUM(H14:I14) -> 0 | K14: =K59 -> 0 | L14: =L59 -> 0 | M14: =SUM(K14:L14) -> 0 | N14: =N59 | O14: =SUM(N14) -> 0
C15: 지급수수료 | D15: =SUM(G15,J15,M15,O15) -> 0 | E15: =E64 -> 0 | F15: =F64 -> 0 | G15: =SUM(E15:F15) -> 0 | H15: =H64 -> 0 | I15: =I64 -> 0 | J15: =SUM(H15:I15) -> 0 | K15: =K64 -> 0 | L15: =L64 -> 0 | M15: =SUM(K15:L15) -> 0 | N15: =N64 -> 0 | O15: =SUM(N15) -> 0
C16: 수 선 비 | D16: =SUM(G16,J16,M16,O16) -> 0 | E16: =E65 -> 0 | F16: =F65 -> 0 | G16: =SUM(E16:F16) -> 0 | H16: =H65 -> 0 | I16: =I65 -> 0 | J16: =SUM(H16:I16) -> 0 | K16: =K65 -> 0 | L16: =L65 -> 0 | M16: =SUM(K16:L16) -> 0 | N16: =N65 | O16: =SUM(N16) -> 0
C17: 광고선전비 | D17: =SUM(G17,J17,M17,O17) -> 0 | E17: =E70 -> 0 | F17: =F70 -> 0 | G17: =SUM(E17:F17) -> 0 | H17: =H70 -> 0 | I17: =I70 -> 0 | J17: =SUM(H17:I17) -> 0 | K17: =K70 -> 0 | L17: =L70 -> 0 | M17: =SUM(K17:L17) -> 0 | N17: =N70 -> 0 | O17: =SUM(N17) -> 0
C18: 세금과공과 | D18: =SUM(G18,J18,M18,O18) -> 0 | E18: =E79 -> 0 | F18: =F79 -> 0 | G18: =SUM(E18:F18) -> 0 | H18: =H79 -> 0 | I18: =I79 -> 0 | J18: =SUM(H18:I18) -> 0 | K18: =K79 -> 0 | L18: =L79 -> 0 | M18: =SUM(K18:L18) -> 0 | N18: =N79 -> 0 | O18: =SUM(N18) -> 0
C19: 감가상각비 | D19: =SUM(G19,J19,M19,O19) -> 0 | E19: =E82 -> 0 | F19: =F82 -> 0 | G19: =SUM(E19:F19) -> 0 | H19: =H82 -> 0 | I19: =I82 -> 0 | J19: =SUM(H19:I19) -> 0 | K19: =K82 -> 0 | L19: =L82 -> 0 | M19: =SUM(K19:L19) -> 0 | N19: =N82 -> 0 | O19: =SUM(N19) -> 0
C20: 기 타 경 비 | D20: =SUM(G20,J20,M20,O20) -> 0 | E20: =E92 -> 0 | F20: =F92 -> 0 | G20: =SUM(E20:F20) -> 0 | H20: =H92 -> 0 | I20: =I92 -> 0 | J20: =SUM(H20:I20) -> 0 | K20: =K92 -> 0 | L20: =L92 -> 0 | M20: =SUM(K20:L20) -> 0 | N20: =N92 -> 0 | O20: =SUM(N20) -> 0
B21: Ⅲ. 매출총이익 | D21: =SUM(G21,J21,M21,O21) -> 16858639 | E21: =E7-E8 -> 16483017 | F21: =F7-F8 -> 0 | G21: =SUM(E21:F21) -> 16483017 | H21: =H7-H8 -> 73941.84 | I21: =I7-I8 -> 0 | J21: =SUM(H21:I21) -> 73941.84 | K21: =K7-K8 -> 0 | L21: =L7-L8 -> 0 | M21: =SUM(K21:L21) -> 0 | N21: =N7-N8 -> 301680 | O21: =SUM(N21) -> 301680
B22: Ⅳ. E B I T D A | D22: =SUM(G22,J22,M22,O22) -> 16858639 | E22: =E21+E19 -> 16483017 | F22: =F21+F19 -> 0 | G22: =SUM(E22:F22) -> 16483017 | H22: =H21+H19 -> 73941.84 | I22: =I21+I19 -> 0 | J22: =SUM(H22:I22) -> 73941.84 | K22: =K21+K19 -> 0 | L22: =L21+L19 -> 0 | M22: =SUM(K22:L22) -> 0 | N22: =N21+N19 -> 301680 | O22: =SUM(N22) -> 301680
A26: ■ 계정세부 | Q26: ■ 공통비 배부
B28: 구분 | D28: 합계 | E28: 객실 | H28: 식음 | K28: 부대 | N28: 임대 | P28: 비고 | R28: 구분 | T28: 합 계 | U28: 지원 | V28: 예약 | W28: 영업기획 | X28: 도급-공통 | Y28: 배부기준
E29: 팔라티움 | F29: 도급-객실 | G29: 계 | H29: 루프탑바 | I29: 예비 | J29: 계 | K29: 인피니티풀 | L29: 예비 | M29: 계 | N29: 입주업체 | O29: 계
B30: 급료 | D30: =SUM(G30,J30,M30,O30) -> 0 | E30: =IFERROR('2)팀공통비'!E30+$T30*E$102,"") -> 0 | F30: =IFERROR('2)팀공통비'!F30+$T30*F$102,"") -> 0 | G30: =SUM(E30:F30) -> 0 | H30: =IFERROR('2)팀공통비'!H30+$T30*H$102,"") -> 0 | I30: =IFERROR('2)팀공통비'!I30+$T30*I$102,"") -> 0 | J30: =SUM(H30:I30) -> 0 | K30: =IFERROR('2)팀공통비'!K30+$T30*K$102,"") -> 0 | L30: =IFERROR('2)팀공통비'!L30+$T30*L$102,"") -> 0 | M30: =SUM(K30:L30) -> 0 | N30: =IFERROR('2)팀공통비'!N30+$T30*N$102,"") | O30: =SUM(N30) -> 0 | R30: 급료 | T30: =SUM(U30:X30) -> 0 | Y30: 매출액
B31: 임금 | D31: =SUM(G31,J31,M31,O31) -> 0 | E31: =IFERROR('2)팀공통비'!E31+$T31*E$102,"") -> 0 | F31: =IFERROR('2)팀공통비'!F31+$T31*F$102,"") -> 0 | G31: =SUM(E31:F31) -> 0 | H31: =IFERROR('2)팀공통비'!H31+$T31*H$102,"") -> 0 | I31: =IFERROR('2)팀공통비'!I31+$T31*I$102,"") -> 0 | J31: =SUM(H31:I31) -> 0 | K31: =IFERROR('2)팀공통비'!K31+$T31*K$102,"") -> 0 | L31: =IFERROR('2)팀공통비'!L31+$T31*L$102,"") -> 0 | M31: =SUM(K31:L31) -> 0 | N31: =IFERROR('2)팀공통비'!N31+$T31*N$102,"") | O31: =SUM(N31) -> 0 | R31: 임금 | T31: =SUM(U31:X31) -> 0 | Y31: 매출액
B32: 상여금 | D32: =SUM(G32,J32,M32,O32) -> 0 | E32: =IFERROR('2)팀공통비'!E32+$T32*E$102,"") -> 0 | F32: =IFERROR('2)팀공통비'!F32+$T32*F$102,"") -> 0 | G32: =SUM(E32:F32) -> 0 | H32: =IFERROR('2)팀공통비'!H32+$T32*H$102,"") -> 0 | I32: =IFERROR('2)팀공통비'!I32+$T32*I$102,"") -> 0 | J32: =SUM(H32:I32) -> 0 | K32: =IFERROR('2)팀공통비'!K32+$T32*K$102,"") -> 0 | L32: =IFERROR('2)팀공통비'!L32+$T32*L$102,"") -> 0 | M32: =SUM(K32:L32) -> 0 | N32: =IFERROR('2)팀공통비'!N32+$T32*N$102,"") | O32: =SUM(N32) -> 0 | R32: 상여금 | T32: =SUM(U32:X32) -> 0 | Y32: 매출액
B33: 제수당 | D33: =SUM(G33,J33,M33,O33) -> 0 | E33: =IFERROR('2)팀공통비'!E33+$T33*E$102,"") -> 0 | F33: =IFERROR('2)팀공통비'!F33+$T33*F$102,"") -> 0 | G33: =SUM(E33:F33) -> 0 | H33: =IFERROR('2)팀공통비'!H33+$T33*H$102,"") -> 0 | I33: =IFERROR('2)팀공통비'!I33+$T33*I$102,"") -> 0 | J33: =SUM(H33:I33) -> 0 | K33: =IFERROR('2)팀공통비'!K33+$T33*K$102,"") -> 0 | L33: =IFERROR('2)팀공통비'!L33+$T33*L$102,"") -> 0 | M33: =SUM(K33:L33) -> 0 | N33: =IFERROR('2)팀공통비'!N33+$T33*N$102,"") | O33: =SUM(N33) -> 0 | R33: 제수당 | T33: =SUM(U33:X33) -> 0 | Y33: 매출액
B34: 퇴직급여 | D34: =SUM(G34,J34,M34,O34) -> 0 | E34: =IFERROR('2)팀공통비'!E34+$T34*E$102,"") -> 0 | F34: =IFERROR('2)팀공통비'!F34+$T34*F$102,"") -> 0 | G34: =SUM(E34:F34) -> 0 | H34: =IFERROR('2)팀공통비'!H34+$T34*H$102,"") -> 0 | I34: =IFERROR('2)팀공통비'!I34+$T34*I$102,"") -> 0 | J34: =SUM(H34:I34) -> 0 | K34: =IFERROR('2)팀공통비'!K34+$T34*K$102,"") -> 0 | L34: =IFERROR('2)팀공통비'!L34+$T34*L$102,"") -> 0 | M34: =SUM(K34:L34) -> 0 | N34: =IFERROR('2)팀공통비'!N34+$T34*N$102,"") | O34: =SUM(N34) -> 0 | R34: 퇴직급여 | T34: =SUM(U34:X34) -> 0 | Y34: 매출액
B35: 인건비소계 | D35: =SUM(G35,J35,M35,O35) -> 0 | E35: =SUM(E30:E34) -> 0 | F35: =SUM(F30:F34) -> 0 | G35: =SUM(E35:F35) -> 0 | H35: =SUM(H30:H34) -> 0 | I35: =SUM(I30:I34) -> 0 | J35: =SUM(H35:I35) -> 0 | K35: =SUM(K30:K34) -> 0 | L35: =SUM(L30:L34) -> 0 | M35: =SUM(K35:L35) -> 0 | N35: =SUM(N30:N34) -> 0 | O35: =SUM(N35) -> 0 | R35: 인건비소계 | T35: =SUM(T30:T34) -> 0 | U35: =SUM(U30:U34) -> 0 | V35: =SUM(V30:V34) -> 0 | W35: =SUM(W30:W34) -> 0 | X35: =SUM(X30:X34) -> 0
B36: 재료비소계 | D36: =SUM(G36,J36,M36,O36) -> 0 | E36: =IFERROR('2)팀공통비'!E36,"") -> 0 | F36: =IFERROR('2)팀공통비'!F36,"") -> 0 | G36: =SUM(E36:F36) -> 0 | H36: =IFERROR('2)팀공통비'!H36,"") -> 0 | I36: =IFERROR('2)팀공통비'!I36,"") -> 0 | J36: =SUM(H36:I36) -> 0 | K36: =IFERROR('2)팀공통비'!K36,"") -> 0 | L36: =IFERROR('2)팀공통비'!L36,"") -> 0 | M36: =SUM(K36:L36) -> 0 | N36: =IFERROR('2)팀공통비'!N36,"") -> 0 | O36: =SUM(N36) -> 0 | R36: 재료비소계 | T36: =SUM(U36:X36) -> 0 | Y36: 재료비
B37: 고정도급비 | D37: =SUM(G37,J37,M37,O37) -> 0 | E37: =IFERROR('2)팀공통비'!E37+$T37*E$102,"") -> 0 | F37: =IFERROR('2)팀공통비'!F37+$T37*F$102,"") -> 0 | G37: =SUM(E37:F37) -> 0 | H37: =IFERROR('2)팀공통비'!H37+$T37*H$102,"") -> 0 | I37: =IFERROR('2)팀공통비'!I37+$T37*I$102,"") -> 0 | J37: =SUM(H37:I37) -> 0 | K37: =IFERROR('2)팀공통비'!K37+$T37*K$102,"") -> 0 | L37: =IFERROR('2)팀공통비'!L37+$T37*L$102,"") -> 0 | M37: =SUM(K37:L37) -> 0 | N37: =IFERROR('2)팀공통비'!N37+$T37*N$102,"") | O37: =SUM(N37) -> 0 | R37: 고정도급비 | T37: =SUM(U37:X37) -> 0 | Y37: 매출액
B38: 추가도급비 | D38: =SUM(G38,J38,M38,O38) -> 0 | E38: =IFERROR('2)팀공통비'!E38+$T38*E$102,"") -> 0 | F38: =IFERROR('2)팀공통비'!F38+$T38*F$102,"") -> 0 | G38: =SUM(E38:F38) -> 0 | H38: =IFERROR('2)팀공통비'!H38+$T38*H$102,"") -> 0 | I38: =IFERROR('2)팀공통비'!I38+$T38*I$102,"") -> 0 | J38: =SUM(H38:I38) -> 0 | K38: =IFERROR('2)팀공통비'!K38+$T38*K$102,"") -> 0 | L38: =IFERROR('2)팀공통비'!L38+$T38*L$102,"") -> 0 | M38: =SUM(K38:L38) -> 0 | N38: =IFERROR('2)팀공통비'!N38+$T38*N$102,"") | O38: =SUM(N38) -> 0 | R38: 추가도급비 | T38: =SUM(U38:X38) -> 0 | Y38: 매출액
B39: 시설관리비 | D39: =SUM(G39,J39,M39,O39) -> 0 | E39: =IFERROR('2)팀공통비'!E39+$T39*E$102,"") -> 0 | F39: =IFERROR('2)팀공통비'!F39+$T39*F$102,"") -> 0 | G39: =SUM(E39:F39) -> 0 | H39: =IFERROR('2)팀공통비'!H39+$T39*H$102,"") -> 0 | I39: =IFERROR('2)팀공통비'!I39+$T39*I$102,"") -> 0 | J39: =SUM(H39:I39) -> 0 | K39: =IFERROR('2)팀공통비'!K39+$T39*K$102,"") -> 0 | L39: =IFERROR('2)팀공통비'!L39+$T39*L$102,"") -> 0 | M39: =SUM(K39:L39) -> 0 | N39: =IFERROR('2)팀공통비'!N39+$T39*N$102,"") | O39: =SUM(N39) -> 0 | R39: 시설관리비 | T39: =SUM(U39:X39) -> 0 | Y39: 매출액
B40: 객실정비료 | D40: =SUM(G40,J40,M40,O40) -> 0 | E40: =IFERROR('2)팀공통비'!E40+$T40*E$102,"") -> 0 | F40: =IFERROR('2)팀공통비'!F40+$T40*F$102,"") -> 0 | G40: =SUM(E40:F40) -> 0 | H40: =IFERROR('2)팀공통비'!H40+$T40*H$102,"") -> 0 | I40: =IFERROR('2)팀공통비'!I40+$T40*I$102,"") -> 0 | J40: =SUM(H40:I40) -> 0 | K40: =IFERROR('2)팀공통비'!K40+$T40*K$102,"") -> 0 | L40: =IFERROR('2)팀공통비'!L40+$T40*L$102,"") -> 0 | M40: =SUM(K40:L40) -> 0 | N40: =IFERROR('2)팀공통비'!N40+$T40*N$102,"") | O40: =SUM(N40) -> 0 | R40: 객실정비료 | T40: =SUM(U40:X40) -> 0 | Y40: 매출액
B41: 용역비소계 | D41: =SUM(G41,J41,M41,O41) -> 0 | E41: =SUM(E37:E40) -> 0 | F41: =SUM(F37:F40) -> 0 | G41: =SUM(E41:F41) -> 0 | H41: =SUM(H37:H40) -> 0 | I41: =SUM(I37:I40) -> 0 | J41: =SUM(H41:I41) -> 0 | K41: =SUM(K37:K40) -> 0 | L41: =SUM(L37:L40) -> 0 | M41: =SUM(K41:L41) -> 0 | N41: =SUM(N37:N40) -> 0 | O41: =SUM(N41) -> 0 | R41: 용역비소계 | T41: =SUM(T37:T40) -> 0 | U41: =SUM(U37:U40) -> 0 | V41: =SUM(V37:V40) -> 0 | W41: =SUM(W37:W40) -> 0 | X41: =SUM(X37:X40) -> 0
B42: 직원급식대 | D42: =SUM(G42,J42,M42,O42) -> 0 | E42: =IFERROR('2)팀공통비'!E42+$T42*E$104,"") -> 0 | F42: =IFERROR('2)팀공통비'!F42+$T42*F$104,"") -> 0 | G42: =SUM(E42:F42) -> 0 | H42: =IFERROR('2)팀공통비'!H42+$T42*H$104,"") -> 0 | I42: =IFERROR('2)팀공통비'!I42+$T42*I$104,"") -> 0 | J42: =SUM(H42:I42) -> 0 | K42: =IFERROR('2)팀공통비'!K42+$T42*K$104,"") -> 0 | L42: =IFERROR('2)팀공통비'!L42+$T42*L$104,"") -> 0 | M42: =SUM(K42:L42) -> 0 | N42: =IFERROR('2)팀공통비'!N42+$T42*N$104,"") | O42: =SUM(N42) -> 0 | R42: 직원급식대 | T42: =SUM(U42:X42) -> 0 | Y42: 인원수
B43: 직원경조비 | D43: =SUM(G43,J43,M43,O43) -> 0 | E43: =IFERROR('2)팀공통비'!E43+$T43*E$102,"") -> 0 | F43: =IFERROR('2)팀공통비'!F43+$T43*F$102,"") -> 0 | G43: =SUM(E43:F43) -> 0 | H43: =IFERROR('2)팀공통비'!H43+$T43*H$102,"") -> 0 | I43: =IFERROR('2)팀공통비'!I43+$T43*I$102,"") -> 0 | J43: =SUM(H43:I43) -> 0 | K43: =IFERROR('2)팀공통비'!K43+$T43*K$102,"") -> 0 | L43: =IFERROR('2)팀공통비'!L43+$T43*L$102,"") -> 0 | M43: =SUM(K43:L43) -> 0 | N43: =IFERROR('2)팀공통비'!N43+$T43*N$102,"") | O43: =SUM(N43) -> 0 | R43: 직원경조비 | T43: =SUM(U43:X43) -> 0 | Y43: 매출액
B44: 의료비 | D44: =SUM(G44,J44,M44,O44) -> 0 | E44: =IFERROR('2)팀공통비'!E44+$T44*E$102,"") -> 0 | F44: =IFERROR('2)팀공통비'!F44+$T44*F$102,"") -> 0 | G44: =SUM(E44:F44) -> 0 | H44: =IFERROR('2)팀공통비'!H44+$T44*H$102,"") -> 0 | I44: =IFERROR('2)팀공통비'!I44+$T44*I$102,"") -> 0 | J44: =SUM(H44:I44) -> 0 | K44: =IFERROR('2)팀공통비'!K44+$T44*K$102,"") -> 0 | L44: =IFERROR('2)팀공통비'!L44+$T44*L$102,"") -> 0 | M44: =SUM(K44:L44) -> 0 | N44: =IFERROR('2)팀공통비'!N44+$T44*N$102,"") | O44: =SUM(N44) -> 0 | R44: 의료비 | T44: =SUM(U44:X44) -> 0 | Y44: 매출액
B45: 세탁비 | D45: =SUM(G45,J45,M45,O45) -> 0 | E45: =IFERROR('2)팀공통비'!E45+$T45*E$102,"") -> 0 | F45: =IFERROR('2)팀공통비'!F45+$T45*F$102,"") -> 0 | G45: =SUM(E45:F45) -> 0 | H45: =IFERROR('2)팀공통비'!H45+$T45*H$102,"") -> 0 | I45: =IFERROR('2)팀공통비'!I45+$T45*I$102,"") -> 0 | J45: =SUM(H45:I45) -> 0 | K45: =IFERROR('2)팀공통비'!K45+$T45*K$102,"") -> 0 | L45: =IFERROR('2)팀공통비'!L45+$T45*L$102,"") -> 0 | M45: =SUM(K45:L45) -> 0 | N45: =IFERROR('2)팀공통비'!N45+$T45*N$102,"") | O45: =SUM(N45) -> 0 | R45: 세탁비 | T45: =SUM(U45:X45) -> 0 | Y45: 매출액
B46: 피복비 | D46: =SUM(G46,J46,M46,O46) -> 0 | E46: =IFERROR('2)팀공통비'!E46+$T46*E$102,"") -> 0 | F46: =IFERROR('2)팀공통비'!F46+$T46*F$102,"") -> 0 | G46: =SUM(E46:F46) -> 0 | H46: =IFERROR('2)팀공통비'!H46+$T46*H$102,"") -> 0 | I46: =IFERROR('2)팀공통비'!I46+$T46*I$102,"") -> 0 | J46: =SUM(H46:I46) -> 0 | K46: =IFERROR('2)팀공통비'!K46+$T46*K$102,"") -> 0 | L46: =IFERROR('2)팀공통비'!L46+$T46*L$102,"") -> 0 | M46: =SUM(K46:L46) -> 0 | N46: =IFERROR('2)팀공통비'!N46+$T46*N$102,"") | O46: =SUM(N46) -> 0 | R46: 피복비 | T46: =SUM(U46:X46) -> 0 | Y46: 매출액
...

Sheet 2)팀공통비
A3: ■ 총괄
P4: [단위 : 백만원]
B5: 구분 | D5: 합계 | E5: 객실 | H5: 식음 | K5: 부대 | N5: 임대 | P5: 비고
E6: 팔라티움 | F6: 도급-객실 | G6: 계 | H6: 루프탑바 | I6: 예비 | J6: 계 | K6: 인피니티풀 | L6: 예비 | M6: 계 | N6: 입주업체 | O6: 계
B7: Ⅰ. 매 출 액 | D7: =SUM(G7,J7,M7,O7) -> 16858639 | E7: ='3)직접비'!E7 -> 16483017 | F7: ='3)직접비'!F7 -> 0 | G7: =SUM(E7:F7) -> 16483017 | H7: ='3)직접비'!H7 -> 73941.84 | I7: ='3)직접비'!I7 -> 0 | J7: =SUM(H7:I7) -> 73941.84 | K7: ='3)직접비'!K7 -> 0 | L7: ='3)직접비'!L7 -> 0 | M7: =SUM(K7:L7) -> 0 | N7: ='3)직접비'!N7 -> 301680 | O7: =SUM(N7) -> 301680
B8: Ⅱ. 운 영 원 가 | D8: =SUM(G8,J8,M8,O8) -> 0 | E8: =SUM(E9:E20) -> 0 | F8: =SUM(F9:F20) -> 0 | G8: =SUM(E8:F8) -> 0 | H8: =SUM(H9:H20) -> 0 | I8: =SUM(I9:I20) -> 0 | J8: =SUM(H8:I8) -> 0 | K8: =SUM(K9:K20) -> 0 | L8: =SUM(L9:L20) -> 0 | M8: =SUM(K8:L8) -> 0 | N8: =SUM(N9:N20) -> 0 | O8: =SUM(N8) -> 0
C9: 인 건 비 | D9: =SUM(G9,J9,M9,O9) -> 0 | E9: =E35 -> 0 | F9: =F35 -> 0 | G9: =SUM(E9:F9) -> 0 | H9: =H35 -> 0 | I9: =I35 -> 0 | J9: =SUM(H9:I9) -> 0 | K9: =K35 -> 0 | L9: =L35 -> 0 | M9: =SUM(K9:L9) -> 0 | N9: =N35 -> 0 | O9: =SUM(N9) -> 0
C10: 재 료 비 | D10: =SUM(G10,J10,M10,O10) -> 0 | E10: =E36 -> 0 | F10: =F36 -> 0 | G10: =SUM(E10:F10) -> 0 | H10: =H36 -> 0 | I10: =I36 -> 0 | J10: =SUM(H10:I10) -> 0 | K10: =K36 -> 0 | L10: =L36 -> 0 | M10: =SUM(K10:L10) -> 0 | N10: =N36 -> 0 | O10: =SUM(N10) -> 0
C11: 용 역 비 | D11: =SUM(G11,J11,M11,O11) -> 0 | E11: =E41 -> 0 | F11: =F41 -> 0 | G11: =SUM(E11:F11) -> 0 | H11: =H41 -> 0 | I11: =I41 -> 0 | J11: =SUM(H11:I11) -> 0 | K11: =K41 -> 0 | L11: =L41 -> 0 | M11: =SUM(K11:L11) -> 0 | N11: =N41 -> 0 | O11: =SUM(N11) -> 0
C12: 복리후생비 | D12: =SUM(G12,J12,M12,O12) -> 0 | E12: =E52 -> 0 | F12: =F52 -> 0 | G12: =SUM(E12:F12) -> 0 | H12: =H52 -> 0 | I12: =I52 -> 0 | J12: =SUM(H12:I12) -> 0 | K12: =K52 -> 0 | L12: =L52 -> 0 | M12: =SUM(K12:L12) -> 0 | N12: =N52 -> 0 | O12: =SUM(N12) -> 0
C13: 수도광열비 | D13: =SUM(G13,J13,M13,O13) -> 0 | E13: =E58 -> 0 | F13: =F58 -> 0 | G13: =SUM(E13:F13) -> 0 | H13: =H58 -> 0 | I13: =I58 -> 0 | J13: =SUM(H13:I13) -> 0 | K13: =K58 -> 0 | L13: =L58 -> 0 | M13: =SUM(K13:L13) -> 0 | N13: =N58 -> 0 | O13: =SUM(N13) -> 0
C14: 소 모 품 비 | D14: =SUM(G14,J14,M14,O14) -> 0 | E14: =E59 -> 0 | F14: =F59 -> 0 | G14: =SUM(E14:F14) -> 0 | H14: =H59 -> 0 | I14: =I59 -> 0 | J14: =SUM(H14:I14) -> 0 | K14: =K59 -> 0 | L14: =L59 -> 0 | M14: =SUM(K14:L14) -> 0 | N14: =N59 | O14: =SUM(N14) -> 0
C15: 지급수수료 | D15: =SUM(G15,J15,M15,O15) -> 0 | E15: =E64 -> 0 | F15: =F64 -> 0 | G15: =SUM(E15:F15) -> 0 | H15: =H64 -> 0 | I15: =I64 -> 0 | J15: =SUM(H15:I15) -> 0 | K15: =K64 -> 0 | L15: =L64 -> 0 | M15: =SUM(K15:L15) -> 0 | N15: =N64 -> 0 | O15: =SUM(N15) -> 0
C16: 수 선 비 | D16: =SUM(G16,J16,M16,O16) -> 0 | E16: =E65 -> 0 | F16: =F65 -> 0 | G16: =SUM(E16:F16) -> 0 | H16: =H65 -> 0 | I16: =I65 -> 0 | J16: =SUM(H16:I16) -> 0 | K16: =K65 -> 0 | L16: =L65 -> 0 | M16: =SUM(K16:L16) -> 0 | N16: =N65 | O16: =SUM(N16) -> 0
C17: 광고선전비 | D17: =SUM(G17,J17,M17,O17) -> 0 | E17: =E70 -> 0 | F17: =F70 -> 0 | G17: =SUM(E17:F17) -> 0 | H17: =H70 -> 0 | I17: =I70 -> 0 | J17: =SUM(H17:I17) -> 0 | K17: =K70 -> 0 | L17: =L70 -> 0 | M17: =SUM(K17:L17) -> 0 | N17: =N70 -> 0 | O17: =SUM(N17) -> 0
C18: 세금과공과 | D18: =SUM(G18,J18,M18,O18) -> 0 | E18: =E79 -> 0 | F18: =F79 -> 0 | G18: =SUM(E18:F18) -> 0 | H18: =H79 -> 0 | I18: =I79 -> 0 | J18: =SUM(H18:I18) -> 0 | K18: =K79 -> 0 | L18: =L79 -> 0 | M18: =SUM(K18:L18) -> 0 | N18: =N79 -> 0 | O18: =SUM(N18) -> 0
C19: 감가상각비 | D19: =SUM(G19,J19,M19,O19) -> 0 | E19: =E82 -> 0 | F19: =F82 -> 0 | G19: =SUM(E19:F19) -> 0 | H19: =H82 -> 0 | I19: =I82 -> 0 | J19: =SUM(H19:I19) -> 0 | K19: =K82 -> 0 | L19: =L82 -> 0 | M19: =SUM(K19:L19) -> 0 | N19: =N82 -> 0 | O19: =SUM(N19) -> 0
C20: 기 타 경 비 | D20: =SUM(G20,J20,M20,O20) -> 0 | E20: =E92 -> 0 | F20: =F92 -> 0 | G20: =SUM(E20:F20) -> 0 | H20: =H92 -> 0 | I20: =I92 -> 0 | J20: =SUM(H20:I20) -> 0 | K20: =K92 -> 0 | L20: =L92 -> 0 | M20: =SUM(K20:L20) -> 0 | N20: =N92 -> 0 | O20: =SUM(N20) -> 0
B21: Ⅲ. 매출총이익 | D21: =SUM(G21,J21,M21,O21) -> 16858639 | E21: =E7-E8 -> 16483017 | F21: =F7-F8 -> 0 | G21: =SUM(E21:F21) -> 16483017 | H21: =H7-H8 -> 73941.84 | I21: =I7-I8 -> 0 | J21: =SUM(H21:I21) -> 73941.84 | K21: =K7-K8 -> 0 | L21: =L7-L8 -> 0 | M21: =SUM(K21:L21) -> 0 | N21: =N7-N8 -> 301680 | O21: =SUM(N21) -> 301680
B22: Ⅳ. E B I T D A | D22: =SUM(G22,J22,M22,O22) -> 16858639 | E22: =E21+E19 -> 16483017 | F22: =F21+F19 -> 0 | G22: =SUM(E22:F22) -> 16483017 | H22: =H21+H19 -> 73941.84 | I22: =I21+I19 -> 0 | J22: =SUM(H22:I22) -> 73941.84 | K22: =K21+K19 -> 0 | L22: =L21+L19 -> 0 | M22: =SUM(K22:L22) -> 0 | N22: =N21+N19 -> 301680 | O22: =SUM(N22) -> 301680
A26: ■ 계정세부 | Q26: ■ 공통비 배부
B28: 구분 | D28: 합계 | E28: 객실 | H28: 식음 | K28: 부대 | N28: 임대 | P28: 비고 | R28: 구분 | T28: 운영CM | U28: 배부기준
E29: 팔라티움 | F29: 도급-객실 | G29: 계 | H29: 루프탑바 | I29: 예비 | J29: 계 | K29: 인피니티풀 | L29: 예비 | M29: 계 | N29: 입주업체 | O29: 계
B30: 급료 | D30: =SUM(G30,J30,M30,O30) -> 0 | E30: =IFERROR('3)직접비'!E30+$T30*E$112,"") -> 0 | F30: =IFERROR('3)직접비'!F30+$T30*F$112,"") -> 0 | G30: =SUM(E30:F30) -> 0 | H30: =IFERROR('3)직접비'!H30+$T30*H$112,"") -> 0 | I30: =IFERROR('3)직접비'!I30+$T30*I$112,"") -> 0 | J30: =SUM(H30:I30) -> 0 | K30: =IFERROR('3)직접비'!K30+$T30*K$112,"") -> 0 | L30: =IFERROR('3)직접비'!L30+$T30*L$112,"") -> 0 | M30: =SUM(K30:L30) -> 0 | N30: =IFERROR('3)직접비'!N30+$T30*N$112,"") | O30: =SUM(N30) -> 0 | R30: 급료 | U30: 매출액
B31: 임금 | D31: =SUM(G31,J31,M31,O31) -> 0 | E31: =IFERROR('3)직접비'!E31+$T31*E$112,"") -> 0 | F31: =IFERROR('3)직접비'!F31+$T31*F$112,"") -> 0 | G31: =SUM(E31:F31) -> 0 | H31: =IFERROR('3)직접비'!H31+$T31*H$112,"") -> 0 | I31: =IFERROR('3)직접비'!I31+$T31*I$112,"") -> 0 | J31: =SUM(H31:I31) -> 0 | K31: =IFERROR('3)직접비'!K31+$T31*K$112,"") -> 0 | L31: =IFERROR('3)직접비'!L31+$T31*L$112,"") -> 0 | M31: =SUM(K31:L31) -> 0 | N31: =IFERROR('3)직접비'!N31+$T31*N$112,"") | O31: =SUM(N31) -> 0 | R31: 임금 | U31: 매출액
B32: 상여금 | D32: =SUM(G32,J32,M32,O32) -> 0 | E32: =IFERROR('3)직접비'!E32+$T32*E$112,"") -> 0 | F32: =IFERROR('3)직접비'!F32+$T32*F$112,"") -> 0 | G32: =SUM(E32:F32) -> 0 | H32: =IFERROR('3)직접비'!H32+$T32*H$112,"") -> 0 | I32: =IFERROR('3)직접비'!I32+$T32*I$112,"") -> 0 | J32: =SUM(H32:I32) -> 0 | K32: =IFERROR('3)직접비'!K32+$T32*K$112,"") -> 0 | L32: =IFERROR('3)직접비'!L32+$T32*L$112,"") -> 0 | M32: =SUM(K32:L32) -> 0 | N32: =IFERROR('3)직접비'!N32+$T32*N$112,"") | O32: =SUM(N32) -> 0 | R32: 상여금 | U32: 매출액
B33: 제수당 | D33: =SUM(G33,J33,M33,O33) -> 0 | E33: =IFERROR('3)직접비'!E33+$T33*E$112,"") -> 0 | F33: =IFERROR('3)직접비'!F33+$T33*F$112,"") -> 0 | G33: =SUM(E33:F33) -> 0 | H33: =IFERROR('3)직접비'!H33+$T33*H$112,"") -> 0 | I33: =IFERROR('3)직접비'!I33+$T33*I$112,"") -> 0 | J33: =SUM(H33:I33) -> 0 | K33: =IFERROR('3)직접비'!K33+$T33*K$112,"") -> 0 | L33: =IFERROR('3)직접비'!L33+$T33*L$112,"") -> 0 | M33: =SUM(K33:L33) -> 0 | N33: =IFERROR('3)직접비'!N33+$T33*N$112,"") | O33: =SUM(N33) -> 0 | R33: 제수당 | U33: 매출액
B34: 퇴직급여 | D34: =SUM(G34,J34,M34,O34) -> 0 | E34: =IFERROR('3)직접비'!E34+$T34*E$112,"") -> 0 | F34: =IFERROR('3)직접비'!F34+$T34*F$112,"") -> 0 | G34: =SUM(E34:F34) -> 0 | H34: =IFERROR('3)직접비'!H34+$T34*H$112,"") -> 0 | I34: =IFERROR('3)직접비'!I34+$T34*I$112,"") -> 0 | J34: =SUM(H34:I34) -> 0 | K34: =IFERROR('3)직접비'!K34+$T34*K$112,"") -> 0 | L34: =IFERROR('3)직접비'!L34+$T34*L$112,"") -> 0 | M34: =SUM(K34:L34) -> 0 | N34: =IFERROR('3)직접비'!N34+$T34*N$112,"") | O34: =SUM(N34) -> 0 | R34: 퇴직급여 | U34: 매출액
B35: 인건비소계 | D35: =SUM(G35,J35,M35,O35) -> 0 | E35: =SUM(E30:E34) -> 0 | F35: =SUM(F30:F34) -> 0 | G35: =SUM(E35:F35) -> 0 | H35: =SUM(H30:H34) -> 0 | I35: =SUM(I30:I34) -> 0 | J35: =SUM(H35:I35) -> 0 | K35: =SUM(K30:K34) -> 0 | L35: =SUM(L30:L34) -> 0 | M35: =SUM(K35:L35) -> 0 | N35: =SUM(N30:N34) -> 0 | O35: =SUM(N35) -> 0 | R35: 인건비소계 | T35: =SUM(T30:T34) -> 0
B36: 재료비소계 | D36: =SUM(G36,J36,M36,O36) -> 0 | E36: =IFERROR('3)직접비'!E36,"") -> 0 | F36: =IFERROR('3)직접비'!F36,"") -> 0 | G36: =SUM(E36:F36) -> 0 | H36: =IFERROR('3)직접비'!H36,"") -> 0 | I36: =IFERROR('3)직접비'!I36,"") -> 0 | J36: =SUM(H36:I36) -> 0 | K36: =IFERROR('3)직접비'!K36,"") -> 0 | L36: =IFERROR('3)직접비'!L36,"") -> 0 | M36: =SUM(K36:L36) -> 0 | N36: =IFERROR('3)직접비'!N36,"") -> 0 | O36: =SUM(N36) -> 0 | R36: 재료비소계 | U36: 재료비
B37: 고정도급비 | D37: =SUM(G37,J37,M37,O37) -> 0 | E37: =IFERROR('3)직접비'!E37+$T37*E$112,"") -> 0 | F37: =IFERROR('3)직접비'!F37+$T37*F$112,"") -> 0 | G37: =SUM(E37:F37) -> 0 | H37: =IFERROR('3)직접비'!H37+$T37*H$112,"") -> 0 | I37: =IFERROR('3)직접비'!I37+$T37*I$112,"") -> 0 | J37: =SUM(H37:I37) -> 0 | K37: =IFERROR('3)직접비'!K37+$T37*K$112,"") -> 0 | L37: =IFERROR('3)직접비'!L37+$T37*L$112,"") -> 0 | M37: =SUM(K37:L37) -> 0 | N37: =IFERROR('3)직접비'!N37+$T37*N$112,"") | O37: =SUM(N37) -> 0 | R37: 고정도급비 | U37: 매출액
B38: 추가도급비 | D38: =SUM(G38,J38,M38,O38) -> 0 | E38: =IFERROR('3)직접비'!E38+$T38*E$112,"") -> 0 | F38: =IFERROR('3)직접비'!F38+$T38*F$112,"") -> 0 | G38: =SUM(E38:F38) -> 0 | H38: =IFERROR('3)직접비'!H38+$T38*H$112,"") -> 0 | I38: =IFERROR('3)직접비'!I38+$T38*I$112,"") -> 0 | J38: =SUM(H38:I38) -> 0 | K38: =IFERROR('3)직접비'!K38+$T38*K$112,"") -> 0 | L38: =IFERROR('3)직접비'!L38+$T38*L$112,"") -> 0 | M38: =SUM(K38:L38) -> 0 | N38: =IFERROR('3)직접비'!N38+$T38*N$112,"") | O38: =SUM(N38) -> 0 | R38: 추가도급비 | U38: 매출액
B39: 시설관리비 | D39: =SUM(G39,J39,M39,O39) -> 0 | E39: =IFERROR('3)직접비'!E39+$T39*E$112,"") -> 0 | F39: =IFERROR('3)직접비'!F39+$T39*F$112,"") -> 0 | G39: =SUM(E39:F39) -> 0 | H39: =IFERROR('3)직접비'!H39+$T39*H$112,"") -> 0 | I39: =IFERROR('3)직접비'!I39+$T39*I$112,"") -> 0 | J39: =SUM(H39:I39) -> 0 | K39: =IFERROR('3)직접비'!K39+$T39*K$112,"") -> 0 | L39: =IFERROR('3)직접비'!L39+$T39*L$112,"") -> 0 | M39: =SUM(K39:L39) -> 0 | N39: =IFERROR('3)직접비'!N39+$T39*N$112,"") | O39: =SUM(N39) -> 0 | R39: 시설관리비 | U39: 매출액
B40: 객실정비료 | D40: =SUM(G40,J40,M40,O40) -> 0 | E40: =IFERROR('3)직접비'!E40+$T40*E$112,"") -> 0 | F40: =IFERROR('3)직접비'!F40+$T40*F$112,"") -> 0 | G40: =SUM(E40:F40) -> 0 | H40: =IFERROR('3)직접비'!H40+$T40*H$112,"") -> 0 | I40: =IFERROR('3)직접비'!I40+$T40*I$112,"") -> 0 | J40: =SUM(H40:I40) -> 0 | K40: =IFERROR('3)직접비'!K40+$T40*K$112,"") -> 0 | L40: =IFERROR('3)직접비'!L40+$T40*L$112,"") -> 0 | M40: =SUM(K40:L40) -> 0 | N40: =IFERROR('3)직접비'!N40+$T40*N$112,"") | O40: =SUM(N40) -> 0 | R40: 객실정비료 | U40: 매출액
B41: 용역비소계 | D41: =SUM(G41,J41,M41,O41) -> 0 | E41: =SUM(E37:E40) -> 0 | F41: =SUM(F37:F40) -> 0 | G41: =SUM(E41:F41) -> 0 | H41: =SUM(H37:H40) -> 0 | I41: =SUM(I37:I40) -> 0 | J41: =SUM(H41:I41) -> 0 | K41: =SUM(K37:K40) -> 0 | L41: =SUM(L37:L40) -> 0 | M41: =SUM(K41:L41) -> 0 | N41: =SUM(N37:N40) -> 0 | O41: =SUM(N41) -> 0 | R41: 용역비소계 | T41: =SUM(T37:T40) -> 0
B42: 직원급식대 | D42: =SUM(G42,J42,M42,O42) -> 0 | E42: =IFERROR('3)직접비'!E42+$T42*E$114,"") -> 0 | F42: =IFERROR('3)직접비'!F42+$T42*F$114,"") -> 0 | G42: =SUM(E42:F42) -> 0 | H42: =IFERROR('3)직접비'!H42+$T42*H$114,"") -> 0 | I42: =IFERROR('3)직접비'!I42+$T42*I$114,"") -> 0 | J42: =SUM(H42:I42) -> 0 | K42: =IFERROR('3)직접비'!K42+$T42*K$114,"") -> 0 | L42: =IFERROR('3)직접비'!L42+$T42*L$114,"") -> 0 | M42: =SUM(K42:L42) -> 0 | N42: =IFERROR('3)직접비'!N42+$T42*N$114,"") | O42: =SUM(N42) -> 0 | R42: 직원급식대 | U42: 인원수
B43: 직원경조비 | D43: =SUM(G43,J43,M43,O43) -> 0 | E43: =IFERROR('3)직접비'!E43+$T43*E$112,"") -> 0 | F43: =IFERROR('3)직접비'!F43+$T43*F$112,"") -> 0 | G43: =SUM(E43:F43) -> 0 | H43: =IFERROR('3)직접비'!H43+$T43*H$112,"") -> 0 | I43: =IFERROR('3)직접비'!I43+$T43*I$112,"") -> 0 | J43: =SUM(H43:I43) -> 0 | K43: =IFERROR('3)직접비'!K43+$T43*K$112,"") -> 0 | L43: =IFERROR('3)직접비'!L43+$T43*L$112,"") -> 0 | M43: =SUM(K43:L43) -> 0 | N43: =IFERROR('3)직접비'!N43+$T43*N$112,"") | O43: =SUM(N43) -> 0 | R43: 직원경조비 | U43: 매출액
B44: 의료비 | D44: =SUM(G44,J44,M44,O44) -> 0 | E44: =IFERROR('3)직접비'!E44+$T44*E$112,"") -> 0 | F44: =IFERROR('3)직접비'!F44+$T44*F$112,"") -> 0 | G44: =SUM(E44:F44) -> 0 | H44: =IFERROR('3)직접비'!H44+$T44*H$112,"") -> 0 | I44: =IFERROR('3)직접비'!I44+$T44*I$112,"") -> 0 | J44: =SUM(H44:I44) -> 0 | K44: =IFERROR('3)직접비'!K44+$T44*K$112,"") -> 0 | L44: =IFERROR('3)직접비'!L44+$T44*L$112,"") -> 0 | M44: =SUM(K44:L44) -> 0 | N44: =IFERROR('3)직접비'!N44+$T44*N$112,"") | O44: =SUM(N44) -> 0 | R44: 의료비 | U44: 매출액
B45: 세탁비 | D45: =SUM(G45,J45,M45,O45) -> 0 | E45: =IFERROR('3)직접비'!E45+$T45*E$112,"") -> 0 | F45: =IFERROR('3)직접비'!F45+$T45*F$112,"") -> 0 | G45: =SUM(E45:F45) -> 0 | H45: =IFERROR('3)직접비'!H45+$T45*H$112,"") -> 0 | I45: =IFERROR('3)직접비'!I45+$T45*I$112,"") -> 0 | J45: =SUM(H45:I45) -> 0 | K45: =IFERROR('3)직접비'!K45+$T45*K$112,"") -> 0 | L45: =IFERROR('3)직접비'!L45+$T45*L$112,"") -> 0 | M45: =SUM(K45:L45) -> 0 | N45: =IFERROR('3)직접비'!N45+$T45*N$112,"") | O45: =SUM(N45) -> 0 | R45: 세탁비 | U45: 매출액
B46: 피복비 | D46: =SUM(G46,J46,M46,O46) -> 0 | E46: =IFERROR('3)직접비'!E46+$T46*E$112,"") -> 0 | F46: =IFERROR('3)직접비'!F46+$T46*F$112,"") -> 0 | G46: =SUM(E46:F46) -> 0 | H46: =IFERROR('3)직접비'!H46+$T46*H$112,"") -> 0 | I46: =IFERROR('3)직접비'!I46+$T46*I$112,"") -> 0 | J46: =SUM(H46:I46) -> 0 | K46: =IFERROR('3)직접비'!K46+$T46*K$112,"") -> 0 | L46: =IFERROR('3)직접비'!L46+$T46*L$112,"") -> 0 | M46: =SUM(K46:L46) -> 0 | N46: =IFERROR('3)직접비'!N46+$T46*N$112,"") | O46: =SUM(N46) -> 0 | R46: 피복비 | U46: 매출액
...

Sheet 3)직접비
A3: ■ 총괄
P4: [단위 : 백만원]
B5: 구분 | D5: 합계 | E5: 객실 | H5: 식음 | K5: 부대 | N5: 임대 | P5: 비고
E6: 팔라티움 | F6: 도급-객실 | G6: 계 | H6: 루프탑바 | I6: 예비 | J6: 계 | K6: 인피니티풀 | L6: 예비 | M6: 계 | N6: 입주업체 | O6: 계
B7: Ⅰ. 매 출 액 | D7: =SUM(G7,J7,M7,O7) -> 16858639 | E7: =매출목표!G9 -> 16483017 | G7: =SUM(E7:F7) -> 16483017 | H7: =매출목표!G12 -> 73941.84 | J7: =SUM(H7:I7) -> 73941.84 | K7: =매출목표!G19 -> 0 | M7: =SUM(K7:L7) -> 0 | N7: =매출목표!G10+매출목표!G14+매출목표!G15+매출목표!G16+매출목표!G17+매출목표!G25 -> 301680 | O7: =SUM(N7) -> 301680
B8: Ⅱ. 운 영 원 가 | D8: =SUM(G8,J8,M8,O8) -> 0 | E8: =SUM(E9:E20) -> 0 | F8: =SUM(F9:F20) -> 0 | G8: =SUM(E8:F8) -> 0 | H8: =SUM(H9:H20) -> 0 | I8: =SUM(I9:I20) -> 0 | J8: =SUM(H8:I8) -> 0 | K8: =SUM(K9:K20) -> 0 | L8: =SUM(L9:L20) -> 0 | M8: =SUM(K8:L8) -> 0 | N8: =SUM(N9:N20) -> 0 | O8: =SUM(N8) -> 0
C9: 인 건 비 | D9: =SUM(G9,J9,M9,O9) -> 0 | E9: =E35 -> 0 | F9: =F35 -> 0 | G9: =SUM(E9:F9) -> 0 | H9: =H35 -> 0 | I9: =I35 -> 0 | J9: =SUM(H9:I9) -> 0 | K9: =K35 -> 0 | L9: =L35 -> 0 | M9: =SUM(K9:L9) -> 0 | N9: =N35 -> 0 | O9: =SUM(N9) -> 0
C10: 재 료 비 | D10: =SUM(G10,J10,M10,O10) -> 0 | E10: =E36 -> 0 | F10: =F36 -> 0 | G10: =SUM(E10:F10) -> 0 | H10: =H36 -> 0 | I10: =I36 -> 0 | J10: =SUM(H10:I10) -> 0 | K10: =K36 -> 0 | L10: =L36 -> 0 | M10: =SUM(K10:L10) -> 0 | N10: =N36 -> 0 | O10: =SUM(N10) -> 0
C11: 용 역 비 | D11: =SUM(G11,J11,M11,O11) -> 0 | E11: =E41 -> 0 | F11: =F41 -> 0 | G11: =SUM(E11:F11) -> 0 | H11: =H41 -> 0 | I11: =I41 -> 0 | J11: =SUM(H11:I11) -> 0 | K11: =K41 -> 0 | L11: =L41 -> 0 | M11: =SUM(K11:L11) -> 0 | N11: =N41 -> 0 | O11: =SUM(N11) -> 0
C12: 복리후생비 | D12: =SUM(G12,J12,M12,O12) -> 0 | E12: =E52 -> 0 | F12: =F52 -> 0 | G12: =SUM(E12:F12) -> 0 | H12: =H52 -> 0 | I12: =I52 -> 0 | J12: =SUM(H12:I12) -> 0 | K12: =K52 -> 0 | L12: =L52 -> 0 | M12: =SUM(K12:L12) -> 0 | N12: =N52 -> 0 | O12: =SUM(N12) -> 0
C13: 수도광열비 | D13: =SUM(G13,J13,M13,O13) -> 0 | E13: =E58 -> 0 | F13: =F58 -> 0 | G13: =SUM(E13:F13) -> 0 | H13: =H58 -> 0 | I13: =I58 -> 0 | J13: =SUM(H13:I13) -> 0 | K13: =K58 -> 0 | L13: =L58 -> 0 | M13: =SUM(K13:L13) -> 0 | N13: =N58 -> 0 | O13: =SUM(N13) -> 0
C14: 소 모 품 비 | D14: =SUM(G14,J14,M14,O14) -> 0 | E14: =E59 -> 0 | F14: =F59 -> 0 | G14: =SUM(E14:F14) -> 0 | H14: =H59 -> 0 | I14: =I59 -> 0 | J14: =SUM(H14:I14) -> 0 | K14: =K59 -> 0 | L14: =L59 -> 0 | M14: =SUM(K14:L14) -> 0 | N14: =N59 -> 0 | O14: =SUM(N14) -> 0
C15: 지급수수료 | D15: =SUM(G15,J15,M15,O15) -> 0 | E15: =E64 -> 0 | F15: =F64 -> 0 | G15: =SUM(E15:F15) -> 0 | H15: =H64 -> 0 | I15: =I64 -> 0 | J15: =SUM(H15:I15) -> 0 | K15: =K64 -> 0 | L15: =L64 -> 0 | M15: =SUM(K15:L15) -> 0 | N15: =N64 -> 0 | O15: =SUM(N15) -> 0
C16: 수 선 비 | D16: =SUM(G16,J16,M16,O16) -> 0 | E16: =E65 -> 0 | F16: =F65 -> 0 | G16: =SUM(E16:F16) -> 0 | H16: =H65 -> 0 | I16: =I65 -> 0 | J16: =SUM(H16:I16) -> 0 | K16: =K65 -> 0 | L16: =L65 -> 0 | M16: =SUM(K16:L16) -> 0 | N16: =N65 -> 0 | O16: =SUM(N16) -> 0
C17: 광고선전비 | D17: =SUM(G17,J17,M17,O17) -> 0 | E17: =E70 -> 0 | F17: =F70 -> 0 | G17: =SUM(E17:F17) -> 0 | H17: =H70 -> 0 | I17: =I70 -> 0 | J17: =SUM(H17:I17) -> 0 | K17: =K70 -> 0 | L17: =L70 -> 0 | M17: =SUM(K17:L17) -> 0 | N17: =N70 -> 0 | O17: =SUM(N17) -> 0
C18: 세금과공과 | D18: =SUM(G18,J18,M18,O18) -> 0 | E18: =E79 -> 0 | F18: =F79 -> 0 | G18: =SUM(E18:F18) -> 0 | H18: =H79 -> 0 | I18: =I79 -> 0 | J18: =SUM(H18:I18) -> 0 | K18: =K79 -> 0 | L18: =L79 -> 0 | M18: =SUM(K18:L18) -> 0 | N18: =N79 -> 0 | O18: =SUM(N18) -> 0
C19: 감가상각비 | D19: =SUM(G19,J19,M19,O19) -> 0 | E19: =E82 -> 0 | F19: =F82 -> 0 | G19: =SUM(E19:F19) -> 0 | H19: =H82 -> 0 | I19: =I82 -> 0 | J19: =SUM(H19:I19) -> 0 | K19: =K82 -> 0 | L19: =L82 -> 0 | M19: =SUM(K19:L19) -> 0 | N19: =N82 -> 0 | O19: =SUM(N19) -> 0
C20: 기 타 경 비 | D20: =SUM(G20,J20,M20,O20) -> 0 | E20: =E92 -> 0 | F20: =F92 -> 0 | G20: =SUM(E20:F20) -> 0 | H20: =H92 -> 0 | I20: =I92 -> 0 | J20: =SUM(H20:I20) -> 0 | K20: =K92 -> 0 | L20: =L92 -> 0 | M20: =SUM(K20:L20) -> 0 | N20: =N92 -> 0 | O20: =SUM(N20) -> 0
B21: Ⅲ. 매출총이익 | D21: =SUM(G21,J21,M21,O21) -> 16858639 | E21: =E7-E8 -> 16483017 | F21: =F7-F8 -> 0 | G21: =SUM(E21:F21) -> 16483017 | H21: =H7-H8 -> 73941.84 | I21: =I7-I8 -> 0 | J21: =SUM(H21:I21) -> 73941.84 | K21: =K7-K8 -> 0 | L21: =L7-L8 -> 0 | M21: =SUM(K21:L21) -> 0 | N21: =N7-N8 -> 301680 | O21: =SUM(N21) -> 301680
B22: Ⅳ. E B I T D A | D22: =SUM(G22,J22,M22,O22) -> 16858639 | E22: =E21+E19 -> 16483017 | F22: =F21+F19 -> 0 | G22: =SUM(E22:F22) -> 16483017 | H22: =H21+H19 -> 73941.84 | I22: =I21+I19 -> 0 | J22: =SUM(H22:I22) -> 73941.84 | K22: =K21+K19 -> 0 | L22: =L21+L19 -> 0 | M22: =SUM(K22:L22) -> 0 | N22: =N21+N19 -> 301680 | O22: =SUM(N22) -> 301680
A26: ■ 계정세부
B28: 구분 | D28: 합계 | E28: 객실 | H28: 식음 | K28: 부대 | N28: 임대 | P28: 비고
E29: 팔라티움 | F29: 도급-객실 | G29: 계 | H29: 루프탑바 | I29: 예비 | J29: 계 | K29: 인피니티풀 | L29: 예비 | M29: 계 | N29: 입주업체 | O29: 계
B30: 급료 | D30: =SUM(G30,J30,M30,O30) -> 0 | G30: =SUM(E30:F30) -> 0 | J30: =SUM(H30:I30) -> 0 | M30: =SUM(K30:L30) -> 0 | O30: =SUM(N30) -> 0
B31: 임금 | D31: =SUM(G31,J31,M31,O31) -> 0 | G31: =SUM(E31:F31) -> 0 | J31: =SUM(H31:I31) -> 0 | M31: =SUM(K31:L31) -> 0 | O31: =SUM(N31) -> 0
B32: 상여금 | D32: =SUM(G32,J32,M32,O32) -> 0 | G32: =SUM(E32:F32) -> 0 | J32: =SUM(H32:I32) -> 0 | M32: =SUM(K32:L32) -> 0 | O32: =SUM(N32) -> 0
B33: 제수당 | D33: =SUM(G33,J33,M33,O33) -> 0 | G33: =SUM(E33:F33) -> 0 | J33: =SUM(H33:I33) -> 0 | M33: =SUM(K33:L33) -> 0 | O33: =SUM(N33) -> 0
B34: 퇴직급여 | D34: =SUM(G34,J34,M34,O34) -> 0 | G34: =SUM(E34:F34) -> 0 | J34: =SUM(H34:I34) -> 0 | M34: =SUM(K34:L34) -> 0 | O34: =SUM(N34) -> 0
B35: 인건비소계 | D35: =SUM(G35,J35,M35,O35) -> 0 | E35: =SUM(E30:E34) -> 0 | F35: =SUM(F30:F34) -> 0 | G35: =SUM(E35:F35) -> 0 | H35: =SUM(H30:H34) -> 0 | I35: =SUM(I30:I34) -> 0 | J35: =SUM(H35:I35) -> 0 | K35: =SUM(K30:K34) -> 0 | L35: =SUM(L30:L34) -> 0 | M35: =SUM(K35:L35) -> 0 | N35: =SUM(N30:N34) -> 0 | O35: =SUM(N35) -> 0
B36: 재료비소계 | D36: =SUM(G36,J36,M36,O36) -> 0 | G36: =SUM(E36:F36) -> 0 | J36: =SUM(H36:I36) -> 0 | M36: =SUM(K36:L36) -> 0 | O36: =SUM(N36) -> 0
B37: 고정도급비 | D37: =SUM(G37,J37,M37,O37) -> 0 | G37: =SUM(E37:F37) -> 0 | J37: =SUM(H37:I37) -> 0 | M37: =SUM(K37:L37) -> 0 | O37: =SUM(N37) -> 0
B38: 추가도급비 | D38: =SUM(G38,J38,M38,O38) -> 0 | G38: =SUM(E38:F38) -> 0 | J38: =SUM(H38:I38) -> 0 | M38: =SUM(K38:L38) -> 0 | O38: =SUM(N38) -> 0
B39: 시설관리비 | D39: =SUM(G39,J39,M39,O39) -> 0 | G39: =SUM(E39:F39) -> 0 | J39: =SUM(H39:I39) -> 0 | M39: =SUM(K39:L39) -> 0 | O39: =SUM(N39) -> 0
B40: 객실정비료 | D40: =SUM(G40,J40,M40,O40) -> 0 | G40: =SUM(E40:F40) -> 0 | J40: =SUM(H40:I40) -> 0 | M40: =SUM(K40:L40) -> 0 | O40: =SUM(N40) -> 0
B41: 용역비소계 | D41: =SUM(G41,J41,M41,O41) -> 0 | E41: =SUM(E37:E40) -> 0 | F41: =SUM(F37:F40) -> 0 | G41: =SUM(E41:F41) -> 0 | H41: =SUM(H37:H40) -> 0 | I41: =SUM(I37:I40) -> 0 | J41: =SUM(H41:I41) -> 0 | K41: =SUM(K37:K40) -> 0 | L41: =SUM(L37:L40) -> 0 | M41: =SUM(K41:L41) -> 0 | N41: =SUM(N37:N40) -> 0 | O41: =SUM(N41) -> 0
B42: 직원급식대 | D42: =SUM(G42,J42,M42,O42) -> 0 | G42: =SUM(E42:F42) -> 0 | J42: =SUM(H42:I42) -> 0 | M42: =SUM(K42:L42) -> 0 | O42: =SUM(N42) -> 0
B43: 직원경조비 | D43: =SUM(G43,J43,M43,O43) -> 0 | G43: =SUM(E43:F43) -> 0 | J43: =SUM(H43:I43) -> 0 | M43: =SUM(K43:L43) -> 0 | O43: =SUM(N43) -> 0
B44: 의료비 | D44: =SUM(G44,J44,M44,O44) -> 0 | G44: =SUM(E44:F44) -> 0 | J44: =SUM(H44:I44) -> 0 | M44: =SUM(K44:L44) -> 0 | O44: =SUM(N44) -> 0
B45: 세탁비 | D45: =SUM(G45,J45,M45,O45) -> 0 | G45: =SUM(E45:F45) -> 0 | J45: =SUM(H45:I45) -> 0 | M45: =SUM(K45:L45) -> 0 | O45: =SUM(N45) -> 0
B46: 피복비 | D46: =SUM(G46,J46,M46,O46) -> 0 | G46: =SUM(E46:F46) -> 0 | J46: =SUM(H46:I46) -> 0 | M46: =SUM(K46:L46) -> 0 | O46: =SUM(N46) -> 0
...

Sheet 매출목표
A3: 1. 매출계획
B5: 구 분 | D5: 면적(평) | E5: 위탁시설 | F5: 수익시설 | G5: 매출액 | T5: 비 고
G6: 합 계 | H6: 1 | I6: 2 | J6: 3 | K6: 4 | L6: 5 | M6: 6 | N6: 7 | O6: 8 | P6: 9 | Q6: 0 | R6: 11 | S6: 12
B7: 객실 | C7: 객실수입 | D7: 11794 | E7: O | F7: O | G7: =SUM(H7:S7) -> 16319819 | H7: =SUM(Sheet1!Y27:Y29) -> 1199021.3 | I7: =SUM(Sheet1!Z27:Z29) -> 970888.97 | J7: =SUM(Sheet1!AA27:AA29) -> 1087499.1 | K7: =SUM(Sheet1!AB27:AB29) -> 1202077.4 | L7: =SUM(Sheet1!AC27:AC29) -> 1401444.9 | M7: =SUM(Sheet1!AD27:AD29) -> 1416805.4 | N7: =SUM(Sheet1!AE27:AE29) -> 1609274.6 | O7: =SUM(Sheet1!AF27:AF29) -> 1723370.7 | ... S7: =SUM(Sheet1!AJ27:AJ29) -> 1294555.9 | T7: 투숙률 64%, ADR 329천원
C8: 기타수입 | G8: =SUM(H8:S8) -> 163198.19 | H8: =H7*1% -> 11990.213 | I8: =I7*1% -> 9708.8897 | J8: =J7*1% -> 10874.991 | K8: =K7*1% -> 12020.774 | L8: =L7*1% -> 14014.449 | M8: =M7*1% -> 14168.054 | N8: =N7*1% -> 16092.746 | O8: =O7*1% -> 17233.707 | ... S8: =S7*1% -> 12945.559 | T8: 객실수입 기준 1% 반영
C9: 객실 소계 | G9: =SUM(H9:S9) -> 16483017 | H9: =SUM(H7:H8) -> 1211011.6 | I9: =SUM(I7:I8) -> 980597.85 | J9: =SUM(J7:J8) -> 1098374.1 | K9: =SUM(K7:K8) -> 1214098.2 | L9: =SUM(L7:L8) -> 1415459.3 | M9: =SUM(M7:M8) -> 1430973.5 | N9: =SUM(N7:N8) -> 1625367.4 | O9: =SUM(O7:O8) -> 1740604.4 | ... S9: =SUM(S7:S8) -> 1307501.5 | T9: '24.12.30 프랜차이즈 검토 기준 매출액 반영
B10: 식음 | C10: 올데이 다이닝 | D10: 155 | E10: X | F10: 미해당 | G10: =SUM(H10:S10) -> 93000 | H10: =50*$D10 -> 7750 | I10: =50*$D10 -> 7750 | J10: =50*$D10 -> 7750 | K10: =50*$D10 -> 7750 | L10: =50*$D10 -> 7750 | M10: =50*$D10 -> 7750 | N10: =50*$D10 -> 7750 | O10: =50*$D10 -> 7750 | ... S10: =50*$D10 -> 7750 | T10: 임대가정(평당 월 50,000원 적용)
C11: 라운지 | D11: 21 | E11: X | F11: 미해당 | G11: =SUM(H11:S11) -> 0
C12: 루프탑 바 | D12: 140 | E12: O | F12: O | G12: =SUM(H12:S12) -> 73941.84 | H12: ='[62]1.매출'!$D$221*H9/$G$9 -> 5432.5263 | I12: ='[62]1.매출'!$D$221*I9/$G$9 -> 4398.904 | J12: ='[62]1.매출'!$D$221*J9/$G$9 -> 4927.2413 | K12: ='[62]1.매출'!$D$221*K9/$G$9 -> 5446.3729 | L12: ='[62]1.매출'!$D$221*L9/$G$9 -> 6349.667 | M12: ='[62]1.매출'!$D$221*M9/$G$9 -> 6419.2624 | N12: ='[62]1.매출'!$D$221*N9/$G$9 -> 7291.302 | O12: ='[62]1.매출'!$D$221*O9/$G$9 -> 7808.2485 | ... S12: ='[62]1.매출'!$D$221*S9/$G$9 -> 5865.3744 | T12: '24.12.30 프랜차이즈 검토 기준 매출액 반영
C13: 식음 소계 | G13: =SUM(H13:S13) -> 166941.84 | H13: =SUM(H10:H12) -> 13182.526 | I13: =SUM(I10:I12) -> 12148.904 | J13: =SUM(J10:J12) -> 12677.241 | K13: =SUM(K10:K12) -> 13196.373 | L13: =SUM(L10:L12) -> 14099.667 | M13: =SUM(M10:M12) -> 14169.262 | N13: =SUM(N10:N12) -> 15041.302 | O13: =SUM(O10:O12) -> 15558.249 | ... S13: =SUM(S10:S12) -> 13615.374
B14: 부대 | C14: 스크린골프 | D14: 100 | E14: X | F14: 미해당 | G14: =SUM(H14:S14) -> 60000 | H14: =50*$D14 -> 5000 | I14: =50*$D14 -> 5000 | J14: =50*$D14 -> 5000 | K14: =50*$D14 -> 5000 | L14: =50*$D14 -> 5000 | M14: =50*$D14 -> 5000 | N14: =50*$D14 -> 5000 | O14: =50*$D14 -> 5000 | ... S14: =50*$D14 -> 5000 | T14: 임대가정(평당 월 50,000원 적용)
C15: 씨어터 룸 | D15: 26 | E15: X | F15: 미해당 | G15: =SUM(H15:S15) -> 15600 | H15: =50*$D15 -> 1300 | I15: =50*$D15 -> 1300 | J15: =50*$D15 -> 1300 | K15: =50*$D15 -> 1300 | L15: =50*$D15 -> 1300 | M15: =50*$D15 -> 1300 | N15: =50*$D15 -> 1300 | O15: =50*$D15 -> 1300 | ... S15: =50*$D15 -> 1300 | T15: 임대가정(평당 월 50,000원 적용)
C16: 프라이빗 스파 | D16: 72 | E16: X | F16: 미해당 | G16: =SUM(H16:S16) -> 43200 | H16: =50*$D16 -> 3600 | I16: =50*$D16 -> 3600 | J16: =50*$D16 -> 3600 | K16: =50*$D16 -> 3600 | L16: =50*$D16 -> 3600 | M16: =50*$D16 -> 3600 | N16: =50*$D16 -> 3600 | O16: =50*$D16 -> 3600 | ... S16: =50*$D16 -> 3600 | T16: 임대가정(평당 월 50,000원 적용)
C17: 피트니스 | D17: 66 | E17: X | F17: 미해당 | G17: =SUM(H17:S17) -> 39600 | H17: =50*$D17 -> 3300 | I17: =50*$D17 -> 3300 | J17: =50*$D17 -> 3300 | K17: =50*$D17 -> 3300 | L17: =50*$D17 -> 3300 | M17: =50*$D17 -> 3300 | N17: =50*$D17 -> 3300 | O17: =50*$D17 -> 3300 | ... S17: =50*$D17 -> 3300 | T17: 임대가정(평당 월 50,000원 적용)
C18: 필라테스 | E18: X | F18: 미해당
C19: 인피니티 풀 | D19: 140 | E19: X | F19: 미해당 | G19: =SUM(H19:S19) -> 0
C20: 레저 소계 | G20: =SUM(H20:S20) -> 158400 | H20: =SUM(H14:H19) -> 13200 | I20: =SUM(I14:I19) -> 13200 | J20: =SUM(J14:J19) -> 13200 | K20: =SUM(K14:K19) -> 13200 | L20: =SUM(L14:L19) -> 13200 | M20: =SUM(M14:M19) -> 13200 | N20: =SUM(N14:N19) -> 13200 | O20: =SUM(O14:O19) -> 13200 | ... S20: =SUM(S14:S19) -> 13200
B21: 기타 | C21: 로비 | E21: O | F21: X | G21: =SUM(H21:S21) -> 0
C22: 비즈니스 센터 | D22: 67 | E22: X | F22: 미해당 | G22: =SUM(H22:S22) -> 0
C23: 테라스 가든 | D23: 90 | E23: X | F23: 미해당 | G23: =SUM(H23:S23) -> 0
C24: 루프탑가든 | D24: 120 | E24: O | F24: X | G24: =SUM(H24:S24) -> 0
